Workbook
Name UPDATE: 'Data Sheet'!$E$1

Sheet Profit & Loss
A1: ='Data Sheet'!B1 -> AVENUE SUPERMARTS LTD | H1: =UPDATE | M1: SCREENER.IN
A3: Narration | B3: ='Data Sheet'!B16 -> 42825 | C3: ='Data Sheet'!C16 -> 43190 | D3: ='Data Sheet'!D16 -> 43555 | E3: ='Data Sheet'!E16 -> 43921 | F3: ='Data Sheet'!F16 -> 44286 | G3: ='Data Sheet'!G16 -> 44651 | H3: ='Data Sheet'!H16 -> 45016 | I3: ='Data Sheet'!I16 -> 45382 | ... K3: ='Data Sheet'!K16 -> 46112 | L3: Trailing | M3: Best Case | N3: Worst Case
A4: Sales | B4: ='Data Sheet'!B17 -> 11897.7 | C4: ='Data Sheet'!C17 -> 15033.2 | D4: ='Data Sheet'!D17 -> 20004.52 | E4: ='Data Sheet'!E17 -> 24870.2 | F4: ='Data Sheet'!F17 -> 24143.06 | G4: ='Data Sheet'!G17 -> 30976.27 | H4: ='Data Sheet'!H17 -> 42839.56 | I4: ='Data Sheet'!I17 -> 50788.83 | ... K4: ='Data Sheet'!K17 -> 68820.74 | L4: =SUM(Quarters!H4:K4) -> 68820.74 | M4: =$K4+M23*K4 -> 80601.684 | N4: =$K4+N23*L4 -> 79791.945
A5: Expenses | B5: =SUM('Data Sheet'!B18,'Data Sheet'!B20:B24, -1*'Data Sheet'!B19) -> 10928.52 | C5: =SUM('Data Sheet'!C18,'Data Sheet'!C20:C24, -1*'Data Sheet'!C19) -> 13680.34 | D5: =SUM('Data Sheet'!D18,'Data Sheet'!D20:D24, -1*'Data Sheet'!D19) -> 18371.21 | E5: =SUM('Data Sheet'!E18,'Data Sheet'!E20:E24, -1*'Data Sheet'!E19) -> 22741.89 | F5: =SUM('Data Sheet'!F18,'Data Sheet'!F20:F24, -1*'Data Sheet'!F19) -> 22398.23 | G5: =SUM('Data Sheet'!G18,'Data Sheet'!G20:G24, -1*'Data Sheet'!G19) -> 28473.92 | H5: =SUM('Data Sheet'!H18,'Data Sheet'!H20:H24, -1*'Data Sheet'!H19) -> 39200.79 | I5: =SUM('Data Sheet'!I18,'Data Sheet'!I20:I24, -1*'Data Sheet'!I19) -> 46683.19 | ... K5: =SUM('Data Sheet'!K18,'Data Sheet'!K20:K24, -1*'Data Sheet'!K19) -> 63634.15 | L5: =SUM(Quarters!H5:K5) -> 63634.15 | M5: =M4-M6 -> 74392.547 | N5: =N4-N6 -> 73778.524
A6: Operating Profit | B6: =B4-B5 -> 969.18 | C6: =C4-C5 -> 1352.86 | D6: =D4-D5 -> 1633.31 | E6: =E4-E5 -> 2128.31 | F6: =F4-F5 -> 1744.83 | G6: =G4-G5 -> 2502.35 | H6: =H4-H5 -> 3638.77 | I6: =I4-I5 -> 4105.64 | ... K6: =K4-K5 -> 5186.59 | L6: =SUM(Quarters!H6:K6) -> 5186.59 | M6: =M4*M24 -> 6209.137 | N6: =N4*N24 -> 6013.4213
A7: Other Income | B7: ='Data Sheet'!B25 -> 27.7 | C7: ='Data Sheet'!C25 -> 87.75 | D7: ='Data Sheet'!D25 -> 48.33 | E7: ='Data Sheet'!E25 -> 59.99 | F7: ='Data Sheet'!F25 -> 194.43 | G7: ='Data Sheet'!G25 -> 113.64 | H7: ='Data Sheet'!H25 -> 127.6 | I7: ='Data Sheet'!I25 -> 144.58 | ... K7: ='Data Sheet'!K25 -> 74.1 | L7: =SUM(Quarters!H7:K7) -> 74.1 | M7: 0 | N7: 0
A8: Depreciation | B8: ='Data Sheet'!B26 -> 127.82 | C8: ='Data Sheet'!C26 -> 159 | D8: ='Data Sheet'!D26 -> 212.49 | E8: ='Data Sheet'!E26 -> 374.41 | F8: ='Data Sheet'!F26 -> 414.16 | G8: ='Data Sheet'!G26 -> 498.08 | H8: ='Data Sheet'!H26 -> 638.87 | I8: ='Data Sheet'!I26 -> 730.76 | ... K8: ='Data Sheet'!K26 -> 1037.02 | L8: =SUM(Quarters!H8:K8) -> 1037.02 | M8: =+$L8 -> 1037.02 | N8: =+$L8 -> 1037.02
A9: Interest | B9: ='Data Sheet'!B27 -> 121.98 | C9: ='Data Sheet'!C27 -> 59.54 | D9: ='Data Sheet'!D27 -> 47.21 | E9: ='Data Sheet'!E27 -> 69.12 | F9: ='Data Sheet'!F27 -> 41.65 | G9: ='Data Sheet'!G27 -> 53.79 | H9: ='Data Sheet'!H27 -> 67.41 | I9: ='Data Sheet'!I27 -> 58.13 | ... K9: ='Data Sheet'!K27 -> 142.05 | L9: =SUM(Quarters!H9:K9) -> 142.05 | M9: =+$L9 -> 142.05 | N9: =+$L9 -> 142.05
A10: Profit before tax | B10: ='Data Sheet'!B28 -> 747.08 | C10: ='Data Sheet'!C28 -> 1222.07 | D10: ='Data Sheet'!D28 -> 1421.94 | E10: ='Data Sheet'!E28 -> 1744.77 | F10: ='Data Sheet'!F28 -> 1483.45 | G10: ='Data Sheet'!G28 -> 2064.12 | H10: ='Data Sheet'!H28 -> 3060.09 | I10: ='Data Sheet'!I28 -> 3461.33 | ... K10: ='Data Sheet'!K28 -> 4081.62 | L10: =SUM(Quarters!H10:K10) -> 4081.62 | M10: =M6+M7-SUM(M8:M9) -> 5030.067 | N10: =N6+N7-SUM(N8:N9) -> 4834.3513
A11: Tax | B11: ='Data Sheet'!B29 -> 268.28 | C11: ='Data Sheet'!C29 -> 415.79 | D11: ='Data Sheet'!D29 -> 519.48 | E11: ='Data Sheet'!E29 -> 443.79 | F11: ='Data Sheet'!F29 -> 384.02 | G11: ='Data Sheet'!G29 -> 571.72 | H11: ='Data Sheet'!H29 -> 681.75 | I11: ='Data Sheet'!I29 -> 925.72 | ... K11: ='Data Sheet'!K29 -> 1111.76 | L11: =SUM(Quarters!H11:K11) -> 1111.76 | M11: =IF($L10>0,$L11/$L10,0) -> 0.27238204 | N11: =IF($L10>0,$L11/$L10,0) -> 0.27238204
A12: Net profit | B12: ='Data Sheet'!B30 -> 478.75 | C12: ='Data Sheet'!C30 -> 806.26 | D12: ='Data Sheet'!D30 -> 902.54 | E12: ='Data Sheet'!E30 -> 1301.08 | F12: ='Data Sheet'!F30 -> 1099.49 | G12: ='Data Sheet'!G30 -> 1492.55 | H12: ='Data Sheet'!H30 -> 2378.51 | I12: ='Data Sheet'!I30 -> 2536.17 | ... K12: ='Data Sheet'!K30 -> 2970.49 | L12: =SUM(Quarters!H12:K12) -> 2970.49 | M12: =M10-M11*M10 -> 3659.967 | N12: =N10-N11*N10 -> 3517.5608
A13: EPS | B13: =IF('Data Sheet'!B93>0,B12/'Data Sheet'!B93,0) -> 7.6710463 | C13: =IF('Data Sheet'!C93>0,C12/'Data Sheet'!C93,0) -> 12.918763 | D13: =IF('Data Sheet'!D93>0,D12/'Data Sheet'!D93,0) -> 14.461465 | E13: =IF('Data Sheet'!E93>0,E12/'Data Sheet'!E93,0) -> 20.084594 | F13: =IF('Data Sheet'!F93>0,F12/'Data Sheet'!F93,0) -> 16.972677 | G13: =IF('Data Sheet'!G93>0,G12/'Data Sheet'!G93,0) -> 23.04029 | H13: =IF('Data Sheet'!H93>0,H12/'Data Sheet'!H93,0) -> 36.688416 | I13: =IF('Data Sheet'!I93>0,I12/'Data Sheet'!I93,0) -> 38.976026 | ... K13: =IF('Data Sheet'!K93>0,K12/'Data Sheet'!K93,0) -> 45.559663 | L13: =IF('Data Sheet'!$B6>0,'Profit & Loss'!L12/'Data Sheet'!$B6,0) -> 45.545446 | M13: =IF('Data Sheet'!$B6>0,'Profit & Loss'!M12/'Data Sheet'!$B6,0) -> 56.116947 | N13: =IF('Data Sheet'!$B6>0,'Profit & Loss'!N12/'Data Sheet'!$B6,0) -> 53.933484
A14: Price to earning | B14: =IF(B15>0,B15/B13,"") -> 83.150326 | C14: =IF(C15>0,C15/C13,"") -> 102.54852 | D14: =IF(D15>0,D15/D13,"") -> 101.72552 | E14: =IF(E15>0,E15/E13,"") -> 108.91433 | F14: =IF(F15>0,F15/F13,"") -> 168.45015 | G14: =IF(G15>0,G15/G13,"") -> 173.75432 | H14: =IF(H15>0,H15/H13,"") -> 92.700923 | I14: =IF(I15>0,I15/I13,"") -> 116.1124 | ... K14: =IF(K15>0,K15/K13,"") -> 86.848756 | L14: =IF(L13>0,L15/L13,0) -> 90.555706 | M14: =M25 -> 97.907638 | N14: =N25 -> 90.555706
A15: Price | B15: ='Data Sheet'!B90 -> 637.85 | C15: ='Data Sheet'!C90 -> 1324.8 | D15: ='Data Sheet'!D90 -> 1471.1 | E15: ='Data Sheet'!E90 -> 2187.5 | F15: ='Data Sheet'!F90 -> 2859.05 | G15: ='Data Sheet'!G90 -> 4003.35 | H15: ='Data Sheet'!H90 -> 3401.05 | I15: ='Data Sheet'!I90 -> 4525.6 | ... K15: ='Data Sheet'!K90 -> 3956.8 | L15: ='Data Sheet'!B8 -> 4124.4 | M15: =M13*M14 -> 5494.2777 | N15: =N13*N14 -> 4883.9847
A17: RATIOS:
A18: Dividend Payout | B18: =IF('Data Sheet'!B30>0, 'Data Sheet'!B31/'Data Sheet'!B30, 0) -> 0 | C18: =IF('Data Sheet'!C30>0, 'Data Sheet'!C31/'Data Sheet'!C30, 0) -> 0 | D18: =IF('Data Sheet'!D30>0, 'Data Sheet'!D31/'Data Sheet'!D30, 0) -> 0 | E18: =IF('Data Sheet'!E30>0, 'Data Sheet'!E31/'Data Sheet'!E30, 0) -> 0 | F18: =IF('Data Sheet'!F30>0, 'Data Sheet'!F31/'Data Sheet'!F30, 0) -> 0 | G18: =IF('Data Sheet'!G30>0, 'Data Sheet'!G31/'Data Sheet'!G30, 0) -> 0 | H18: =IF('Data Sheet'!H30>0, 'Data Sheet'!H31/'Data Sheet'!H30, 0) -> 0 | I18: =IF('Data Sheet'!I30>0, 'Data Sheet'!I31/'Data Sheet'!I30, 0) -> 0 | ... K18: =IF('Data Sheet'!K30>0, 'Data Sheet'!K31/'Data Sheet'!K30, 0) -> 0
A19: OPM | B19: =IF(B6>0,B6/B4,0) -> 0.081459442 | C19: =IF(C6>0,C6/C4,0) -> 0.089991486 | D19: =IF(D6>0,D6/D4,0) -> 0.081647048 | E19: =IF(E6>0,E6/E4,0) -> 0.085576714 | F19: =IF(F6>0,F6/F4,0) -> 0.072270458 | G19: =IF(G6>0,G6/G4,0) -> 0.080782806 | H19: =IF(H6>0,H6/H4,0) -> 0.084939481 | I19: =IF(I6>0,I6/I4,0) -> 0.08083746 | ... L19: =IF(L6>0,L6/L4,0) -> 0.075363764
G22: TRENDS: | H22: 10 YEARS | I22: 7 YEARS | J22: 5 YEARS | K22: 3 YEARS | L22: RECENT | M22: BEST | N22: WORST
G23: Sales Growth | H23: =IF(B4=0,"",POWER($K4/B4,1/9)-1) -> 0.2153326 | I23: =IF(D4=0,"",POWER($K4/D4,1/7)-1) -> 0.19304242 | J23: =IF(F4=0,"",POWER($K4/F4,1/5)-1) -> 0.23306339 | K23: =IF(H4=0,"",POWER($K4/H4, 1/3)-1) -> 0.17118305 | L23: =IF(ISERROR(MAX(IF(J4=0,"",(K4-J4)/J4),IF(K4=0,"",(L4-K4)/K4))),"",MAX(IF(J4=0,"",(K4-J4)/J4),IF(K4=0,"",(L4-K4)/K4))) -> 0.15941713 | M23: =MAX(K23:L23) -> 0.17118305 | N23: =MIN(H23:L23) -> 0.15941713
G24: OPM | H24: =IF(SUM(B4:$K$4)=0,"",SUMPRODUCT(B19:$K$19,B4:$K$4)/SUM(B4:$K$4)) -> 0.079592179 | I24: =IF(SUM(E4:$K$4)=0,"",SUMPRODUCT(E19:$K$19,E4:$K$4)/SUM(E4:$K$4)) -> 0.078864345 | J24: =IF(SUM(G4:$K$4)=0,"",SUMPRODUCT(G19:$K$19,G4:$K$4)/SUM(G4:$K$4)) -> 0.078833721 | K24: =IF(SUM(I4:$K$4)=0, "", SUMPRODUCT(I19:$K$19,I4:$K$4)/SUM(I4:$K$4)) -> 0.077034829 | L24: =L19 -> 0.075363764 | M24: =MAX(K24:L24) -> 0.077034829 | N24: =MIN(H24:L24) -> 0.075363764
G25: Price to Earning | H25: =IF(ISERROR(AVERAGEIF(B14:$L14,">0")),"",AVERAGEIF(B14:$L14,">0")) -> 111.17042 | I25: =IF(ISERROR(AVERAGEIF(E14:$L14,">0")),"",AVERAGEIF(E14:$L14,">0")) -> 116.93128 | J25: =IF(ISERROR(AVERAGEIF(G14:$L14,">0")),"",AVERAGEIF(G14:$L14,">0")) -> 109.68097 | K25: =IF(ISERROR(AVERAGEIF(I14:$L14,">0")),"",AVERAGEIF(I14:$L14,">0")) -> 97.907638 | L25: =L14 -> 90.555706 | M25: =MAX(K25:L25) -> 97.907638 | N25: =MIN(H25:L25) -> 90.555706

Sheet Quarters
A1: ='Profit & Loss'!A1 -> AVENUE SUPERMARTS LTD | E1: =UPDATE | J1: SCREENER.IN
A3: Narration | B3: ='Data Sheet'!B41 -> 45291 | C3: ='Data Sheet'!C41 -> 45382 | D3: ='Data Sheet'!D41 -> 45473 | E3: ='Data Sheet'!E41 -> 45565 | F3: ='Data Sheet'!F41 -> 45657 | G3: ='Data Sheet'!G41 -> 45747 | H3: ='Data Sheet'!H41 -> 45838 | I3: ='Data Sheet'!I41 -> 45930 | ... K3: ='Data Sheet'!K41 -> 46112
A4: Sales | B4: ='Data Sheet'!B42 -> 13572.47 | C4: ='Data Sheet'!C42 -> 12726.55 | D4: ='Data Sheet'!D42 -> 14069.14 | E4: ='Data Sheet'!E42 -> 14444.5 | F4: ='Data Sheet'!F42 -> 15972.55 | G4: ='Data Sheet'!G42 -> 14871.86 | H4: ='Data Sheet'!H42 -> 16359.7 | I4: ='Data Sheet'!I42 -> 16676.3 | ... K4: ='Data Sheet'!K42 -> 17683.86
A5: Expenses | B5: ='Data Sheet'!B43 -> 12452.58 | C5: ='Data Sheet'!C43 -> 11782.91 | D5: ='Data Sheet'!D43 -> 12847.89 | E5: ='Data Sheet'!E43 -> 13350.73 | F5: ='Data Sheet'!F43 -> 14755.31 | G5: ='Data Sheet'!G43 -> 13916.79 | H5: ='Data Sheet'!H43 -> 15060.66 | I5: ='Data Sheet'!I43 -> 15462.65 | ... K5: ='Data Sheet'!K43 -> 16473.33
A6: Operating Profit | B6: ='Data Sheet'!B50 -> 1119.89 | C6: ='Data Sheet'!C50 -> 943.64 | D6: ='Data Sheet'!D50 -> 1221.25 | E6: ='Data Sheet'!E50 -> 1093.77 | F6: ='Data Sheet'!F50 -> 1217.24 | G6: ='Data Sheet'!G50 -> 955.07 | H6: ='Data Sheet'!H50 -> 1299.04 | I6: ='Data Sheet'!I50 -> 1213.65 | ... K6: ='Data Sheet'!K50 -> 1210.53
A7: Other Income | B7: ='Data Sheet'!B44 -> 32.92 | C7: ='Data Sheet'!C44 -> 37.87 | D7: ='Data Sheet'!D44 -> 41.6 | E7: ='Data Sheet'!E44 -> 33.52 | F7: ='Data Sheet'!F44 -> 24.14 | G7: ='Data Sheet'!G44 -> 25.05 | H7: ='Data Sheet'!H44 -> 19.43 | I7: ='Data Sheet'!I44 -> 19.57 | ... K7: ='Data Sheet'!K44 -> 18.17
A8: Depreciation | B8: ='Data Sheet'!B45 -> 189.33 | C8: ='Data Sheet'!C45 -> 204.89 | D8: ='Data Sheet'!D45 -> 192.76 | E8: ='Data Sheet'!E45 -> 207.78 | F8: ='Data Sheet'!F45 -> 228.12 | G8: ='Data Sheet'!G45 -> 240.86 | H8: ='Data Sheet'!H45 -> 231.7 | I8: ='Data Sheet'!I45 -> 253.47 | ... K8: ='Data Sheet'!K45 -> 283.56
A9: Interest | B9: ='Data Sheet'!B46 -> 14.55 | C9: ='Data Sheet'!C46 -> 13.42 | D9: ='Data Sheet'!D46 -> 15.96 | E9: ='Data Sheet'!E46 -> 16.32 | F9: ='Data Sheet'!F46 -> 18.21 | G9: ='Data Sheet'!G46 -> 18.96 | H9: ='Data Sheet'!H46 -> 29.3 | I9: ='Data Sheet'!I46 -> 34.96 | ... K9: ='Data Sheet'!K46 -> 40.97
A10: Profit before tax | B10: ='Data Sheet'!B47 -> 948.93 | C10: ='Data Sheet'!C47 -> 763.2 | D10: ='Data Sheet'!D47 -> 1054.13 | E10: ='Data Sheet'!E47 -> 903.19 | F10: ='Data Sheet'!F47 -> 995.05 | G10: ='Data Sheet'!G47 -> 720.3 | H10: ='Data Sheet'!H47 -> 1057.47 | I10: ='Data Sheet'!I47 -> 944.79 | ... K10: ='Data Sheet'!K47 -> 904.17
A11: Tax | B11: ='Data Sheet'!B48 -> 258.52 | C11: ='Data Sheet'!C48 -> 200.06 | D11: ='Data Sheet'!D48 -> 280.45 | E11: ='Data Sheet'!E48 -> 243.75 | F11: ='Data Sheet'!F48 -> 271.51 | G11: ='Data Sheet'!G48 -> 169.51 | H11: ='Data Sheet'!H48 -> 284.66 | I11: ='Data Sheet'!I48 -> 259.94 | ... K11: ='Data Sheet'!K48 -> 247.75
A12: Net profit | B12: ='Data Sheet'!B49 -> 690.61 | C12: ='Data Sheet'!C49 -> 563.25 | D12: ='Data Sheet'!D49 -> 773.82 | E12: ='Data Sheet'!E49 -> 659.58 | F12: ='Data Sheet'!F49 -> 723.72 | G12: ='Data Sheet'!G49 -> 550.9 | H12: ='Data Sheet'!H49 -> 772.97 | I12: ='Data Sheet'!I49 -> 685.01 | ... K12: ='Data Sheet'!K49 -> 656.59
A14: OPM | B14: =IF(B4>0,B6/B4,"") -> 0.082511879 | C14: =IF(C4>0,C6/C4,"") -> 0.074147353 | D14: =IF(D4>0,D6/D4,"") -> 0.086803458 | E14: =IF(E4>0,E6/E4,"") -> 0.075722247 | F14: =IF(F4>0,F6/F4,"") -> 0.076208245 | G14: =IF(G4>0,G6/G4,"") -> 0.064219943 | H14: =IF(H4>0,H6/H4,"") -> 0.079404879 | I14: =IF(I4>0,I6/I4,"") -> 0.072776935 | ... K14: =IF(K4>0,K6/K4,"") -> 0.068453946

Sheet Balance Sheet
A1: ='Profit & Loss'!A1 -> AVENUE SUPERMARTS LTD | E1: =UPDATE | J1: SCREENER.IN
A3: Narration | B3: ='Data Sheet'!B56 -> 42825 | C3: ='Data Sheet'!C56 -> 43190 | D3: ='Data Sheet'!D56 -> 43555 | E3: ='Data Sheet'!E56 -> 43921 | F3: ='Data Sheet'!F56 -> 44286 | G3: ='Data Sheet'!G56 -> 44651 | H3: ='Data Sheet'!H56 -> 45016 | I3: ='Data Sheet'!I56 -> 45382 | ... K3: ='Data Sheet'!K56 -> 46112
A4: Equity Share Capital | B4: ='Data Sheet'!B57 -> 624.08 | C4: ='Data Sheet'!C57 -> 624.08 | D4: ='Data Sheet'!D57 -> 624.08 | E4: ='Data Sheet'!E57 -> 647.77 | F4: ='Data Sheet'!F57 -> 647.77 | G4: ='Data Sheet'!G57 -> 647.77 | H4: ='Data Sheet'!H57 -> 648.26 | I4: ='Data Sheet'!I57 -> 650.73 | ... K4: ='Data Sheet'!K57 -> 651.96
A5: Reserves | B5: ='Data Sheet'!B58 -> 3217.7 | C5: ='Data Sheet'!C58 -> 4044.97 | D5: ='Data Sheet'!D58 -> 4963.37 | E5: ='Data Sheet'!E58 -> 10431.97 | F5: ='Data Sheet'!F58 -> 11535.94 | G5: ='Data Sheet'!G58 -> 13029.87 | H5: ='Data Sheet'!H58 -> 15430.44 | I5: ='Data Sheet'!I58 -> 18047.09 | ... K5: ='Data Sheet'!K58 -> 23812.08
A6: Borrowings | B6: ='Data Sheet'!B59 -> 1497.32 | C6: ='Data Sheet'!C59 -> 439.25 | D6: ='Data Sheet'!D59 -> 700.15 | E6: ='Data Sheet'!E59 -> 333.19 | F6: ='Data Sheet'!F59 -> 392.71 | G6: ='Data Sheet'!G59 -> 646.94 | H6: ='Data Sheet'!H59 -> 642.98 | I6: ='Data Sheet'!I59 -> 592.16 | ... K6: ='Data Sheet'!K59 -> 2424.99
A7: Other Liabilities | B7: ='Data Sheet'!B60 -> 480.18 | C7: ='Data Sheet'!C60 -> 539.92 | D7: ='Data Sheet'!D60 -> 717.9 | E7: ='Data Sheet'!E60 -> 663.23 | F7: ='Data Sheet'!F60 -> 1078.63 | G7: ='Data Sheet'!G60 -> 1146.4 | H7: ='Data Sheet'!H60 -> 1382.84 | I7: ='Data Sheet'!I60 -> 1882.5 | ... K7: ='Data Sheet'!K60 -> 2635.23
A8: Total | B8: ='Data Sheet'!B61 -> 5819.28 | C8: ='Data Sheet'!C61 -> 5648.22 | D8: ='Data Sheet'!D61 -> 7005.5 | E8: ='Data Sheet'!E61 -> 12076.16 | F8: ='Data Sheet'!F61 -> 13655.05 | G8: ='Data Sheet'!G61 -> 15470.98 | H8: ='Data Sheet'!H61 -> 18104.52 | I8: ='Data Sheet'!I61 -> 21172.48 | ... K8: ='Data Sheet'!K61 -> 29524.26
A10: Net Block | B10: ='Data Sheet'!B62 -> 2577.75 | C10: ='Data Sheet'!C62 -> 3399.97 | D10: ='Data Sheet'!D62 -> 4400.37 | E10: ='Data Sheet'!E62 -> 5948.03 | F10: ='Data Sheet'!F62 -> 7008.8 | G10: ='Data Sheet'!G62 -> 9260.02 | H10: ='Data Sheet'!H62 -> 11340.48 | I10: ='Data Sheet'!I62 -> 13415 | ... K10: ='Data Sheet'!K62 -> 20090.31
A11: Capital Work in Progress | B11: ='Data Sheet'!B63 -> 152.89 | C11: ='Data Sheet'!C63 -> 147.07 | D11: ='Data Sheet'!D63 -> 376.84 | E11: ='Data Sheet'!E63 -> 364.4 | F11: ='Data Sheet'!F63 -> 1019.59 | G11: ='Data Sheet'!G63 -> 1129.34 | H11: ='Data Sheet'!H63 -> 829.16 | I11: ='Data Sheet'!I63 -> 935.22 | ... K11: ='Data Sheet'!K63 -> 1299.96
A12: Investments | B12: ='Data Sheet'!B64 -> 25.69 | C12: ='Data Sheet'!C64 -> 68.18 | D12: ='Data Sheet'!D64 -> 16.53 | E12: ='Data Sheet'!E64 -> 14.68 | F12: ='Data Sheet'!F64 -> 2.95 | G12: ='Data Sheet'!G64 -> 5.94 | H12: ='Data Sheet'!H64 -> 202.2 | I12: ='Data Sheet'!I64 -> 106.67 | ... K12: ='Data Sheet'!K64 -> 4.01
A13: Other Assets | B13: ='Data Sheet'!B65 -> 3062.95 | C13: ='Data Sheet'!C65 -> 2033 | D13: ='Data Sheet'!D65 -> 2211.76 | E13: ='Data Sheet'!E65 -> 5749.05 | F13: ='Data Sheet'!F65 -> 5623.71 | G13: ='Data Sheet'!G65 -> 5075.68 | H13: ='Data Sheet'!H65 -> 5732.68 | I13: ='Data Sheet'!I65 -> 6715.59 | ... K13: ='Data Sheet'!K65 -> 8129.98
A14: Total | B14: ='Data Sheet'!B66 -> 5819.28 | C14: ='Data Sheet'!C66 -> 5648.22 | D14: ='Data Sheet'!D66 -> 7005.5 | E14: ='Data Sheet'!E66 -> 12076.16 | F14: ='Data Sheet'!F66 -> 13655.05 | G14: ='Data Sheet'!G66 -> 15470.98 | H14: ='Data Sheet'!H66 -> 18104.52 | I14: ='Data Sheet'!I66 -> 21172.48 | ... K14: ='Data Sheet'!K66 -> 29524.26
A16: Working Capital | B16: =B13-B7 -> 2582.77 | C16: =C13-C7 -> 1493.08 | D16: =D13-D7 -> 1493.86 | E16: =E13-E7 -> 5085.82 | F16: =F13-F7 -> 4545.08 | G16: =G13-G7 -> 3929.28 | H16: =H13-H7 -> 4349.84 | I16: =I13-I7 -> 4833.09 | ... K16: =K13-K7 -> 5494.75
A17: Debtors | B17: ='Data Sheet'!B67 -> 21 | C17: ='Data Sheet'!C67 -> 33.52 | D17: ='Data Sheet'!D67 -> 64.37 | E17: ='Data Sheet'!E67 -> 19.55 | F17: ='Data Sheet'!F67 -> 43.58 | G17: ='Data Sheet'!G67 -> 66.89 | H17: ='Data Sheet'!H67 -> 62.16 | I17: ='Data Sheet'!I67 -> 166.37 | ... K17: ='Data Sheet'!K67 -> 149.34
A18: Inventory | B18: ='Data Sheet'!B68 -> 947.9 | C18: ='Data Sheet'!C68 -> 1163.45 | D18: ='Data Sheet'!D68 -> 1608.65 | E18: ='Data Sheet'!E68 -> 1947.4 | F18: ='Data Sheet'!F68 -> 2248.28 | G18: ='Data Sheet'!G68 -> 2742.66 | H18: ='Data Sheet'!H68 -> 3243.48 | I18: ='Data Sheet'!I68 -> 3927.31 | ... K18: ='Data Sheet'!K68 -> 5900.64
A20: Debtor Days | B20: =IF('Profit & Loss'!B4>0,'Balance Sheet'!B17/('Profit & Loss'!B4/365),0) -> 0.64424216 | C20: =IF('Profit & Loss'!C4>0,'Balance Sheet'!C17/('Profit & Loss'!C4/365),0) -> 0.81385201 | D20: =IF('Profit & Loss'!D4>0,'Balance Sheet'!D17/('Profit & Loss'!D4/365),0) -> 1.1744871 | E20: =IF('Profit & Loss'!E4>0,'Balance Sheet'!E17/('Profit & Loss'!E4/365),0) -> 0.28691969 | F20: =IF('Profit & Loss'!F4>0,'Balance Sheet'!F17/('Profit & Loss'!F4/365),0) -> 0.65885186 | G20: =IF('Profit & Loss'!G4>0,'Balance Sheet'!G17/('Profit & Loss'!G4/365),0) -> 0.78817914 | H20: =IF('Profit & Loss'!H4>0,'Balance Sheet'!H17/('Profit & Loss'!H4/365),0) -> 0.52961328 | I20: =IF('Profit & Loss'!I4>0,'Balance Sheet'!I17/('Profit & Loss'!I4/365),0) -> 1.1956379 | ... K20: =IF('Profit & Loss'!K4>0,'Balance Sheet'!K17/('Profit & Loss'!K4/365),0) -> 0.79204467
A21: Inventory Turnover | B21: =IF('Balance Sheet'!B18>0,'Profit & Loss'!B4/'Balance Sheet'!B18,0) -> 12.55164 | C21: =IF('Balance Sheet'!C18>0,'Profit & Loss'!C4/'Balance Sheet'!C18,0) -> 12.921226 | D21: =IF('Balance Sheet'!D18>0,'Profit & Loss'!D4/'Balance Sheet'!D18,0) -> 12.435595 | E21: =IF('Balance Sheet'!E18>0,'Profit & Loss'!E4/'Balance Sheet'!E18,0) -> 12.770977 | F21: =IF('Balance Sheet'!F18>0,'Profit & Loss'!F4/'Balance Sheet'!F18,0) -> 10.738458 | G21: =IF('Balance Sheet'!G18>0,'Profit & Loss'!G4/'Balance Sheet'!G18,0) -> 11.294244 | H21: =IF('Balance Sheet'!H18>0,'Profit & Loss'!H4/'Balance Sheet'!H18,0) -> 13.2079 | I21: =IF('Balance Sheet'!I18>0,'Profit & Loss'!I4/'Balance Sheet'!I18,0) -> 12.932218 | ... K21: =IF('Balance Sheet'!K18>0,'Profit & Loss'!K4/'Balance Sheet'!K18,0) -> 11.663267
A23: Return on Equity | B23: =IF(SUM('Balance Sheet'!B4:B5)>0,'Profit & Loss'!B12/SUM('Balance Sheet'!B4:B5),"") -> 0.12461671 | C23: =IF(SUM('Balance Sheet'!C4:C5)>0,'Profit & Loss'!C12/SUM('Balance Sheet'!C4:C5),"") -> 0.17268181 | D23: =IF(SUM('Balance Sheet'!D4:D5)>0,'Profit & Loss'!D12/SUM('Balance Sheet'!D4:D5),"") -> 0.16152986 | E23: =IF(SUM('Balance Sheet'!E4:E5)>0,'Profit & Loss'!E12/SUM('Balance Sheet'!E4:E5),"") -> 0.11742875 | F23: =IF(SUM('Balance Sheet'!F4:F5)>0,'Profit & Loss'!F12/SUM('Balance Sheet'!F4:F5),"") -> 0.090242627 | G23: =IF(SUM('Balance Sheet'!G4:G5)>0,'Profit & Loss'!G12/SUM('Balance Sheet'!G4:G5),"") -> 0.10912336 | H23: =IF(SUM('Balance Sheet'!H4:H5)>0,'Profit & Loss'!H12/SUM('Balance Sheet'!H4:H5),"") -> 0.14792925 | I23: =IF(SUM('Balance Sheet'!I4:I5)>0,'Profit & Loss'!I12/SUM('Balance Sheet'!I4:I5),"") -> 0.13563988 | ... K23: =IF(SUM('Balance Sheet'!K4:K5)>0,'Profit & Loss'!K12/SUM('Balance Sheet'!K4:K5),"") -> 0.12142271
A24: Return on Capital Emp | C24: =IF((B4+B5+B6+C4+C5+C6)>0,('Profit & Loss'!C10+'Profit & Loss'!C9)*2/(B4+B5+B6+C4+C5+C6),"") -> 0.24534525 | D24: =IF((C4+C5+C6+D4+D5+D6)>0,('Profit & Loss'!D10+'Profit & Loss'!D9)*2/(C4+C5+C6+D4+D5+D6),"") -> 0.25783835 | E24: =IF((D4+D5+D6+E4+E5+E6)>0,('Profit & Loss'!E10+'Profit & Loss'!E9)*2/(D4+D5+D6+E4+E5+E6),"") -> 0.20495319 | F24: =IF((E4+E5+E6+F4+F5+F6)>0,('Profit & Loss'!F10+'Profit & Loss'!F9)*2/(E4+E5+E6+F4+F5+F6),"") -> 0.12714809 | G24: =IF((F4+F5+F6+G4+G5+G6)>0,('Profit & Loss'!G10+'Profit & Loss'!G9)*2/(F4+F5+F6+G4+G5+G6),"") -> 0.15745957 | H24: =IF((G4+G5+G6+H4+H5+H6)>0,('Profit & Loss'!H10+'Profit & Loss'!H9)*2/(G4+G5+G6+H4+H5+H6),"") -> 0.20147354 | I24: =IF((H4+H5+H6+I4+I5+I6)>0,('Profit & Loss'!I10+'Profit & Loss'!I9)*2/(H4+H5+H6+I4+I5+I6),"") -> 0.19546225 | J24: =IF((I4+I5+I6+J4+J5+J6)>0,('Profit & Loss'!J10+'Profit & Loss'!J9)*2/(I4+I5+I6+J4+J5+J6),"") -> 0.18018097 | K24: =IF((J4+J5+J6+K4+K5+K6)>0,('Profit & Loss'!K10+'Profit & Loss'!K9)*2/(J4+J5+J6+K4+K5+K6),"") -> 0.17191614

Sheet Cash Flow
A1: ='Balance Sheet'!A1 -> AVENUE SUPERMARTS LTD | E1: =UPDATE | J1: SCREENER.IN
A3: Narration | B3: ='Data Sheet'!B81 -> 42825 | C3: ='Data Sheet'!C81 -> 43190 | D3: ='Data Sheet'!D81 -> 43555 | E3: ='Data Sheet'!E81 -> 43921 | F3: ='Data Sheet'!F81 -> 44286 | G3: ='Data Sheet'!G81 -> 44651 | H3: ='Data Sheet'!H81 -> 45016 | I3: ='Data Sheet'!I81 -> 45382 | ... K3: ='Data Sheet'!K81 -> 46112
A4: Cash from Operating Activity | B4: ='Data Sheet'!B82 -> 455.28 | C4: ='Data Sheet'!C82 -> 729.99 | D4: ='Data Sheet'!D82 -> 806.84 | E4: ='Data Sheet'!E82 -> 1280.14 | F4: ='Data Sheet'!F82 -> 1375.14 | G4: ='Data Sheet'!G82 -> 1372.35 | H4: ='Data Sheet'!H82 -> 2630.27 | I4: ='Data Sheet'!I82 -> 2745.84 | ... K4: ='Data Sheet'!K82 -> 3466.74
A5: Cash from Investing Activity | B5: ='Data Sheet'!B83 -> -2481.61 | C5: ='Data Sheet'!C83 -> 463.55 | D5: ='Data Sheet'!D83 -> -958.37 | E5: ='Data Sheet'!E83 -> -4656.56 | F5: ='Data Sheet'!F83 -> -1110 | G5: ='Data Sheet'!G83 -> -1289.49 | H5: ='Data Sheet'!H83 -> -2313.1 | I5: ='Data Sheet'!I83 -> -2468.23 | ... K5: ='Data Sheet'!K83 -> -4206.96
A6: Cash from Financing Activity | B6: ='Data Sheet'!B84 -> 2025.26 | C6: ='Data Sheet'!C84 -> -1159.06 | D6: ='Data Sheet'!D84 -> 208.98 | E6: ='Data Sheet'!E84 -> 3357.42 | F6: ='Data Sheet'!F84 -> -179.5 | G6: ='Data Sheet'!G84 -> -179.24 | H6: ='Data Sheet'!H84 -> -205.14 | I6: ='Data Sheet'!I84 -> -147.64 | ... K6: ='Data Sheet'!K84 -> 288.18
A7: Net Cash Flow | B7: ='Data Sheet'!B85 -> -1.07 | C7: ='Data Sheet'!C85 -> 34.48 | D7: ='Data Sheet'!D85 -> 57.45 | E7: ='Data Sheet'!E85 -> -19 | F7: ='Data Sheet'!F85 -> 85.64 | G7: ='Data Sheet'!G85 -> -96.38 | H7: ='Data Sheet'!H85 -> 112.03 | I7: ='Data Sheet'!I85 -> 129.97 | ... K7: ='Data Sheet'!K85 -> -452.04

Sheet Customization
A1: How to use it?
A3: You can customize this workbook as you want.
B4: You can add custom formating, add conditional formating, add your own formulas… do ANYTHING.
B5: Please don't edit the "Data Sheet" only.
A7: After customization, you can upload this back on Screener.
B8: Upload on: | C8: https://www.screener.in/excel/
A10: Download your customized workbooks now onwards.
B11: Now whenever you will "Export to excel" from Screener, it will export your customized file.
A14: TESTING:
B15: This is a testing feature currently.
B16: You can report any formula errors on the worksheet at: support@screener.in

Sheet Data Sheet
A1: COMPANY NAME | B1: AVENUE SUPERMARTS LTD | E1: =IF(B2<>B3, "A NEW VERSION OF THE WORKSHEET IS AVAILABLE", "")
A2: LATEST VERSION | B2: 2.1 | E2: PLEASE DO NOT MAKE ANY CHANGES TO THIS SHEET
A3: CURRENT VERSION | B3: 2.1
A5: META
A6: Number of shares | B6: =IF(B9>0, B9/B8, 0) -> 65.220352
A7: Face Value | B7: 10
A8: Current Price | B8: 4124.4
A9: Market Capitalization | B9: 268994.82
A15: PROFIT & LOSS
A16: Report Date | B16: 42825 | C16: 43190 | D16: 43555 | E16: 43921 | F16: 44286 | G16: 44651 | H16: 45016 | I16: 45382 | J16: 45747 | K16: 46112
A17: Sales | B17: 11897.7 | C17: 15033.2 | D17: 20004.52 | E17: 24870.2 | F17: 24143.06 | G17: 30976.27 | H17: 42839.56 | I17: 50788.83 | J17: 59358.05 | K17: 68820.74
A18: Raw Material Cost | B18: 10357.25 | C18: 12846.95 | D18: 17445.49 | E18: 21441.68 | F18: 20855.56 | G18: 26891.77 | H18: 36884.77 | I18: 43958.31 | J18: 51668.76 | K18: 59315.99
A19: Change in Inventory | B19: 276.22 | C19: 211.31 | D19: 444.65 | E19: 338.75 | F19: 300.88 | G19: 494.38 | H19: 500.82 | I19: 683.77 | J19: 1117.06 | K19: 856.26
A20: Power and Fuel | B20: 99.41 | C20: 121.26 | D20: 152.8 | E20: 188.24 | F20: 174.2 | G20: 207.86 | H20: 314.62 | I20: 376.59 | J20: 447.75
A21: Other Mfr. Exp | B21: 332.9 | C21: 373.72 | D21: 499.72 | E21: 645.96 | F21: 746.43 | G21: 805.85 | H21: 1116.56 | I21: 1323.43 | J21: 1751.85
A22: Employee Cost | B22: 192.67 | C22: 283.14 | D22: 356.17 | E22: 457.14 | F22: 537.58 | G22: 617.36 | H22: 748.16 | I22: 907.82 | J22: 1167.47 | K22: 1541.48
A23: Selling and admin | B23: 71.24 | C23: 96 | D23: 135.84 | E23: 66.4 | F23: 108.69 | G23: 143.41 | H23: 212.04 | I23: 274.43 | J23: 312.48
A24: Other Expenses | B24: 151.27 | C24: 170.58 | D24: 225.84 | E24: 281.22 | F24: 276.65 | G24: 302.05 | H24: 425.46 | I24: 526.38 | J24: 632.29 | K24: 3632.94
A25: Other Income | B25: 27.7 | C25: 87.75 | D25: 48.33 | E25: 59.99 | F25: 194.43 | G25: 113.64 | H25: 127.6 | I25: 144.58 | J25: 117.13 | K25: 74.1
A26: Depreciation | B26: 127.82 | C26: 159 | D26: 212.49 | E26: 374.41 | F26: 414.16 | G26: 498.08 | H26: 638.87 | I26: 730.76 | J26: 869.52 | K26: 1037.02
A27: Interest | B27: 121.98 | C27: 59.54 | D27: 47.21 | E27: 69.12 | F27: 41.65 | G27: 53.79 | H27: 67.41 | I27: 58.13 | J27: 69.45 | K27: 142.05
A28: Profit before tax | B28: 747.08 | C28: 1222.07 | D28: 1421.94 | E28: 1744.77 | F28: 1483.45 | G28: 2064.12 | H28: 3060.09 | I28: 3461.33 | J28: 3672.67 | K28: 4081.62
A29: Tax | B29: 268.28 | C29: 415.79 | D29: 519.48 | E29: 443.79 | F29: 384.02 | G29: 571.72 | H29: 681.75 | I29: 925.72 | J29: 965.22 | K29: 1111.76
A30: Net profit | B30: 478.75 | C30: 806.26 | D30: 902.54 | E30: 1301.08 | F30: 1099.49 | G30: 1492.55 | H30: 2378.51 | I30: 2536.17 | J30: 2708.02 | K30: 2970.49
A31: Dividend Amount
A40: Quarters
A41: Report Date | B41: 45291 | C41: 45382 | D41: 45473 | E41: 45565 | F41: 45657 | G41: 45747 | H41: 45838 | I41: 45930 | J41: 46022 | K41: 46112
A42: Sales | B42: 13572.47 | C42: 12726.55 | D42: 14069.14 | E42: 14444.5 | F42: 15972.55 | G42: 14871.86 | H42: 16359.7 | I42: 16676.3 | J42: 18100.88 | K42: 17683.86
A43: Expenses | B43: 12452.58 | C43: 11782.91 | D43: 12847.89 | E43: 13350.73 | F43: 14755.31 | G43: 13916.79 | H43: 15060.66 | I43: 15462.65 | J43: 16637.51 | K43: 16473.33
A44: Other Income | B44: 32.92 | C44: 37.87 | D44: 41.6 | E44: 33.52 | F44: 24.14 | G44: 25.05 | H44: 19.43 | I44: 19.57 | J44: 16.93 | K44: 18.17
A45: Depreciation | B45: 189.33 | C45: 204.89 | D45: 192.76 | E45: 207.78 | F45: 228.12 | G45: 240.86 | H45: 231.7 | I45: 253.47 | J45: 268.29 | K45: 283.56
A46: Interest | B46: 14.55 | C46: 13.42 | D46: 15.96 | E46: 16.32 | F46: 18.21 | G46: 18.96 | H46: 29.3 | I46: 34.96 | J46: 36.82 | K46: 40.97
A47: Profit before tax | B47: 948.93 | C47: 763.2 | D47: 1054.13 | E47: 903.19 | F47: 995.05 | G47: 720.3 | H47: 1057.47 | I47: 944.79 | J47: 1175.19 | K47: 904.17
A48: Tax | B48: 258.52 | C48: 200.06 | D48: 280.45 | E48: 243.75 | F48: 271.51 | G48: 169.51 | H48: 284.66 | I48: 259.94 | J48: 319.41 | K48: 247.75
A49: Net profit | B49: 690.61 | C49: 563.25 | D49: 773.82 | E49: 659.58 | F49: 723.72 | G49: 550.9 | H49: 772.97 | I49: 685.01 | J49: 855.92 | K49: 656.59
A50: Operating Profit | B50: 1119.89 | C50: 943.64 | D50: 1221.25 | E50: 1093.77 | F50: 1217.24 | G50: 955.07 | H50: 1299.04 | I50: 1213.65 | J50: 1463.37 | K50: 1210.53
A55: BALANCE SHEET
A56: Report Date | B56: 42825 | C56: 43190 | D56: 43555 | E56: 43921 | F56: 44286 | G56: 44651 | H56: 45016 | I56: 45382 | J56: 45747 | K56: 46112
A57: Equity Share Capital | B57: 624.08 | C57: 624.08 | D57: 624.08 | E57: 647.77 | F57: 647.77 | G57: 647.77 | H57: 648.26 | I57: 650.73 | J57: 650.73 | K57: 651.96
A58: Reserves | B58: 3217.7 | C58: 4044.97 | D58: 4963.37 | E58: 10431.97 | F58: 11535.94 | G58: 13029.87 | H58: 15430.44 | I58: 18047.09 | J58: 20777.02 | K58: 23812.08
...

Sheet Sheet1
C4: Mean | D4: =AVERAGE(E8:E16) -> 0.22088089
C6: Years | D6: Revenue | E6: Growth rate | K6: Forecasting Methods | L6: Formula | M6: When to use
C7: 42825 | D7: 11897.7 | K7: Arithmatic Mean | L7: AVERAGE | M7: When no outliers
C8: 43190 | D8: 15033.2 | E8: =D8/D7-1 -> 0.26353833 | K8: Median | L8: MEDIAN | M8: When outliers exist
C9: 43555 | D9: 20004.52 | E9: =D9/D8-1 -> 0.33068941 | K9: Geometric Mean | L9: RRI | M9: When we have starting & ending point
C10: 43921 | D10: 24870.2 | E10: =D10/D9-1 -> 0.24322903 | K10: Regression | L10: Data Analysis Pack
C11: 44286 | D11: 24143.06 | E11: =D11/D10-1 -> -0.029237401 | L11: FORECAST
C12: 44651 | D12: 30976.27 | E12: =D12/D11-1 -> 0.28302999 | L12: Graph Based
C13: 45016 | D13: 42839.56 | E13: =D13/D12-1 -> 0.38297994
C14: 45382 | D14: 50788.83 | E14: =D14/D13-1 -> 0.1855591 | L14: Linear
C15: 45747 | D15: 59358.05 | E15: =D15/D14-1 -> 0.16872253 | L15: Exponential
C16: 46112 | D16: 68820.74 | E16: =D16/D15-1 -> 0.15941713 | L16: Polynomial
C17: 46477 | D17: =D16*(1+$D$4) -> 84021.927 | E17: =D4 -> 0.22088089 | L17: Log
C18: 46843 | D18: =D17*(1+$D$4) -> 102580.76 | E18: =E17 -> 0.22088089 | K18: Code based | L18: AI/ML
C19: 47208 | D19: =D18*(1+$D$4) -> 125238.9 | E19: =E18 -> 0.22088089
C20: 47573 | D20: =D19*(1+$D$4) -> 152901.78 | E20: =E19 -> 0.22088089
C21: 47938 | D21: =D20*(1+$D$4) -> 186674.86 | E21: =E20 -> 0.22088089
C22: 48304 | D22: =D21*(1+$D$4) -> 227907.77 | E22: =E21 -> 0.22088089
C23: 48669 | D23: =D22*(1+$D$4) -> 278248.24 | E23: =E22 -> 0.22088089
C24: 49034 | D24: =D23*(1+$D$4) -> 339707.96 | E24: =E23 -> 0.22088089
C25: 49399 | D25: =D24*(1+$D$4) -> 414742.95 | E25: =E24 -> 0.22088089
C27: Median | D27: =MEDIAN(E30:E38) -> 0.24322903 | J27: =_xlfn.RRI(H38,J29,J38) -> 0.19186106
C28: Years | D28: Revenue | E28: Growth rate | H28: Weight | I28: Years | J28: Revenue | M28: Weight | N28: Years | O28: Revenue
C29: 42825 | D29: 11897.7 | H29: 1 | I29: 42825 | J29: 11897.7 | M29: 1 | N29: 42825 | O29: 11897.7
C30: 43190 | D30: 15033.2 | E30: =D30/D29-1 -> 0.26353833 | H30: 2 | I30: 43190 | M30: 2 | N30: 43190 | O30: 15033.2 | P30: =O30/O29-1 -> 0.26353833
C31: 43555 | D31: 20004.52 | E31: =D31/D30-1 -> 0.33068941 | H31: 3 | I31: 43555 | M31: 3 | N31: 43555 | O31: 20004.52 | P31: =O31/O30-1 -> 0.33068941
C32: 43921 | D32: 24870.2 | E32: =D32/D31-1 -> 0.24322903 | H32: 4 | I32: 43921 | M32: 4 | N32: 43921 | O32: 24870.2 | P32: =O32/O31-1 -> 0.24322903
C33: 44286 | D33: 24143.06 | E33: =D33/D32-1 -> -0.029237401 | H33: 5 | I33: 44286 | M33: 5 | N33: 44286 | O33: 24143.06 | P33: =O33/O32-1 -> -0.029237401
C34: 44651 | D34: 30976.27 | E34: =D34/D33-1 -> 0.28302999 | H34: 6 | I34: 44651 | M34: 6 | N34: 44651 | O34: 30976.27 | P34: =O34/O33-1 -> 0.28302999
C35: 45016 | D35: 42839.56 | E35: =D35/D34-1 -> 0.38297994 | H35: 7 | I35: 45016 | M35: 7 | N35: 45016 | O35: 42839.56 | P35: =O35/O34-1 -> 0.38297994
C36: 45382 | D36: 50788.83 | E36: =D36/D35-1 -> 0.1855591 | H36: 8 | I36: 45382 | M36: 8 | N36: 45382 | O36: 50788.83 | P36: =O36/O35-1 -> 0.1855591
C37: 45747 | D37: 59358.05 | E37: =D37/D36-1 -> 0.16872253 | H37: 9 | I37: 45747 | M37: 9 | N37: 45747 | O37: 59358.05 | P37: =O37/O36-1 -> 0.16872253
C38: 46112 | D38: 68820.74 | E38: =D38/D37-1 -> 0.15941713 | H38: 10 | I38: 46112 | J38: 68820.74 | M38: 10 | N38: 46112 | O38: 68820.74 | P38: =O38/O37-1 -> 0.15941713
C39: 46477 | D39: =D38*(1+$D$27) -> 85559.942 | E39: =D27 -> 0.24322903 | H39: 11 | I39: 46477 | J39: =J38*(1+$J$27) -> 82024.76 | M39: 11 | N39: 46477 | O39: =FORECAST(M39,$O$29:$O$38,$M$29:$M$38) -> 69448.018 | P39: =O39/O38-1 -> 0.0091146651
C40: 46843 | D40: =D39*(1+$D$27) -> 106370.6 | E40: =E39 -> 0.24322903 | H40: 12 | I40: 46843 | J40: =J39*(1+$J$27) -> 97762.118 | M40: 12 | N40: 46843 | O40: =FORECAST(M40,$O$29:$O$38,$M$29:$M$38) -> 75734.346 | P40: =O40/O39-1 -> 0.090518468
C41: 47208 | D41: =D40*(1+$D$27) -> 132243.02 | E41: =E40 -> 0.24322903 | H41: 13 | I41: 47208 | J41: =J40*(1+$J$27) -> 116518.86 | M41: 13 | N41: 47208 | O41: =FORECAST(M41,$O$29:$O$38,$M$29:$M$38) -> 82020.674 | P41: =O41/O40-1 -> 0.083004984
C42: 47573 | D42: =D41*(1+$D$27) -> 164408.36 | E42: =E41 -> 0.24322903 | H42: 14 | I42: 47573 | J42: =J41*(1+$J$27) -> 138874.3 | M42: 14 | N42: 47573 | O42: =FORECAST(M42,$O$29:$O$38,$M$29:$M$38) -> 88307.003 | P42: =O42/O41-1 -> 0.076643215
C43: 47938 | D43: =D42*(1+$D$27) -> 204397.25 | E43: =E42 -> 0.24322903 | H43: 15 | I43: 47938 | J43: =J42*(1+$J$27) -> 165518.87 | M43: 15 | N43: 47938 | O43: =FORECAST(M43,$O$29:$O$38,$M$29:$M$38) -> 94593.331 | P43: =O43/O42-1 -> 0.071187199
C44: 48304 | D44: =D43*(1+$D$27) -> 254112.6 | E44: =E43 -> 0.24322903 | H44: 16 | I44: 48304 | J44: =J43*(1+$J$27) -> 197275.49 | M44: 16 | N44: 48304 | O44: =FORECAST(M44,$O$29:$O$38,$M$29:$M$38) -> 100879.66 | P44: =O44/O43-1 -> 0.066456357
C45: 48669 | D45: =D44*(1+$D$27) -> 315920.16 | E45: =E44 -> 0.24322903 | H45: 17 | I45: 48669 | J45: =J44*(1+$J$27) -> 235124.98 | M45: 17 | N45: 48669 | O45: =FORECAST(M45,$O$29:$O$38,$M$29:$M$38) -> 107165.99 | P45: =O45/O44-1 -> 0.062315121
...
