Workbook
Name UPDATE: 'Source Data Sheet'!$E$1

Sheet Profit & Loss
A1: ='Source Data Sheet'!B1 -> HINDUSTAN UNILEVER LTD | H1: =UPDATE | M1: SCREENER.IN
A3: Narration | B3: ='Source Data Sheet'!B16 -> 42460 | C3: ='Source Data Sheet'!C16 -> 42825 | D3: ='Source Data Sheet'!D16 -> 43190 | E3: ='Source Data Sheet'!E16 -> 43555 | F3: ='Source Data Sheet'!F16 -> 43921 | G3: ='Source Data Sheet'!G16 -> 44286 | H3: ='Source Data Sheet'!H16 -> 44651 | I3: ='Source Data Sheet'!I16 -> 45016 | ... K3: ='Source Data Sheet'!K16 -> 45747 | L3: Trailing | M3: Best Case | N3: Worst Case
A4: Sales | B4: ='Source Data Sheet'!B17 -> 32186 | C4: ='Source Data Sheet'!C17 -> 33162 | D4: ='Source Data Sheet'!D17 -> 35545 | E4: ='Source Data Sheet'!E17 -> 39310 | F4: ='Source Data Sheet'!F17 -> 39783 | G4: ='Source Data Sheet'!G17 -> 47028 | H4: ='Source Data Sheet'!H17 -> 52446 | I4: ='Source Data Sheet'!I17 -> 60580 | ... K4: ='Source Data Sheet'!K17 -> 63121 | L4: =SUM(Quarters!H4:K4) -> 64544 | M4: =$K4+M23*K4 -> 67142.015 | N4: =$K4+N23*L4 -> 64576.08
A5: Expenses | B5: =SUM('Source Data Sheet'!B18,'Source Data Sheet'!B20:B24, -1*'Source Data Sheet'!B19) -> 26276 | C5: =SUM('Source Data Sheet'!C18,'Source Data Sheet'!C20:C24, -1*'Source Data Sheet'!C19) -> 26834 | D5: =SUM('Source Data Sheet'!D18,'Source Data Sheet'!D20:D24, -1*'Source Data Sheet'!D19) -> 28046 | E5: =SUM('Source Data Sheet'!E18,'Source Data Sheet'!E20:E24, -1*'Source Data Sheet'!E19) -> 30430 | F5: =SUM('Source Data Sheet'!F18,'Source Data Sheet'!F20:F24, -1*'Source Data Sheet'!F19) -> 29922 | G5: =SUM('Source Data Sheet'!G18,'Source Data Sheet'!G20:G24, -1*'Source Data Sheet'!G19) -> 35402 | H5: =SUM('Source Data Sheet'!H18,'Source Data Sheet'!H20:H24, -1*'Source Data Sheet'!H19) -> 39589 | I5: =SUM('Source Data Sheet'!I18,'Source Data Sheet'!I20:I24, -1*'Source Data Sheet'!I19) -> 46433 | ... K5: =SUM('Source Data Sheet'!K18,'Source Data Sheet'!K20:K24, -1*'Source Data Sheet'!K19) -> 48278 | L5: =SUM(Quarters!H5:K5) -> 49646 | M5: =M4-M6 -> 51351.448 | N5: =N4-N6 -> 49772.613
A6: Operating Profit | B6: =B4-B5 -> 5910 | C6: =C4-C5 -> 6328 | D6: =D4-D5 -> 7499 | E6: =E4-E5 -> 8880 | F6: =F4-F5 -> 9861 | G6: =G4-G5 -> 11626 | H6: =H4-H5 -> 12857 | I6: =I4-I5 -> 14147 | ... K6: =K4-K5 -> 14843 | L6: =SUM(Quarters!H6:K6) -> 14898 | M6: =M4*M24 -> 15790.567 | N6: =N4*N24 -> 14803.467
A7: Other Income | B7: ='Source Data Sheet'!B25 -> 486 | C7: ='Source Data Sheet'!C25 -> 606 | D7: ='Source Data Sheet'!D25 -> 353 | E7: ='Source Data Sheet'!E25 -> 322 | F7: ='Source Data Sheet'!F25 -> 424 | G7: ='Source Data Sheet'!G25 -> 170 | H7: ='Source Data Sheet'!H25 -> 219 | I7: ='Source Data Sheet'!I25 -> 448 | ... K7: ='Source Data Sheet'!K25 -> 1322 | L7: =SUM(Quarters!H7:K7) -> 4562 | M7: 0 | N7: 0
A8: Depreciation | B8: ='Source Data Sheet'!B26 -> 353 | C8: ='Source Data Sheet'!C26 -> 432 | D8: ='Source Data Sheet'!D26 -> 520 | E8: ='Source Data Sheet'!E26 -> 565 | F8: ='Source Data Sheet'!F26 -> 1002 | G8: ='Source Data Sheet'!G26 -> 1074 | H8: ='Source Data Sheet'!H26 -> 1091 | I8: ='Source Data Sheet'!I26 -> 1137 | ... K8: ='Source Data Sheet'!K26 -> 1355 | L8: =SUM(Quarters!H8:K8) -> 1367 | M8: =+$L8 -> 1367 | N8: =+$L8 -> 1367
A9: Interest | B9: ='Source Data Sheet'!B27 -> 17 | C9: ='Source Data Sheet'!C27 -> 35 | D9: ='Source Data Sheet'!D27 -> 26 | E9: ='Source Data Sheet'!E27 -> 33 | F9: ='Source Data Sheet'!F27 -> 118 | G9: ='Source Data Sheet'!G27 -> 117 | H9: ='Source Data Sheet'!H27 -> 106 | I9: ='Source Data Sheet'!I27 -> 114 | ... K9: ='Source Data Sheet'!K27 -> 395 | L9: =SUM(Quarters!H9:K9) -> 419 | M9: =+$L9 -> 419 | N9: =+$L9 -> 419
A10: Profit before tax | B10: ='Source Data Sheet'!B28 -> 6026 | C10: ='Source Data Sheet'!C28 -> 6467 | D10: ='Source Data Sheet'!D28 -> 7306 | E10: ='Source Data Sheet'!E28 -> 8604 | F10: ='Source Data Sheet'!F28 -> 9165 | G10: ='Source Data Sheet'!G28 -> 10605 | H10: ='Source Data Sheet'!H28 -> 11879 | I10: ='Source Data Sheet'!I28 -> 13344 | ... K10: ='Source Data Sheet'!K28 -> 14415 | L10: =SUM(Quarters!H10:K10) -> 17674 | M10: =M6+M7-SUM(M8:M9) -> 14004.567 | N10: =N6+N7-SUM(N8:N9) -> 13017.467
A11: Tax | B11: ='Source Data Sheet'!B29 -> 1875 | C11: ='Source Data Sheet'!C29 -> 1977 | D11: ='Source Data Sheet'!D29 -> 2079 | E11: ='Source Data Sheet'!E29 -> 2544 | F11: ='Source Data Sheet'!F29 -> 2409 | G11: ='Source Data Sheet'!G29 -> 2606 | H11: ='Source Data Sheet'!H29 -> 2987 | I11: ='Source Data Sheet'!I29 -> 3201 | ... K11: ='Source Data Sheet'!K29 -> 3744 | L11: =SUM(Quarters!H11:K11) -> 3134 | M11: =IF($L10>0,$L11/$L10,0) -> 0.17732262 | N11: =IF($L10>0,$L11/$L10,0) -> 0.17732262
A12: Net profit | B12: ='Source Data Sheet'!B30 -> 4151 | C12: ='Source Data Sheet'!C30 -> 4476 | D12: ='Source Data Sheet'!D30 -> 5214 | E12: ='Source Data Sheet'!E30 -> 6054 | F12: ='Source Data Sheet'!F30 -> 6748 | G12: ='Source Data Sheet'!G30 -> 7995 | H12: ='Source Data Sheet'!H30 -> 8879 | I12: ='Source Data Sheet'!I30 -> 10120 | ... K12: ='Source Data Sheet'!K30 -> 10649 | L12: =SUM(Quarters!H12:K12) -> 14512 | M12: =M10-M11*M10 -> 11521.24 | N12: =N10-N11*N10 -> 10709.176
A13: EPS | B13: =IF('Source Data Sheet'!B93>0,B12/'Source Data Sheet'!B93,0) -> 19.182957 | C13: =IF('Source Data Sheet'!C93>0,C12/'Source Data Sheet'!C93,0) -> 20.681052 | D13: =IF('Source Data Sheet'!D93>0,D12/'Source Data Sheet'!D93,0) -> 24.088704 | E13: =IF('Source Data Sheet'!E93>0,E12/'Source Data Sheet'!E93,0) -> 27.966924 | F13: =IF('Source Data Sheet'!F93>0,F12/'Source Data Sheet'!F93,0) -> 31.171471 | G13: =IF('Source Data Sheet'!G93>0,G12/'Source Data Sheet'!G93,0) -> 34.027068 | H13: =IF('Source Data Sheet'!H93>0,H12/'Source Data Sheet'!H93,0) -> 37.789411 | I13: =IF('Source Data Sheet'!I93>0,I12/'Source Data Sheet'!I93,0) -> 43.071161 | ... K13: =IF('Source Data Sheet'!K93>0,K12/'Source Data Sheet'!K93,0) -> 45.322608 | L13: =IF('Source Data Sheet'!$B6>0,'Profit & Loss'!L12/'Source Data Sheet'!$B6,0) -> 61.745365 | M13: =IF('Source Data Sheet'!$B6>0,'Profit & Loss'!M12/'Source Data Sheet'!$B6,0) -> 49.020341 | N13: =IF('Source Data Sheet'!$B6>0,'Profit & Loss'!N12/'Source Data Sheet'!$B6,0) -> 45.565184
A14: Price to earning | B14: =IF(B15>0,B15/B13,"") -> 43.380695 | C14: =IF(C15>0,C15/C13,"") -> 42.193696 | D14: =IF(D15>0,D15/D13,"") -> 52.975453 | E14: =IF(E15>0,E15/E13,"") -> 58.409356 | F14: =IF(F15>0,F15/F13,"") -> 70.571903 | G14: =IF(G15>0,G15/G13,"") -> 68.390258 | H14: =IF(H15>0,H15/H13,"") -> 51.884905 | I14: =IF(I15>0,I15/I13,"") -> 56.892824 | ... K14: =IF(K15>0,K15/K13,"") -> 47.699815 | L14: =IF(L13>0,L15/L13,0) -> 37.059462 | M14: =M25 -> 47.799695 | N14: =N25 -> 37.059462
A15: Price | B15: ='Source Data Sheet'!B90 -> 832.17 | C15: ='Source Data Sheet'!C90 -> 872.61 | D15: ='Source Data Sheet'!D90 -> 1276.11 | E15: ='Source Data Sheet'!E90 -> 1633.53 | F15: ='Source Data Sheet'!F90 -> 2199.83 | G15: ='Source Data Sheet'!G90 -> 2327.12 | H15: ='Source Data Sheet'!H90 -> 1960.7 | I15: ='Source Data Sheet'!I90 -> 2450.44 | ... K15: ='Source Data Sheet'!K90 -> 2161.88 | L15: ='Source Data Sheet'!B8 -> 2288.25 | M15: =M13*M14 -> 2343.1573 | N15: =N13*N14 -> 1688.6212
A17: RATIOS:
A18: Dividend Payout | B18: =IF('Source Data Sheet'!B30>0, 'Source Data Sheet'!B31/'Source Data Sheet'!B30, 0) -> 0.83257046 | C18: =IF('Source Data Sheet'!C30>0, 'Source Data Sheet'!C31/'Source Data Sheet'!C30, 0) -> 0.82037534 | D18: =IF('Source Data Sheet'!D30>0, 'Source Data Sheet'!D31/'Source Data Sheet'!D30, 0) -> 0.82853855 | E18: =IF('Source Data Sheet'!E30>0, 'Source Data Sheet'!E31/'Source Data Sheet'!E30, 0) -> 0.78493558 | F18: =IF('Source Data Sheet'!F30>0, 'Source Data Sheet'!F31/'Source Data Sheet'!F30, 0) -> 0.80023711 | G18: =IF('Source Data Sheet'!G30>0, 'Source Data Sheet'!G31/'Source Data Sheet'!G30, 0) -> 1.1904315 | H18: =IF('Source Data Sheet'!H30>0, 'Source Data Sheet'!H31/'Source Data Sheet'!H30, 0) -> 0.89987611 | I18: =IF('Source Data Sheet'!I30>0, 'Source Data Sheet'!I31/'Source Data Sheet'!I30, 0) -> 0.90563241 | ... K18: =IF('Source Data Sheet'!K30>0, 'Source Data Sheet'!K31/'Source Data Sheet'!K30, 0) -> 1.1695934
A19: OPM | B19: =IF(B6>0,B6/B4,0) -> 0.18362021 | C19: =IF(C6>0,C6/C4,0) -> 0.19082082 | D19: =IF(D6>0,D6/D4,0) -> 0.21097201 | E19: =IF(E6>0,E6/E4,0) -> 0.22589672 | F19: =IF(F6>0,F6/F4,0) -> 0.24786969 | G19: =IF(G6>0,G6/G4,0) -> 0.24721443 | H19: =IF(H6>0,H6/H4,0) -> 0.24514739 | I19: =IF(I6>0,I6/I4,0) -> 0.23352592 | ... L19: =IF(L6>0,L6/L4,0) -> 0.23081929
G22: TRENDS: | H22: 10 YEARS | I22: 7 YEARS | J22: 5 YEARS | K22: 3 YEARS | L22: RECENT | M22: BEST | N22: WORST
G23: Sales Growth | H23: =IF(B4=0,"",POWER($K4/B4,1/9)-1) -> 0.077707146 | I23: =IF(D4=0,"",POWER($K4/D4,1/7)-1) -> 0.0854952 | J23: =IF(F4=0,"",POWER($K4/F4,1/5)-1) -> 0.096718749 | K23: =IF(H4=0,"",POWER($K4/H4, 1/3)-1) -> 0.063703284 | L23: =IF(ISERROR(MAX(IF(J4=0,"",(K4-J4)/J4),IF(K4=0,"",(L4-K4)/K4))),"",MAX(IF(J4=0,"",(K4-J4)/J4),IF(K4=0,"",(L4-K4)/K4))) -> 0.022544003 | M23: =MAX(K23:L23) -> 0.063703284 | N23: =MIN(H23:L23) -> 0.022544003
G24: OPM | H24: =IF(SUM(B4:$K$4)=0,"",SUMPRODUCT(B19:$K$19,B4:$K$4)/SUM(B4:$K$4)) -> 0.22924072 | I24: =IF(SUM(E4:$K$4)=0,"",SUMPRODUCT(E19:$K$19,E4:$K$4)/SUM(E4:$K$4)) -> 0.23855461 | J24: =IF(SUM(G4:$K$4)=0,"",SUMPRODUCT(G19:$K$19,G4:$K$4)/SUM(G4:$K$4)) -> 0.23900011 | K24: =IF(SUM(I4:$K$4)=0, "", SUMPRODUCT(I19:$K$19,I4:$K$4)/SUM(I4:$K$4)) -> 0.2351816 | L24: =L19 -> 0.23081929 | M24: =MAX(K24:L24) -> 0.2351816 | N24: =MIN(H24:L24) -> 0.22924072
G25: Price to Earning | H25: =IF(ISERROR(AVERAGEIF(B14:$L14,">0")),"",AVERAGEIF(B14:$L14,">0")) -> 52.636822 | I25: =IF(ISERROR(AVERAGEIF(E14:$L14,">0")),"",AVERAGEIF(E14:$L14,">0")) -> 55.0569 | J25: =IF(ISERROR(AVERAGEIF(G14:$L14,">0")),"",AVERAGEIF(G14:$L14,">0")) -> 51.912324 | K25: =IF(ISERROR(AVERAGEIF(I14:$L14,">0")),"",AVERAGEIF(I14:$L14,">0")) -> 47.799695 | L25: =L14 -> 37.059462 | M25: =MAX(K25:L25) -> 47.799695 | N25: =MIN(H25:L25) -> 37.059462

Sheet Quarters
A1: ='Profit & Loss'!A1 -> HINDUSTAN UNILEVER LTD | E1: =UPDATE | J1: SCREENER.IN
A3: Narration | B3: ='Source Data Sheet'!B41 -> 45199 | C3: ='Source Data Sheet'!C41 -> 45291 | D3: ='Source Data Sheet'!D41 -> 45382 | E3: ='Source Data Sheet'!E41 -> 45473 | F3: ='Source Data Sheet'!F41 -> 45565 | G3: ='Source Data Sheet'!G41 -> 45657 | H3: ='Source Data Sheet'!H41 -> 45747 | I3: ='Source Data Sheet'!I41 -> 45838 | ... K3: ='Source Data Sheet'!K41 -> 46022
A4: Sales | B4: ='Source Data Sheet'!B42 -> 15623 | C4: ='Source Data Sheet'!C42 -> 15567 | D4: ='Source Data Sheet'!D42 -> 15210 | E4: ='Source Data Sheet'!E42 -> 15707 | F4: ='Source Data Sheet'!F42 -> 15926 | G4: ='Source Data Sheet'!G42 -> 15556 | H4: ='Source Data Sheet'!H42 -> 15670 | I4: ='Source Data Sheet'!I42 -> 16514 | ... K4: ='Source Data Sheet'!K42 -> 16441
A5: Expenses | B5: ='Source Data Sheet'!B43 -> 11828 | C5: ='Source Data Sheet'!C43 -> 11902 | D5: ='Source Data Sheet'!D43 -> 11675 | E5: ='Source Data Sheet'!E43 -> 11965 | F5: ='Source Data Sheet'!F43 -> 12139 | G5: ='Source Data Sheet'!G43 -> 11867 | H5: ='Source Data Sheet'!H43 -> 12052 | I5: ='Source Data Sheet'!I43 -> 12797 | ... K5: ='Source Data Sheet'!K43 -> 12660
A6: Operating Profit | B6: ='Source Data Sheet'!B50 -> 3795 | C6: ='Source Data Sheet'!C50 -> 3665 | D6: ='Source Data Sheet'!D50 -> 3535 | E6: ='Source Data Sheet'!E50 -> 3742 | F6: ='Source Data Sheet'!F50 -> 3787 | G6: ='Source Data Sheet'!G50 -> 3689 | H6: ='Source Data Sheet'!H50 -> 3618 | I6: ='Source Data Sheet'!I50 -> 3717 | ... K6: ='Source Data Sheet'!K50 -> 3781
A7: Other Income | B7: ='Source Data Sheet'!B44 -> 178 | C7: ='Source Data Sheet'!C44 -> 184 | D7: ='Source Data Sheet'!D44 -> 309 | E7: ='Source Data Sheet'!E44 -> 209 | F7: ='Source Data Sheet'!F44 -> 203 | G7: ='Source Data Sheet'!G44 -> 733 | H7: ='Source Data Sheet'!H44 -> 171 | I7: ='Source Data Sheet'!I44 -> 74 | ... K7: ='Source Data Sheet'!K44 -> 4048
A8: Depreciation | B8: ='Source Data Sheet'!B45 -> 297 | C8: ='Source Data Sheet'!C45 -> 313 | D8: ='Source Data Sheet'!D45 -> 320 | E8: ='Source Data Sheet'!E45 -> 329 | F8: ='Source Data Sheet'!F45 -> 338 | G8: ='Source Data Sheet'!G45 -> 318 | H8: ='Source Data Sheet'!H45 -> 347 | I8: ='Source Data Sheet'!I45 -> 361 | ... K8: ='Source Data Sheet'!K45 -> 337
A9: Interest | B9: ='Source Data Sheet'!B46 -> 88 | C9: ='Source Data Sheet'!C46 -> 91 | D9: ='Source Data Sheet'!D46 -> 105 | E9: ='Source Data Sheet'!E46 -> 93 | F9: ='Source Data Sheet'!F46 -> 110 | G9: ='Source Data Sheet'!G46 -> 109 | H9: ='Source Data Sheet'!H46 -> 80 | I9: ='Source Data Sheet'!I46 -> 127 | ... K9: ='Source Data Sheet'!K46 -> 88
A10: Profit before tax | B10: ='Source Data Sheet'!B47 -> 3588 | C10: ='Source Data Sheet'!C47 -> 3445 | D10: ='Source Data Sheet'!D47 -> 3419 | E10: ='Source Data Sheet'!E47 -> 3529 | F10: ='Source Data Sheet'!F47 -> 3542 | G10: ='Source Data Sheet'!G47 -> 3995 | H10: ='Source Data Sheet'!H47 -> 3362 | I10: ='Source Data Sheet'!I47 -> 3303 | ... K10: ='Source Data Sheet'!K47 -> 7404
A11: Tax | B11: ='Source Data Sheet'!B48 -> 931 | C11: ='Source Data Sheet'!C48 -> 937 | D11: ='Source Data Sheet'!D48 -> 858 | E11: ='Source Data Sheet'!E48 -> 917 | F11: ='Source Data Sheet'!F48 -> 947 | G11: ='Source Data Sheet'!G48 -> 1006 | H11: ='Source Data Sheet'!H48 -> 887 | I11: ='Source Data Sheet'!I48 -> 535 | ... K11: ='Source Data Sheet'!K48 -> 801
A12: Net profit | B12: ='Source Data Sheet'!B49 -> 2656 | C12: ='Source Data Sheet'!C49 -> 2509 | D12: ='Source Data Sheet'!D49 -> 2558 | E12: ='Source Data Sheet'!E49 -> 2610 | F12: ='Source Data Sheet'!F49 -> 2591 | G12: ='Source Data Sheet'!G49 -> 2984 | H12: ='Source Data Sheet'!H49 -> 2464 | I12: ='Source Data Sheet'!I49 -> 2756 | ... K12: ='Source Data Sheet'!K49 -> 6607
A14: OPM | B14: =IF(B4>0,B6/B4,"") -> 0.24291109 | C14: =IF(C4>0,C6/C4,"") -> 0.23543393 | D14: =IF(D4>0,D6/D4,"") -> 0.23241289 | E14: =IF(E4>0,E6/E4,"") -> 0.23823773 | F14: =IF(F4>0,F6/F4,"") -> 0.23778727 | G14: =IF(G4>0,G6/G4,"") -> 0.23714322 | H14: =IF(H4>0,H6/H4,"") -> 0.23088705 | I14: =IF(I4>0,I6/I4,"") -> 0.22508175 | ... K14: =IF(K4>0,K6/K4,"") -> 0.22997385

Sheet Cover Page
B3: Project Title | C3: Financial Statement Analysis for Hindustan Unilever
B4: Student Name | C4: Anamika Singh
B5: Course Name and Instructor Details | C5: Financial Modelling & Valuation
B6: Date of Submission | C6: 46149

Sheet Table of Content
B2: Table of Content
B3: Source Data
B4: Income Statement
B5: Balance Sheet
B6: Cash Flow'
B7: Ratios
B8: Comparative Industry Analysis

Sheet Source Data Sheet
A1: COMPANY NAME | B1: HINDUSTAN UNILEVER LTD | E1: =IF(B2<>B3, "A NEW VERSION OF THE WORKSHEET IS AVAILABLE", "")
A2: LATEST VERSION | B2: 2.1 | E2: PLEASE DO NOT MAKE ANY CHANGES TO THIS SHEET
A3: CURRENT VERSION | B3: 2.1
A5: META
A6: Number of shares | B6: =IF(B9>0, B9/B8, 0) -> 235.02979
A7: Face Value | B7: 1
A8: Current Price | B8: 2288.25
A9: Market Capitalization | B9: 537806.91
A15: PROFIT & LOSS
A16: Report Date | B16: 42460 | C16: 42825 | D16: 43190 | E16: 43555 | F16: 43921 | G16: 44286 | H16: 44651 | I16: 45016 | J16: 45382 | K16: 45747
A17: Sales | B17: 32186 | C17: 33162 | D17: 35545 | E17: 39310 | F17: 39783 | G17: 47028 | H17: 52446 | I17: 60580 | J17: 61896 | K17: 63121
A18: Raw Material Cost | B18: 13184 | C18: 13606 | D18: 14233 | E18: 15845 | F18: 15697 | G18: 20141 | H18: 22871 | I18: 28427 | J18: 26822 | K18: 27344
A19: Change in Inventory | B19: -83 | C19: -144 | D19: 72 | E19: -12 | F19: 108 | G19: 405 | H19: 22 | I19: 75 | J19: 11 | K19: 153
A20: Power and Fuel | B20: 309 | C20: 295 | D20: 295 | E20: 308 | F20: 299 | G20: 339 | H20: 318 | I20: 384 | J20: 446 | K20: 427
A21: Other Mfr. Exp | B21: 2966 | C21: 2887 | D21: 2998 | E21: 3041 | F21: 2906 | G21: 2868 | H21: 3354 | I21: 3791 | J21: 3385 | K21: 3834
A22: Employee Cost | B22: 1680 | C22: 1743 | D22: 1860 | E22: 1875 | F22: 1820 | G22: 2358 | H22: 2545 | I22: 2854 | J22: 3009 | K22: 3077
A23: Selling and admin | B23: 6741 | C23: 6689 | D23: 7252 | E23: 7796 | F23: 7620 | G23: 7906 | H23: 8164 | I23: 8785 | J23: 10780 | K23: 10693
A24: Other Expenses | B24: 1313 | C24: 1470 | D24: 1480 | E24: 1553 | F24: 1688 | G24: 2195 | H24: 2359 | I24: 2267 | J24: 2806 | K24: 3056
A25: Other Income | B25: 486 | C25: 606 | D25: 353 | E25: 322 | F25: 424 | G25: 170 | H25: 219 | I25: 448 | J25: 817 | K25: 1322
A26: Depreciation | B26: 353 | C26: 432 | D26: 520 | E26: 565 | F26: 1002 | G26: 1074 | H26: 1091 | I26: 1137 | J26: 1216 | K26: 1355
A27: Interest | B27: 17 | C27: 35 | D27: 26 | E27: 33 | F27: 118 | G27: 117 | H27: 106 | I27: 114 | J27: 334 | K27: 395
... A31: Dividend Amount | B31: 3456 | C31: 3672 | D31: 4320 | E31: 4752 | F31: 5400 | G31: 9517.5 | H31: 7990 | I31: 9165 | J31: 9870 | K31: 12455
A40: Quarters
A41: Report Date | B41: 45199 | C41: 45291 | D41: 45382 | E41: 45473 | F41: 45565 | G41: 45657 | H41: 45747 | I41: 45838 | J41: 45930 | K41: 46022
A42: Sales | B42: 15623 | C42: 15567 | D42: 15210 | E42: 15707 | F42: 15926 | G42: 15556 | H42: 15670 | I42: 16514 | J42: 15919 | K42: 16441
A43: Expenses | B43: 11828 | C43: 11902 | D43: 11675 | E43: 11965 | F43: 12139 | G43: 11867 | H43: 12052 | I43: 12797 | J43: 12137 | K43: 12660
A44: Other Income | B44: 178 | C44: 184 | D44: 309 | E44: 209 | F44: 203 | G44: 733 | H44: 171 | I44: 74 | J44: 269 | K44: 4048
A45: Depreciation | B45: 297 | C45: 313 | D45: 320 | E45: 329 | F45: 338 | G45: 318 | H45: 347 | I45: 361 | J45: 322 | K45: 337
A46: Interest | B46: 88 | C46: 91 | D46: 105 | E46: 93 | F46: 110 | G46: 109 | H46: 80 | I46: 127 | J46: 124 | K46: 88
A47: Profit before tax | B47: 3588 | C47: 3445 | D47: 3419 | E47: 3529 | F47: 3542 | G47: 3995 | H47: 3362 | I47: 3303 | J47: 3605 | K47: 7404
A48: Tax | B48: 931 | C48: 937 | D48: 858 | E48: 917 | F48: 947 | G48: 1006 | H48: 887 | I48: 535 | J48: 911 | K48: 801
A49: Net profit | B49: 2656 | C49: 2509 | D49: 2558 | E49: 2610 | F49: 2591 | G49: 2984 | H49: 2464 | I49: 2756 | J49: 2685 | K49: 6607
A50: Operating Profit | B50: 3795 | C50: 3665 | D50: 3535 | E50: 3742 | F50: 3787 | G50: 3689 | H50: 3618 | I50: 3717 | J50: 3782 | K50: 3781
A55: BALANCE SHEET
A56: Report Date | B56: 42460 | C56: 42825 | D56: 43190 | E56: 43555 | F56: 43921 | G56: 44286 | H56: 44651 | I56: 45016 | J56: 45382 | K56: 45747
A57: Equity Share Capital | B57: 216 | C57: 216 | D57: 216 | E57: 216 | F57: 216 | G57: 235 | H57: 235 | I57: 235 | J57: 235 | K57: 235
A58: Reserves | B58: 6357 | C58: 6528 | D58: 7065 | E58: 7651 | F58: 8013 | G58: 47439 | H58: 48826 | I58: 50069 | J58: 50983 | K58: 49167
A59: Borrowings | B59: 177 | C59: 277 | E59: 99 | H59: 1043 | I59: 1219 | J59: 1484 | K59: 1648
A60: Other Liabilities | B60: 8043 | C60: 8685 | D60: 10581 | E60: 10663 | F60: 11924 | G60: 21066 | H60: 20402 | I60: 21554 | J60: 25787 | K60: 28813
A61: Total | B61: 14793 | C61: 15706 | D61: 17862 | E61: 18629 | F61: 20153 | G61: 68740 | H61: 70506 | I61: 73077 | J61: 78489 | K61: 79863
...

Sheet Income Statement
B2: Income Statement for Hindustan Unilever
B3: Amount in Rs. Cr.
B4: Particular | C4: 44986 | D4: 45352 | E4: 45717 | F4: Trend
B5: Revenue | C5: ='Source Data Sheet'!I17 -> 60580 | D5: ='Source Data Sheet'!J17 -> 61896 | E5: ='Source Data Sheet'!K17 -> 63121
B6: % Growth | C6: - | D6: =D5/C5-1 -> 0.021723341 | E6: =E5/D5-1 -> 0.019791263
B8: COGS | C8: ='Source Data Sheet'!I18+'Source Data Sheet'!I20+'Source Data Sheet'!I21-'Source Data Sheet'!I19 -> 32527 | D8: ='Source Data Sheet'!J18+'Source Data Sheet'!J20+'Source Data Sheet'!J21-'Source Data Sheet'!J19 -> 30642 | E8: ='Source Data Sheet'!K18+'Source Data Sheet'!K20+'Source Data Sheet'!K21-'Source Data Sheet'!K19 -> 31452
B10: Gross Profit | C10: =C5-C8 -> 28053 | D10: =D5-D8 -> 31254 | E10: =E5-E8 -> 31669
B11: Gross Profit Margin | C11: =C10/C5 -> 0.46307362 | D11: =D10/D5 -> 0.50494378 | E11: =E10/E5 -> 0.50171892
B13: ='Source Data Sheet'!A24 -> Other Expenses | C13: ='Source Data Sheet'!I22+'Source Data Sheet'!I23+'Source Data Sheet'!I24 -> 13906 | D13: ='Source Data Sheet'!J22+'Source Data Sheet'!J23+'Source Data Sheet'!J24 -> 16595 | E13: ='Source Data Sheet'!K22+'Source Data Sheet'!K23+'Source Data Sheet'!K24 -> 16826
B15: EBITDA | C15: =C10-C13 -> 14147 | D15: =D10-D13 -> 14659 | E15: =E10-E13 -> 14843
B16: EBITDA % | C16: =C15/C5 -> 0.23352592 | D16: =D15/D5 -> 0.23683275 | E16: =E15/E5 -> 0.23515153
B18: ='Source Data Sheet'!A25 -> Other Income | C18: ='Source Data Sheet'!I25 -> 448 | D18: ='Source Data Sheet'!J25 -> 817 | E18: ='Source Data Sheet'!K25 -> 1322
B19: ='Source Data Sheet'!A26 -> Depreciation | C19: ='Source Data Sheet'!I26 -> 1137 | D19: ='Source Data Sheet'!J26 -> 1216 | E19: ='Source Data Sheet'!K26 -> 1355
B21: EBIT | C21: =C15+C18-C19 -> 13458 | D21: =D15+D18-D19 -> 14260 | E21: =E15+E18-E19 -> 14810
B23: ='Source Data Sheet'!A27 -> Interest | C23: ='Source Data Sheet'!I27 -> 114 | D23: ='Source Data Sheet'!J27 -> 334 | E23: ='Source Data Sheet'!K27 -> 395
B25: EBT | C25: =C21-C23 -> 13344 | D25: =D21-D23 -> 13926 | E25: =E21-E23 -> 14415
B27: ='Source Data Sheet'!A29 -> Tax | C27: ='Source Data Sheet'!I29 -> 3201 | D27: ='Source Data Sheet'!J29 -> 3644 | E27: ='Source Data Sheet'!K29 -> 3744
B29: Net Profit | C29: =C25-C27 -> 10143 | D29: =D25-D27 -> 10282 | E29: =E25-E27 -> 10671
B30: Net Profit Margin | C30: =C29/C5 -> 0.1674315 | D30: =D29/D5 -> 0.16611736 | E30: =E29/E5 -> 0.16905626

Sheet Balance Sheet
B2: Balance Sheet for Hindustan Unilever
B3: ='Income Statement'!B3 -> Amount in Rs. Cr.
B4: Particulars | C4: 45016 | D4: 45382 | E4: 45747
B5: ASSETS | G5: Particulars | H5: 45016 | I5: 45382 | J5: 45747
B6: Non-Current Assets | G6: =B21 -> Inventories | H6: =C21 -> 4251 | I6: =D21 -> 4022 | J6: =E21 -> 4415
B7: Property, Plant & Equipment | C7: 6949 | D7: 8031 | E7: 8625 | G7: =B23 -> Trade Receivables | H7: =C23 -> 3079 | I7: =D23 -> 2997 | J7: =E23 -> 3819
B8: Capital Work-in-Progress | C8: 1132 | D8: 1025 | E8: 1009 | G8: Trade Payables | H8: =C52+C53 -> 9574 | I8: =D52+D53 -> 10486 | J8: =E52+E53 -> 11315
B9: Goodwill | C9: 17466 | D9: 17466 | E9: 17466
B10: Other Intangible Assets | C10: 28263 | D10: 28247 | E10: 28244
B11: Investments (Equity Method) | C11: 69 | D11: 65 | E11: 57
B12: Investments | C12: 2 | D12: 2 | E12: 2
B13: Loans | C13: 98 | D13: 102 | E13: 87
B14: Other Financial Assets | C14: 725 | D14: 760 | E14: 763
B15: Deferred Tax Assets | C15: 10 | D15: 10 | E15: 17
B16: Non-current Tax Assets (Net) | C16: 1164 | D16: 1175 | E16: 1199
B17: Other Non-current Assets | C17: 211 | D17: 292 | E17: 360
B18: Total Non-Current Assets (A) | C18: =SUM(C7:C17) -> 56089 | D18: =SUM(D7:D17) -> 57175 | E18: =SUM(E7:E17) -> 57829
B20: Current Assets
B21: Inventories | C21: 4251 | D21: 4022 | E21: 4415
B22: Investments | C22: 2811 | D22: 4558 | E22: 3751
B23: Trade Receivables | C23: 3079 | D23: 2997 | E23: 3819
B24: Cash & Cash Equivalents | C24: 714 | D24: 825 | E24: 6071
B25: Bank Balances (Other) | C25: 3964 | D25: 6734 | E25: 1483
B26: Loans | C26: 36 | D26: 38 | E26: 46
B27: Other Financial Assets | C27: 1386 | D27: 1425 | E27: 1488
B28: Other Current Assets | C28: 745 | D28: 713 | E28: 955 | G28: Trend Analysis
B29: Assets Held for Sale | C29: 12 | D29: 12 | E29: 23
B30: Total Current Assets (B) | C30: =SUM(C21:C29) -> 16998 | D30: =SUM(D21:D29) -> 21324 | E30: =SUM(E21:E29) -> 22051
B32: TOTAL ASSETS (A+B) | C32: =C18+C30 -> 73087 | D32: =D18+D30 -> 78499 | E32: =E18+E30 -> 79880
B34: EQUITY & LIABILITIES
B35: Equity
B36: Equity Share Capital | C36: 235 | D36: 235 | E36: 235
B37: Other Equity | C37: 50069 | D37: 50983 | E37: 49167
B38: Non-controlling Interest | C38: 218 | D38: 205 | E38: 207
B39: Total Equity (A) | C39: =SUM(C36:C38) -> 50522 | D39: =SUM(D36:D38) -> 51423 | E39: =SUM(E36:E38) -> 49609
B41: Non-Current Liabilities
B42: Lease Liabilities | C42: 807 | D42: 1106 | E42: 1243
B43: Other Financial Liabilities | C43: 860 | D43: 715 | E43: 680
B44: Provisions | C44: 1363 | D44: 1576 | E44: 1528
B45: Deferred Tax Liabilities | C45: 6421 | D45: 6557 | E45: 6685
...

Sheet Cash Flow
B2: Cash Flow for Hindustan Unilever
B3: ='Balance Sheet'!B3:E3 -> Amount in Rs. Cr.
B4: Particulars | C4: 45016 | D4: 45382 | E4: 45747 | G4: The largest positive or negative contributors category.
B5: A. Cash Flows from Operating Activities | G5: =B5 -> A. Cash Flows from Operating Activities
B6: Profit Before Tax | C6: 13345 | D6: 13926 | E6: 14415
B7: Adjustments: | G7: Positive | H7: =B6 -> Profit Before Tax
B8: Depreciation & Amortisation | C8: 1152 | D8: 1216 | E8: 1363 | G8: Negative | H8: =B36 -> Taxes Paid
B9: Loss on Sale of PPE | C9: -100 | D9: 18 | E9: 43
B10: Contingent consideration true up for business combination | C10: -2 | D10: 0 | E10: 0 | G10: =B39 -> B. Cash Flows from Investing Activities
B11: Fair Value Loss/(Gain) on Financial Liability | C11: 0 | D11: -132 | E11: 120
B12: Interest Income | C12: -411 | D12: -546 | E12: -755 | G12: Positive | H12: =B48 -> Purchase of Current Investments
B13: Dividend Income | C13: -2 | D13: -3 | E13: 0 | G13: Negative | H13: =B49 -> Sale of Current Investments
B14: Other Non-Operating Income | C14: -99 | D14: -249 | E14: -256
B15: Interest Expense | C15: 114 | D15: 317 | E15: 372 | G15: =B57 -> C. Cash Flows from Financing Activities
B16: Profit on Sale of Business | C16: 0 | D16: 0 | E16: -595
B17: Movement in Provisions | C17: 0 | D17: -159 | E17: 0 | G17: Positive | H17: =B58 -> Dividends Paid
B18: Provision for expenses on employee stock options | C18: 1 | D18: 0 | E18: 0 | G18: Negative | H18: =B62 -> Lease Liability Payments (Principal)
B19: Profit on sale of brand rights | C19: -60 | D19: 0 | E19: 0
B20: Payment from Retirement Benefit Reserve | C20: -1 | D20: -1 | E20: -1
B21: Share of Loss of JV | C21: 1 | D21: 4 | E21: 8
B22: Transaction cost from acquisition | C22: 2 | D22: 0 | E22: 0
B23: Inventory Write-off | C23: 184 | D23: 167 | E23: 189
B24: Bad Debts Written Off | C24: -27 | D24: -11 | E24: 24
B25: Share-Based Payments | C25: 0 | D25: 0 | E25: 11
B26: Mark-to-Market (Gain)/Loss | C26: -8 | D26: -10 | E26: 4
B27: Cash from Operations before WC Changes | C27: =SUM(C6:C26) -> 14089 | D27: =SUM(D6:D26) -> 14537 | E27: =SUM(E6:E26) -> 14942
B29: Working Capital Changes:
B30: Change in Non-Current Assets | C30: -14 | D30: -30 | E30: -87
B31: Change in Current Assets | C31: -1111 | D31: 220 | E31: -1275
B32: Change in Inventories | C32: -339 | D32: 74 | E32: -584
B33: Change in Non-Current Liabilities | C33: -116 | D33: 128 | E33: -284
B34: Change in Current Liabilities | C34: 620 | D34: 921 | E34: 1442
B35: Cash Generated from Operations | C35: =SUM(C27:C34) -> 13129 | D35: =SUM(D27:D34) -> 15850 | E35: =SUM(E27:E34) -> 14154
B36: Taxes Paid | C36: -3138 | D36: -381 | E36: -2268
B37: Net Cash from Operating Activities (A) | C37: =C35+C36 -> 9991 | D37: =D35+D36 -> 15469 | E37: =E35+E36 -> 11886
B39: B. Cash Flows from Investing Activities
B40: Purchase of PPE | C40: -1174 | D40: -1468 | E40: -1254
B41: Sale of PPE | C41: 121 | D41: 20 | E41: 13
B42: Purchase of Intangible Assets | C42: -18 | D42: -9 | E42: -21
B43: Sale of Business | C43: 60 | D43: 0 | E43: 595
...

Sheet Ratios
B2: Ratio Analysis for Hindustan Unilever
B3: ='Cash Flow'!B4 -> Particulars | C3: 44986 | D3: 45352 | E3: 45717
B4: Liquidity Ratios
B6: Current Ratio | C6: ='Balance Sheet'!C66 -> 1.4132025 | D6: ='Balance Sheet'!D66 -> 1.6557186 | E6: ='Balance Sheet'!E66 -> 1.3334341
B7: Quick Ratio | C7: =('Balance Sheet'!C64-'Balance Sheet'!C21)/'Balance Sheet'!C65 -> 1.0597772 | D7: =('Balance Sheet'!D64-'Balance Sheet'!D21)/'Balance Sheet'!D65 -> 1.3434273 | E7: =('Balance Sheet'!E64-'Balance Sheet'!E21)/'Balance Sheet'!E65 -> 1.066457
B9: Solvency Ratio
B11: Debt-to-Equity Ratio | C11: ='Balance Sheet'!C67 -> 0.001939749 | D11: ='Balance Sheet'!D67 -> 0.00025280517 | E11: ='Balance Sheet'!E67 -> 2.0157633e-05
B12: Interest Coverage Ratio | C12: ='Income Statement'!C21/'Income Statement'!C23 -> 118.05263 | D12: ='Income Statement'!D21/'Income Statement'!D23 -> 42.694611 | E12: ='Income Statement'!E21/'Income Statement'!E23 -> 37.493671
B14: Profitability Ratios
B16: Gross Profit Margin | C16: ='Income Statement'!C11 -> 0.46307362 | D16: ='Income Statement'!D11 -> 0.50494378 | E16: ='Income Statement'!E11 -> 0.50171892
B17: Net Profit Margin | C17: ='Income Statement'!C30 -> 0.1674315 | D17: ='Income Statement'!D30 -> 0.16611736 | E17: ='Income Statement'!E30 -> 0.16905626
B18: Return on Equity (ROE) | C18: ='Income Statement'!C29/'Balance Sheet'!C39 -> 0.20076402 | D18: ='Income Statement'!D29/'Balance Sheet'!D39 -> 0.19994944 | E18: ='Income Statement'!E29/'Balance Sheet'!E39 -> 0.2151021
B19: Return on Assets (ROA) | C19: ='Income Statement'!C29/'Balance Sheet'!C32 -> 0.13877981 | D19: ='Income Statement'!D29/'Balance Sheet'!D32 -> 0.13098256 | E19: ='Income Statement'!E29/'Balance Sheet'!E32 -> 0.13358788
B21: Efficiency Ratios
B23: Inventory Turnove | C23: - | D23: ='Income Statement'!D8/(('Balance Sheet'!C21+'Balance Sheet'!D21)/2) -> 7.4077118 | E23: ='Income Statement'!E8/(('Balance Sheet'!D21+'Balance Sheet'!E21)/2) -> 7.4557307
B24: Accounts Receivable Turnover | C24: - | D24: ='Income Statement'!D5/(('Balance Sheet'!C23+'Balance Sheet'!D23)/2) -> 20.37393 | E24: ='Income Statement'!E5/(('Balance Sheet'!D23+'Balance Sheet'!E23)/2) -> 18.52142
B25: Asset Turnover | C25: - | D25: ='Income Statement'!D5/(('Balance Sheet'!C32+'Balance Sheet'!D32)/2) -> 0.81664534 | E25: ='Income Statement'!E5/(('Balance Sheet'!D32+'Balance Sheet'!E32)/2) -> 0.797088

Sheet Comparative Industry Analysis
B2: Key Differences (Latest Year) | L2: Competitive Advantages & Weaknesses
B3: Revenue Growth:
B10: Margins:
B17: Key Ratios:
