Workbook

Sheet Meta 10k Report 
B2: META PLATFORMS, INC. CONSOLIDATED STATEMENTS OF INCOME
B3: (In millions, except per share amounts)
C4: 2022A | D4: 2023A | E4: 2024A
B5: Revenue | C5: 116609 | D5: 134902 | E5: 164501
B6: Costs and expenses:
B7: Cost of revenue | C7: 25249 | D7: 25959 | E7: 30161
B8: Research and development | C8: 35338 | D8: 38483 | E8: 43873
B9: Marketing and sales | C9: 15262 | D9: 12301 | E9: 11347
B10: General and administrative | C10: 11816 | D10: 11408 | E10: 9740
B11: Total costs and expenses | C11: 87665 | D11: 88151 | E11: 95121
B12: Income from operations | C12: 28944 | D12: 46751 | E12: 69380
B13: Interest and other income (expense), net | C13: -125 | D13: 677 | E13: 1283
B14: Income before provision for income taxes | C14: 28819 | D14: 47428 | E14: 70663
B15: Provision for income taxes | C15: 5619 | D15: 8330 | E15: 8303
B16: Net income | C16: 23200 | D16: 39098 | E16: 62360
B19: META PLATFORMS, INC. CONSOLIDATED BALANCE SHEETS
B20: (In millions, except number of shares and par value)
C21: 2022A | D21: 2023A | E21: 2024A
B22: Assets
B23: Current assets:
B24: Cash and cash equivalents | C24: 14681 | D24: 41862 | E24: 43889
B25: Marketable securities | C25: 26057 | D25: 23541 | E25: 33926
B26: Accounts receivable, net | C26: 13466 | D26: 16169 | E26: 16994
B27: Prepaid expenses and other current assets | C27: 5345 | D27: 3793 | E27: 5236
B28: Total current assets | C28: 59549 | D28: 85365 | E28: 100045
B29: Non-marketable equity securities | C29: 6201 | D29: 6141 | E29: 6070
B30: Property and equipment, net | C30: 79518 | D30: 96587 | E30: 121346
B31: Operating lease right-of-use assets | C31: 12673 | D31: 13294 | E31: 14922
B32: Goodwill | C32: 20306 | D32: 20654 | E32: 20654
B33: Other assets | C33: 7480 | D33: 7582 | E33: 13017
B34: Total assets | C34: 185727 | D34: 229623 | E34: 276054
B36: Liabilities and stockholders' equity
B37: Current liabilities:
B38: Accounts payable | C38: 4990 | D38: 4849 | E38: 7687
B39: Operating lease liabilities, current | C39: 1117 | D39: 1623 | E39: 1942
B40: Accrued expenses and other current liabilities | C40: 1367 | D40: 25488 | E40: 23967
B41: Total current liabilities | C41: 19552 | D41: 31960 | E41: 33596
B42: Operating lease liabilities, non-current | C42: 27026 | D42: 17226 | E42: 18292
B43: Long-term debt | C43: 15301 | D43: 18385 | E43: 28826
B44: Long-term income taxes | C44: 9923 | D44: 7514 | E44: 9987
...

Sheet Revenue Sources
B2: Revenue Sources
B3: ='Meta 10k Report '!B3:E3 -> (In millions, except per share amounts)
C4: ='Meta 10k Report '!C4 -> 2022A | D4: ='Meta 10k Report '!D4 -> 2023A | E4: ='Meta 10k Report '!E4 -> 2024A | F4: 2025 | G4: 2026 | H4: 2027 | I4: 2028 | J4: 2029
B5: Revenue | C5: =SUM(C8,C11,C14,C17) -> 116609 | D5: =SUM(D8,D11,D14,D17) -> 134902 | E5: =SUM(E8,E11,E14,E17) -> 164501 | F5: =SUM(F8,F11,F14,F17) -> 196325.48 | G5: =SUM(G8,G11,G14,G17) -> 233965.89 | H5: =SUM(H8,H11,H14,H17) -> 278506.67 | I5: =SUM(I8,I11,I14,I17) -> 331050.86 | J5: =SUM(J8,J11,J14,J17) -> 392834.19
B6: %Growth | D6: =D5/C5-1 -> 0.15687468 | E6: =E5/D5-1 -> 0.21941113 | F6: =F5/E5-1 -> 0.19346069 | G6: =G5/F5-1 -> 0.19172455 | H6: =H5/G5-1 -> 0.19037296 | I6: =I5/H5-1 -> 0.18866401 | J6: =J5/I5-1 -> 0.18662792
B8: United States and Canada | C8: 50150 | D8: 52888 | E8: 63207 | F8: =E8*(1+F9) -> 71098.604 | G8: =F8*(1+G9) -> 79975.5 | H8: =G8*(1+H9) -> 89960.706 | I8: =H8*(1+I9) -> 101192.6 | J8: =I8*(1+J9) -> 113826.83
B9: %Growth | D9: =D8/C8-1 -> 0.054596211 | E9: =E8/D8-1 -> 0.19511042 | F9: =AVERAGE($D$9:$E$9) -> 0.12485332 | G9: =AVERAGE($D$9:$E$9) -> 0.12485332 | H9: =AVERAGE($D$9:$E$9) -> 0.12485332 | I9: =AVERAGE($D$9:$E$9) -> 0.12485332 | J9: =AVERAGE($D$9:$E$9) -> 0.12485332
B11: Europe | C11: 26681 | D11: 31210 | E11: 38361 | F11: =E11*(1+F12) -> 46011.556 | G11: =F11*(1+G12) -> 54957.848 | H11: =G11*(1+H12) -> 65368.83 | I11: =H11*(1+I12) -> 77425.181 | J11: =I11*(1+J12) -> 91318.028
B12: %Growth | D12: =D11/C11-1 -> 0.16974626 | E12: =E11/D11-1 -> 0.22912528 | F12: =AVERAGE(D12:E12) -> 0.19943577 | G12: =F12-0.5% -> 0.19443577 | H12: =G12-0.5% -> 0.18943577 | I12: =H12-0.5% -> 0.18443577 | J12: =I12-0.5% -> 0.17943577
B14: Asia-Pacific | C14: 27760 | D14: 36154 | E14: 45009 | F14: =E14*(1+F15) -> 57325.758 | G14: =F14*(1+G15) -> 72497.078 | H14: =G14*(1+H15) -> 91248.52 | I14: =H14*(1+I15) -> 114302.55 | J14: =I14*(1+J15) -> 142495.39
B15: %Growth | D15: =D14/C14-1 -> 0.30237752 | E15: =E14/D14-1 -> 0.24492449 | F15: =AVERAGE(D15:E15) -> 0.27365101 | G15: =F15-0.9% -> 0.26465101 | H15: =G15-0.6% -> 0.25865101 | I15: =H15-0.6% -> 0.25265101 | J15: =I15-0.6% -> 0.24665101
B17: Rest of World | C17: 12018 | D17: 14650 | E17: 17924 | F17: =E17*(1+F18) -> 21889.56 | G17: =F17*(1+G18) -> 26535.467 | H17: =G17*(1+H18) -> 31928.615 | I17: =H17*(1+I18) -> 38130.526 | J17: =I17*(1+J18) -> 45193.94
B18: %Growth | D18: =D17/C17-1 -> 0.21900483 | E18: =E17/D17-1 -> 0.22348123 | F18: =AVERAGE(D18:E18) -> 0.22124303 | G18: =F18-0.9% -> 0.21224303 | H18: =G18-0.9% -> 0.20324303 | I18: =H18-0.9% -> 0.19424303 | J18: =I18-0.9% -> 0.18524303

Sheet Other Items
B2: Other Items
B3: ='Revenue Sources'!B3:J3 -> (In millions, except per share amounts)
C4: ='Revenue Sources'!C4 -> 2022A | D4: ='Revenue Sources'!D4 -> 2023A | E4: ='Revenue Sources'!E4 -> 2024A | F4: ='Revenue Sources'!F4 -> 2025 | G4: ='Revenue Sources'!G4 -> 2026 | H4: ='Revenue Sources'!H4 -> 2027 | I4: ='Revenue Sources'!I4 -> 2028 | J4: ='Revenue Sources'!J4 -> 2029
B5: Cost of Good Sold | C5: ='Meta 10k Report '!C7-Schedules!C7 -> 16563 | D5: ='Meta 10k Report '!D7-Schedules!D7 -> 14781 | E5: ='Meta 10k Report '!E7-Schedules!E7 -> 14663 | F5: ='Revenue Sources'!F5*'Other Items'!F6 -> 16321.761 | G5: ='Revenue Sources'!G5*'Other Items'!G6 -> 18047.248 | H5: ='Revenue Sources'!H5*'Other Items'!H6 -> 19811.916 | I5: ='Revenue Sources'!I5*'Other Items'!I6 -> 21563.407 | J5: ='Revenue Sources'!J5*'Other Items'!J6 -> 23230.735
B6: as of % revenue | C6: =C5/'Revenue Sources'!C5 -> 0.14203878 | D6: =D5/'Revenue Sources'!D5 -> 0.10956843 | E6: =E5/'Revenue Sources'!E5 -> 0.089136236 | F6: =E6-0.6% -> 0.083136236 | G6: =F6-0.6% -> 0.077136236 | H6: =G6-0.6% -> 0.071136236 | I6: =H6-0.6% -> 0.065136236 | J6: =I6-0.6% -> 0.059136236
B8: ='Meta 10k Report '!B8 -> Research and development | C8: ='Meta 10k Report '!C8 -> 35338 | D8: ='Meta 10k Report '!D8 -> 38483 | E8: ='Meta 10k Report '!E8 -> 43873 | F8: ='Revenue Sources'!F5*'Other Items'!F9 -> 50397.446 | G8: ='Revenue Sources'!G5*'Other Items'!G9 -> 57720.215 | H8: ='Revenue Sources'!H5*'Other Items'!H9 -> 65923.517 | I8: ='Revenue Sources'!I5*'Other Items'!I9 -> 75050.403 | J8: ='Revenue Sources'!J5*'Other Items'!J9 -> 85128.561
B9: as of % revenue | C9: =C8/'Revenue Sources'!C5 -> 0.30304693 | D9: =D8/'Revenue Sources'!D5 -> 0.28526634 | E9: =E8/'Revenue Sources'!E5 -> 0.26670355 | F9: =E9-1% -> 0.25670355 | G9: =F9-1% -> 0.24670355 | H9: =G9-1% -> 0.23670355 | I9: =H9-1% -> 0.22670355 | J9: =I9-1% -> 0.21670355
B11: ='Meta 10k Report '!B9 -> Marketing and sales | C11: ='Meta 10k Report '!C9 -> 15262 | D11: ='Meta 10k Report '!D9 -> 12301 | E11: ='Meta 10k Report '!E9 -> 11347 | F11: ='Revenue Sources'!F5*'Other Items'!F12 -> 11578.944 | G11: ='Revenue Sources'!G5*'Other Items'!G12 -> 13798.912 | H11: ='Revenue Sources'!H5*'Other Items'!H12 -> 16425.851 | I11: ='Revenue Sources'!I5*'Other Items'!I12 -> 19524.818 | J11: ='Revenue Sources'!J5*'Other Items'!J12 -> 23168.694
B12: as of % revenue | C12: =C11/'Revenue Sources'!C5 -> 0.13088184 | D12: =D11/'Revenue Sources'!D5 -> 0.091184712 | E12: =E11/'Revenue Sources'!E5 -> 0.068978304 | F12: =E12-1% -> 0.058978304 | G12: =$F$12 -> 0.058978304 | H12: =$F$12 -> 0.058978304 | I12: =$F$12 -> 0.058978304 | J12: =$F$12 -> 0.058978304
B14: ='Meta 10k Report '!B10 -> General and administrative | C14: ='Meta 10k Report '!C10 -> 11816 | D14: ='Meta 10k Report '!D10 -> 11408 | E14: ='Meta 10k Report '!E10 -> 9740 | F14: ='Revenue Sources'!F5*'Other Items'!F15 -> 11624.307 | G14: ='Revenue Sources'!G5*'Other Items'!G15 -> 13852.972 | H14: ='Revenue Sources'!H5*'Other Items'!H15 -> 16490.204 | I14: ='Revenue Sources'!I5*'Other Items'!I15 -> 19601.311 | J14: ='Revenue Sources'!J5*'Other Items'!J15 -> 23259.463
B15: as of % revenue | C15: =C14/'Revenue Sources'!C5 -> 0.10133009 | D15: =D14/'Revenue Sources'!D5 -> 0.084565092 | E15: =E14/'Revenue Sources'!E5 -> 0.059209367 | F15: =$E$15 -> 0.059209367 | G15: =$E$15 -> 0.059209367 | H15: =$E$15 -> 0.059209367 | I15: =$E$15 -> 0.059209367 | J15: =$E$15 -> 0.059209367
B17: Other Current Asset | C17: ='Meta 10k Report '!C27 -> 5345 | D17: ='Meta 10k Report '!D27 -> 3793 | E17: ='Meta 10k Report '!E27 -> 5236 | F17: ='Revenue Sources'!F5*'Other Items'!F18 -> 4285.7054 | G17: ='Revenue Sources'!G5*'Other Items'!G18 -> 2767.7215 | H17: ='Revenue Sources'!H5*'Other Items'!H18 -> 509.55406 | I17: ='Revenue Sources'!I5*'Other Items'!I18 -> -2704.82 | J17: ='Revenue Sources'!J5*'Other Items'!J18 -> -7137.9568
B18: as of % revenue | C18: =C17/'Revenue Sources'!C5 -> 0.045836942 | D18: =D17/'Revenue Sources'!D5 -> 0.028116707 | E18: =E17/'Revenue Sources'!E5 -> 0.031829594 | F18: =E18-1% -> 0.021829594 | G18: =F18-1% -> 0.011829594 | H18: =G18-1% -> 0.0018295937 | I18: =H18-1% -> -0.0081704063 | J18: =I18-1% -> -0.018170406
B20: Account Payable | C20: ='Meta 10k Report '!C38 -> 4990 | D20: ='Meta 10k Report '!D38 -> 4849 | E20: ='Meta 10k Report '!E38 -> 7687 | F20: =F5*F21/365 -> 6276.1248 | G20: =G5*G21/365 -> 6939.6176 | H20: =H5*H21/365 -> 7618.1765 | I20: =I5*I21/365 -> 8291.6683 | J20: =J5*J21/365 -> 8932.7978
B21: Days Payable | C21: =(C20/C5)*365 -> 109.96498 | D21: =(D20/D5)*365 -> 119.74055 | E21: =(E20/E5)*365 -> 191.34931 | F21: =AVERAGE($C$21:$E$21) -> 140.35161 | G21: =AVERAGE($C$21:$E$21) -> 140.35161 | H21: =AVERAGE($C$21:$E$21) -> 140.35161 | I21: =AVERAGE($C$21:$E$21) -> 140.35161 | J21: =AVERAGE($C$21:$E$21) -> 140.35161
B23: Accrued Expenses and other Liabilities | C23: ='Meta 10k Report '!C40 -> 1367 | D23: ='Meta 10k Report '!D40 -> 25488 | E23: ='Meta 10k Report '!E40 -> 23967 | F23: ='Revenue Sources'!F5*'Other Items'!F24 -> 22666.12 | G23: ='Revenue Sources'!G5*'Other Items'!G24 -> 27011.772 | H23: ='Revenue Sources'!H5*'Other Items'!H24 -> 32154.083 | I23: ='Revenue Sources'!I5*'Other Items'!I24 -> 38220.401 | J23: ='Revenue Sources'!J5*'Other Items'!J24 -> 45353.395
B24: as of % revenue | C24: =C23/'Revenue Sources'!C5 -> 0.011722937 | D24: =D23/'Revenue Sources'!D5 -> 0.18893715 | E24: =E23/'Revenue Sources'!E5 -> 0.14569516 | F24: =AVERAGE($C$24:$E$24) -> 0.11545175 | G24: =AVERAGE($C$24:$E$24) -> 0.11545175 | H24: =AVERAGE($C$24:$E$24) -> 0.11545175 | I24: =AVERAGE($C$24:$E$24) -> 0.11545175 | J24: =AVERAGE($C$24:$E$24) -> 0.11545175
B26: Account Receivable | C26: ='Meta 10k Report '!C26 -> 13466 | D26: ='Meta 10k Report '!D26 -> 16169 | E26: ='Meta 10k Report '!E26 -> 16994 | F26: =('Revenue Sources'!F5*'Other Items'!F27)/365 -> 20281.671 | G26: =('Revenue Sources'!G5*'Other Items'!G27)/365 -> 24170.165 | H26: =('Revenue Sources'!H5*'Other Items'!H27)/365 -> 28771.511 | I26: =('Revenue Sources'!I5*'Other Items'!I27)/365 -> 34199.66 | J26: =('Revenue Sources'!J5*'Other Items'!J27)/365 -> 40582.271 | L26: =F26-E26 -> 3287.671
B27: Days Receivable | C27: =(C26/'Revenue Sources'!C5)*365 -> 42.150177 | D27: =(D26/'Revenue Sources'!D5)*365 -> 43.747943 | E27: =(E26/'Revenue Sources'!E5)*365 -> 37.706822 | F27: =$E$27 -> 37.706822 | G27: =$E$27 -> 37.706822 | H27: =$E$27 -> 37.706822 | I27: =$E$27 -> 37.706822 | J27: =$E$27 -> 37.706822

Sheet Schedules
B2: Schedules
B3: ='Meta 10k Report '!B3:E3 -> (In millions, except per share amounts)
C4: ='Revenue Sources'!C4 -> 2022A | D4: ='Revenue Sources'!D4 -> 2023A | E4: ='Revenue Sources'!E4 -> 2024A | F4: ='Revenue Sources'!F4 -> 2025 | G4: ='Revenue Sources'!G4 -> 2026 | H4: ='Revenue Sources'!H4 -> 2027 | I4: ='Revenue Sources'!I4 -> 2028 | J4: ='Revenue Sources'!J4 -> 2029
B5: Beginning Balance | D5: =C8 -> 79518 | E5: =D8 -> 96587 | F5: =E8 -> 121346 | G5: =F8 -> 142202.38 | H5: =G8 -> 159156.13 | I5: =H8 -> 172207.27 | J5: =I8 -> 181355.78
B6: add: Capex | D6: =SUM(D7:D8)-D5 -> 28247 | E6: =SUM(E7:E8)-E5 -> 40257 | F6: =$E$6 -> 40257 | G6: =$E$6 -> 40257 | H6: =$E$6 -> 40257 | I6: =$E$6 -> 40257 | J6: =$E$6 -> 40257
B7: less: Depreciation | C7: 8686 | D7: 11178 | E7: 15498 | F7: =(F5+F6)/F10 -> 19400.622 | G7: =(G5+G6)/G10 -> 23303.244 | H7: =(H5+H6)/H10 -> 27205.866 | I7: =(I5+I6)/I10 -> 31108.488 | J7: =(J5+J6)/J10 -> 35011.11
B8: Closing Balance | C8: ='Meta 10k Report '!C30 -> 79518 | D8: ='Meta 10k Report '!D30 -> 96587 | E8: ='Meta 10k Report '!E30 -> 121346 | F8: =SUM(F5:F6)-F7 -> 142202.38 | G8: =SUM(G5:G6)-G7 -> 159156.13 | H8: =SUM(H5:H6)-H7 -> 172207.27 | I8: =SUM(I5:I6)-I7 -> 181355.78 | J8: =SUM(J5:J6)-J7 -> 186601.67
B10: Useful life | D10: =(D5+D6)/D7 -> 9.6408123 | E10: =(E5+E6)/E7 -> 8.8297845 | F10: =E10-0.5 -> 8.3297845 | G10: =F10-0.5 -> 7.8297845 | H10: =G10-0.5 -> 7.3297845 | I10: =H10-0.5 -> 6.8297845 | J10: =I10-0.5 -> 6.3297845
B13: Debt Schedule
B14: Beginning Balance of Debt | D14: =C16 -> 15301 | E14: =D16 -> 18385 | F14: =E16 -> 28826 | G14: =F16 -> 39267 | H14: =G16 -> 49708 | I14: =H16 -> 60149 | J14: =I16 -> 70590
B15: add/less: Debt Taken /(debt repaid) | D15: =D16-D14 -> 3084 | E15: =E16-E14 -> 10441 | F15: =$E$15 -> 10441 | G15: =$E$15 -> 10441 | H15: =$E$15 -> 10441 | I15: =$E$15 -> 10441 | J15: =$E$15 -> 10441
B16: Closing Balance | C16: ='Meta 10k Report '!C43 -> 15301 | D16: ='Meta 10k Report '!D43 -> 18385 | E16: ='Meta 10k Report '!E43 -> 28826 | F16: =SUM(F14:F15) -> 39267 | G16: =SUM(G14:G15) -> 49708 | H16: =SUM(H14:H15) -> 60149 | I16: =SUM(I14:I15) -> 70590 | J16: =SUM(J14:J15) -> 81031
B18: Interest Expense | C18: ='Meta 10k Report '!C13 -> -125 | D18: ='Meta 10k Report '!D13 -> 677 | E18: ='Meta 10k Report '!E13 -> 1283 | F18: =F16*F19 -> 1747.7125 | G18: =G16*G19 -> 2212.425 | H18: =H16*H19 -> 2677.1375 | I18: =I16*I19 -> 3141.8501 | J18: =J16*J19 -> 3606.5626
C19: =C18/C16 -> -0.0081694007 | D19: =D18/D16 -> 0.036823497 | E19: =E18/E16 -> 0.04450843 | F19: =$E$19 -> 0.04450843 | G19: =$E$19 -> 0.04450843 | H19: =$E$19 -> 0.04450843 | I19: =$E$19 -> 0.04450843 | J19: =$E$19 -> 0.04450843

Sheet P&L
B2: Income Statement for Meta
B3: ='Meta 10k Report '!B3:E3 -> (In millions, except per share amounts)
B4: Particular | C4: ='Revenue Sources'!C4 -> 2022A | D4: ='Revenue Sources'!D4 -> 2023A | E4: ='Revenue Sources'!E4 -> 2024A | F4: ='Revenue Sources'!F4 -> 2025 | G4: ='Revenue Sources'!G4 -> 2026 | H4: ='Revenue Sources'!H4 -> 2027 | I4: ='Revenue Sources'!I4 -> 2028 | J4: ='Revenue Sources'!J4 -> 2029
B5: Revenue | C5: ='Revenue Sources'!C5 -> 116609 | D5: ='Revenue Sources'!D5 -> 134902 | E5: ='Revenue Sources'!E5 -> 164501 | F5: ='Revenue Sources'!F5 -> 196325.48 | G5: ='Revenue Sources'!G5 -> 233965.89 | H5: ='Revenue Sources'!H5 -> 278506.67 | I5: ='Revenue Sources'!I5 -> 331050.86 | J5: ='Revenue Sources'!J5 -> 392834.19
B6: % of Growth | D6: =D5/C5-1 -> 0.15687468 | E6: =E5/D5-1 -> 0.21941113 | F6: =F5/E5-1 -> 0.19346069 | G6: =G5/F5-1 -> 0.19172455 | H6: =H5/G5-1 -> 0.19037296 | I6: =I5/H5-1 -> 0.18866401 | J6: =J5/I5-1 -> 0.18662792
B8: COGS | C8: ='Other Items'!C5 -> 16563 | D8: ='Other Items'!D5 -> 14781 | E8: ='Other Items'!E5 -> 14663 | F8: ='Other Items'!F5 -> 16321.761 | G8: ='Other Items'!G5 -> 18047.248 | H8: ='Other Items'!H5 -> 19811.916 | I8: ='Other Items'!I5 -> 21563.407 | J8: ='Other Items'!J5 -> 23230.735
B10: Gross Profit | C10: =C5-C8 -> 100046 | D10: =D5-D8 -> 120121 | E10: =E5-E8 -> 149838 | F10: =F5-F8 -> 180003.72 | G10: =G5-G8 -> 215918.64 | H10: =H5-H8 -> 258694.76 | I10: =I5-I8 -> 309487.45 | J10: =J5-J8 -> 369603.45
B11: GP % | C11: =C10/C5 -> 0.85796122 | D11: =D10/D5 -> 0.89043157 | E11: =E10/E5 -> 0.91086376 | F11: =F10/F5 -> 0.91686376 | G11: =G10/G5 -> 0.92286376 | H11: =H10/H5 -> 0.92886376 | I11: =I10/I5 -> 0.93486376 | J11: =J10/J5 -> 0.94086376
B13: Operating Expense
B14: ='Other Items'!B8 -> Research and development | C14: ='Other Items'!C8 -> 35338 | D14: ='Other Items'!D8 -> 38483 | E14: ='Other Items'!E8 -> 43873 | F14: ='Other Items'!F8 -> 50397.446 | G14: ='Other Items'!G8 -> 57720.215 | H14: ='Other Items'!H8 -> 65923.517 | I14: ='Other Items'!I8 -> 75050.403 | J14: ='Other Items'!J8 -> 85128.561
B15: ='Other Items'!B11 -> Marketing and sales | C15: ='Other Items'!C11 -> 15262 | D15: ='Other Items'!D11 -> 12301 | E15: ='Other Items'!E11 -> 11347 | F15: ='Other Items'!F11 -> 11578.944 | G15: ='Other Items'!G11 -> 13798.912 | H15: ='Other Items'!H11 -> 16425.851 | I15: ='Other Items'!I11 -> 19524.818 | J15: ='Other Items'!J11 -> 23168.694
B16: ='Other Items'!B14 -> General and administrative | C16: ='Other Items'!C14 -> 11816 | D16: ='Other Items'!D14 -> 11408 | E16: ='Other Items'!E14 -> 9740 | F16: ='Other Items'!F14 -> 11624.307 | G16: ='Other Items'!G14 -> 13852.972 | H16: ='Other Items'!H14 -> 16490.204 | I16: ='Other Items'!I14 -> 19601.311 | J16: ='Other Items'!J14 -> 23259.463
B18: EBITDA | C18: =C10-C14-C15-C16 -> 37630 | D18: =D10-D14-D15-D16 -> 57929 | E18: =E10-E14-E15-E16 -> 84878 | F18: =F10-F14-F15-F16 -> 106403.02 | G18: =G10-G14-G15-G16 -> 130546.54 | H18: =H10-H14-H15-H16 -> 159855.18 | I18: =I10-I14-I15-I16 -> 195310.92 | J18: =J10-J14-J15-J16 -> 238046.73
B19: EBITDA % | C19: =C18/C5 -> 0.32270236 | D19: =D18/D5 -> 0.42941543 | E19: =E18/E5 -> 0.51597255 | F19: =F18/F5 -> 0.54197255 | G19: =G18/G5 -> 0.55797255 | H19: =H18/H5 -> 0.57397255 | I19: =I18/I5 -> 0.58997255 | J19: =J18/J5 -> 0.60597255
B21: Depreciation | C21: =Schedules!C7 -> 8686 | D21: =Schedules!D7 -> 11178 | E21: =Schedules!E7 -> 15498 | F21: =Schedules!F7 -> 19400.622 | G21: =Schedules!G7 -> 23303.244 | H21: =Schedules!H7 -> 27205.866 | I21: =Schedules!I7 -> 31108.488 | J21: =Schedules!J7 -> 35011.11
B23: EBIT | C23: =C18-C21 -> 28944 | D23: =D18-D21 -> 46751 | E23: =E18-E21 -> 69380 | F23: =F18-F21 -> 87002.397 | G23: =G18-G21 -> 107243.3 | H23: =H18-H21 -> 132649.32 | I23: =I18-I21 -> 164202.43 | J23: =J18-J21 -> 203035.62
B24: EBIT % | C24: =C23/C5 -> 0.24821412 | D24: =D23/D5 -> 0.34655528 | E24: =E23/E5 -> 0.42176035 | F24: =F23/F5 -> 0.44315388 | G24: =G23/G5 -> 0.45837152 | H24: =H23/H5 -> 0.47628776 | I24: =I23/I5 -> 0.49600364 | J24: =J23/J5 -> 0.51684815
B26: ='Meta 10k Report '!B13 -> Interest and other income (expense), net | C26: =Schedules!C18 -> -125 | D26: =Schedules!D18 -> 677 | E26: =Schedules!E18 -> 1283 | F26: =Schedules!F18 -> 1747.7125 | G26: =Schedules!G18 -> 2212.425 | H26: =Schedules!H18 -> 2677.1375 | I26: =Schedules!I18 -> 3141.8501 | J26: =Schedules!J18 -> 3606.5626
B28: EBI | C28: =C23+C26 -> 28819 | D28: =D23+D26 -> 47428 | E28: =E23+E26 -> 70663 | F28: =F23+F26 -> 88750.11 | G28: =G23+G26 -> 109455.73 | H28: =H23+H26 -> 135326.46 | I28: =I23+I26 -> 167344.28 | J28: =J23+J26 -> 206642.19
B29: EBI % | C29: =C28/C5 -> 0.24714216 | D29: =D28/D5 -> 0.35157374 | E29: =E28/E5 -> 0.4295597 | F29: =F28/F5 -> 0.452056 | G29: =G28/G5 -> 0.4678277 | H29: =H28/H5 -> 0.48590023 | I29: =I28/I5 -> 0.50549417 | J29: =J28/J5 -> 0.52602903
B31: Tax | C31: ='Meta 10k Report '!C15 -> 5619 | D31: ='Meta 10k Report '!D15 -> 8330 | E31: ='Meta 10k Report '!E15 -> 8303 | F31: =F28*F32 -> 10428.26 | G31: =G28*G32 -> 12861.199 | H31: =H28*H32 -> 15901.045 | I31: =I28*I32 -> 19663.184 | J31: =J28*J32 -> 24280.742
B32: Tax % | C32: =C31/C28 -> 0.19497554 | D32: =D31/D28 -> 0.17563465 | E32: =E31/E28 -> 0.11750138 | F32: =$E$32 -> 0.11750138 | G32: =$E$32 -> 0.11750138 | H32: =$E$32 -> 0.11750138 | I32: =$E$32 -> 0.11750138 | J32: =$E$32 -> 0.11750138
B34: Net Profit | C34: =C28-C31 -> 23200 | D34: =D28-D31 -> 39098 | E34: =E28-E31 -> 62360 | F34: =F28-F31 -> 78321.849 | G34: =G28-G31 -> 96594.527 | H34: =H28-H31 -> 119425.41 | I34: =I28-I31 -> 147681.1 | J34: =J28-J31 -> 182361.44
B35: Net Profit % | C35: =C34/C5 -> 0.19895548 | D35: =D34/D5 -> 0.28982521 | E35: =E34/E5 -> 0.37908584 | F35: =F34/F5 -> 0.39893879 | G35: =G34/G5 -> 0.4128573 | H35: =H34/H5 -> 0.42880628 | I35: =I34/I5 -> 0.44609791 | J35: =J34/J5 -> 0.46421989

Sheet Balanace Sheet
B2: Balance Sheet for Meta
B3: ='Revenue Sources'!B3:J3 -> (In millions, except per share amounts)
C4: ='Revenue Sources'!C4 -> 2022A | D4: ='Revenue Sources'!D4 -> 2023A | E4: ='Revenue Sources'!E4 -> 2024A | F4: ='Revenue Sources'!F4 -> 2025 | G4: ='Revenue Sources'!G4 -> 2026 | H4: ='Revenue Sources'!H4 -> 2027 | I4: ='Revenue Sources'!I4 -> 2028 | J4: ='Revenue Sources'!J4 -> 2029
B5: ='Meta 10k Report '!B22 -> Assets
B6: ='Meta 10k Report '!B23 -> Current assets:
B7: ='Meta 10k Report '!B24 -> Cash and cash equivalents | C7: ='Meta 10k Report '!C24 -> 14681 | D7: ='Meta 10k Report '!D24 -> 41862 | E7: ='Meta 10k Report '!E24 -> 43889 | F7: =E7+'Cash Flow'!C32 -> 106746.34 | G7: =F7+'Cash Flow'!D32 -> 199466.75 | H7: =G7+'Cash Flow'!E32 -> 319759.71 | I7: =H7+'Cash Flow'!F32 -> 473259.33 | J7: =I7+'Cash Flow'!G32 -> 666640.53
B8: ='Meta 10k Report '!B25 -> Marketable securities | C8: ='Meta 10k Report '!C25 -> 26057 | D8: ='Meta 10k Report '!D25 -> 23541 | E8: ='Meta 10k Report '!E25 -> 33926 | F8: 33926 | G8: 33926 | H8: 33926 | I8: 33926 | J8: 33926
B9: ='Meta 10k Report '!B26 -> Accounts receivable, net | C9: ='Meta 10k Report '!C26 -> 13466 | D9: ='Meta 10k Report '!D26 -> 16169 | E9: ='Meta 10k Report '!E26 -> 16994 | F9: ='Other Items'!F26 -> 20281.671 | G9: ='Other Items'!G26 -> 24170.165 | H9: ='Other Items'!H26 -> 28771.511 | I9: ='Other Items'!I26 -> 34199.66 | J9: ='Other Items'!J26 -> 40582.271
B10: ='Meta 10k Report '!B27 -> Prepaid expenses and other current assets | C10: ='Meta 10k Report '!C27 -> 5345 | D10: ='Meta 10k Report '!D27 -> 3793 | E10: ='Meta 10k Report '!E27 -> 5236 | F10: ='Other Items'!F17 -> 4285.7054 | G10: ='Other Items'!G17 -> 2767.7215 | H10: ='Other Items'!H17 -> 509.55406 | I10: ='Other Items'!I17 -> -2704.82 | J10: ='Other Items'!J17 -> -7137.9568
B11: ='Meta 10k Report '!B28 -> Total current assets | C11: ='Meta 10k Report '!C28 -> 59549 | D11: ='Meta 10k Report '!D28 -> 85365 | E11: ='Meta 10k Report '!E28 -> 100045 | F11: =SUM(F7:F10) -> 165239.72 | G11: =SUM(G7:G10) -> 260330.63 | H11: =SUM(H7:H10) -> 382966.78 | I11: =SUM(I7:I10) -> 538680.17 | J11: =SUM(J7:J10) -> 734010.85
B12: ='Meta 10k Report '!B29 -> Non-marketable equity securities | C12: ='Meta 10k Report '!C29 -> 6201 | D12: ='Meta 10k Report '!D29 -> 6141 | E12: ='Meta 10k Report '!E29 -> 6070 | F12: 6070 | G12: 6070 | H12: 6070 | I12: 6070 | J12: 6070
B13: ='Meta 10k Report '!B30 -> Property and equipment, net | C13: ='Meta 10k Report '!C30 -> 79518 | D13: ='Meta 10k Report '!D30 -> 96587 | E13: ='Meta 10k Report '!E30 -> 121346 | F13: =Schedules!F8 -> 142202.38 | G13: =Schedules!G8 -> 159156.13 | H13: =Schedules!H8 -> 172207.27 | I13: =Schedules!I8 -> 181355.78 | J13: =Schedules!J8 -> 186601.67
B14: ='Meta 10k Report '!B31 -> Operating lease right-of-use assets | C14: ='Meta 10k Report '!C31 -> 12673 | D14: ='Meta 10k Report '!D31 -> 13294 | E14: ='Meta 10k Report '!E31 -> 14922 | F14: 14922 | G14: 14922 | H14: 14922 | I14: 14922 | J14: 14922
B15: ='Meta 10k Report '!B32 -> Goodwill | C15: ='Meta 10k Report '!C32 -> 20306 | D15: ='Meta 10k Report '!D32 -> 20654 | E15: ='Meta 10k Report '!E32 -> 20654 | F15: 20654 | G15: 20654 | H15: 20654 | I15: 20654 | J15: 20654
B16: ='Meta 10k Report '!B33 -> Other assets | C16: ='Meta 10k Report '!C33 -> 7480 | D16: ='Meta 10k Report '!D33 -> 7582 | E16: ='Meta 10k Report '!E33 -> 13017 | F16: 13017 | G16: 13017 | H16: 13017 | I16: 13017 | J16: 13017
B17: ='Meta 10k Report '!B34 -> Total assets | C17: ='Meta 10k Report '!C34 -> 185727 | D17: ='Meta 10k Report '!D34 -> 229623 | E17: ='Meta 10k Report '!E34 -> 276054 | F17: =SUM(F11:F16) -> 362105.09 | G17: =SUM(G11:G16) -> 474149.77 | H17: =SUM(H11:H16) -> 609837.05 | I17: =SUM(I11:I16) -> 774698.95 | J17: =SUM(J11:J16) -> 975275.52
B19: ='Meta 10k Report '!B36 -> Liabilities and stockholders' equity
B20: ='Meta 10k Report '!B37 -> Current liabilities:
B21: ='Meta 10k Report '!B38 -> Accounts payable | C21: ='Meta 10k Report '!C38 -> 4990 | D21: ='Meta 10k Report '!D38 -> 4849 | E21: ='Meta 10k Report '!E38 -> 7687 | F21: ='Other Items'!F20 -> 6276.1248 | G21: ='Other Items'!G20 -> 6939.6176 | H21: ='Other Items'!H20 -> 7618.1765 | I21: ='Other Items'!I20 -> 8291.6683 | J21: ='Other Items'!J20 -> 8932.7978
B22: ='Meta 10k Report '!B39 -> Operating lease liabilities, current | C22: ='Meta 10k Report '!C39 -> 1117 | D22: ='Meta 10k Report '!D39 -> 1623 | E22: ='Meta 10k Report '!E39 -> 1942 | F22: 1942 | G22: 1942 | H22: 1942 | I22: 1942 | J22: 1942
B23: ='Meta 10k Report '!B40 -> Accrued expenses and other current liabilities | C23: ='Meta 10k Report '!C40 -> 1367 | D23: ='Meta 10k Report '!D40 -> 25488 | E23: ='Meta 10k Report '!E40 -> 23967 | F23: ='Other Items'!F23 -> 22666.12 | G23: ='Other Items'!G23 -> 27011.772 | H23: ='Other Items'!H23 -> 32154.083 | I23: ='Other Items'!I23 -> 38220.401 | J23: ='Other Items'!J23 -> 45353.395
B24: ='Meta 10k Report '!B41 -> Total current liabilities | C24: ='Meta 10k Report '!C41 -> 19552 | D24: ='Meta 10k Report '!D41 -> 31960 | E24: ='Meta 10k Report '!E41 -> 33596 | F24: =SUM(F21:F23) -> 30884.245 | G24: =SUM(G21:G23) -> 35893.39 | H24: =SUM(H21:H23) -> 41714.26 | I24: =SUM(I21:I23) -> 48454.069 | J24: =SUM(J21:J23) -> 56228.193
B25: ='Meta 10k Report '!B42 -> Operating lease liabilities, non-current | C25: ='Meta 10k Report '!C42 -> 27026 | D25: ='Meta 10k Report '!D42 -> 17226 | E25: ='Meta 10k Report '!E42 -> 18292 | F25: 18292 | G25: 18292 | H25: 18292 | I25: 18292 | J25: 18292
B26: ='Meta 10k Report '!B43 -> Long-term debt | C26: ='Meta 10k Report '!C43 -> 15301 | D26: ='Meta 10k Report '!D43 -> 18385 | E26: ='Meta 10k Report '!E43 -> 28826 | F26: =Schedules!F16 -> 39267 | G26: =Schedules!G16 -> 49708 | H26: =Schedules!H16 -> 60149 | I26: =Schedules!I16 -> 70590 | J26: =Schedules!J16 -> 81031
B27: ='Meta 10k Report '!B44 -> Long-term income taxes | C27: ='Meta 10k Report '!C44 -> 9923 | D27: ='Meta 10k Report '!D44 -> 7514 | E27: ='Meta 10k Report '!E44 -> 9987 | F27: 9987 | G27: 9987 | H27: 9987 | I27: 9987 | J27: 9987
B28: ='Meta 10k Report '!B45 -> Other liabilities | C28: ='Meta 10k Report '!C45 -> 7764 | D28: ='Meta 10k Report '!D45 -> 1370 | E28: ='Meta 10k Report '!E45 -> 2716 | F28: 2716 | G28: 2716 | H28: 2716 | I28: 2716 | J28: 2716
B29: ='Meta 10k Report '!B46 -> Total liabilities | C29: ='Meta 10k Report '!C46 -> 60014 | D29: ='Meta 10k Report '!D46 -> 76455 | E29: ='Meta 10k Report '!E46 -> 93417 | F29: =SUM(F24:F28) -> 101146.24 | G29: =SUM(G24:G28) -> 116596.39 | H29: =SUM(H24:H28) -> 132858.26 | I29: =SUM(I24:I28) -> 150039.07 | J29: =SUM(J24:J28) -> 168254.19
B30: ='Meta 10k Report '!B47 -> Commitments and contingencies
B31: ='Meta 10k Report '!B48 -> Stockholders' equity:
B32: ='Meta 10k Report '!B49 -> Additional paid-in capital | C32: ='Meta 10k Report '!C49 -> 64444 | D32: ='Meta 10k Report '!D49 -> 73253 | E32: ='Meta 10k Report '!E49 -> 83228 | F32: 83228 | G32: 83228 | H32: 83228 | I32: 83228 | J32: 83228
B33: ='Meta 10k Report '!B50 -> Accumulated other comprehensive loss | C33: ='Meta 10k Report '!C50 -> -3530 | D33: ='Meta 10k Report '!D50 -> -2155 | E33: ='Meta 10k Report '!E50 -> -3097 | F33: -3097 | G33: -3097 | H33: -3097 | I33: -3097 | J33: -3097
B34: ='Meta 10k Report '!B51 -> Retained earnings | C34: ='Meta 10k Report '!C51 -> 64799 | D34: ='Meta 10k Report '!D51 -> 82070 | E34: ='Meta 10k Report '!E51 -> 102506 | F34: =E34+'P&L'!F34 -> 180827.85 | G34: =F34+'P&L'!G34 -> 277422.38 | H34: =G34+'P&L'!H34 -> 396847.79 | I34: =H34+'P&L'!I34 -> 544528.88 | J34: =I34+'P&L'!J34 -> 726890.33
B35: ='Meta 10k Report '!B52 -> Total stockholders' equity | C35: ='Meta 10k Report '!C52 -> 125713 | D35: ='Meta 10k Report '!D52 -> 153168 | E35: ='Meta 10k Report '!E52 -> 182637 | F35: =SUM(F32:F34) -> 260958.85 | G35: =SUM(G32:G34) -> 357553.38 | H35: =SUM(H32:H34) -> 476978.79 | I35: =SUM(I32:I34) -> 624659.88 | J35: =SUM(J32:J34) -> 807021.33
B36: ='Meta 10k Report '!B53 -> Total liabilities and stockholders' equity | C36: ='Meta 10k Report '!C53 -> 185727 | D36: ='Meta 10k Report '!D53 -> 229623 | E36: ='Meta 10k Report '!E53 -> 276054 | F36: =F29+F35 -> 362105.09 | G36: =G29+G35 -> 474149.77 | H36: =H29+H35 -> 609837.05 | I36: =I29+I35 -> 774698.95 | J36: =J29+J35 -> 975275.52
B38: Check | C38: =C17=C36 -> TRUE | D38: =D17=D36 -> TRUE | E38: =E17=E36 -> TRUE | F38: =F17=F36 -> TRUE | G38: =G17=G36 -> TRUE | H38: =H17=H36 -> TRUE | I38: =I17=I36 -> TRUE | J38: =J17=J36 -> TRUE

Sheet Cash Flow
B2: Cash Flow for Meta
B3: ='Revenue Sources'!B3:J3 -> (In millions, except per share amounts)
B4: ='P&L'!B4 -> Particular | C4: ='P&L'!F4 -> 2025 | D4: ='P&L'!G4 -> 2026 | E4: ='P&L'!H4 -> 2027 | F4: ='P&L'!I4 -> 2028 | G4: ='P&L'!J4 -> 2029
B5: EBIT | C5: ='P&L'!F23 -> 87002.397 | D5: ='P&L'!G23 -> 107243.3 | E5: ='P&L'!H23 -> 132649.32 | F5: ='P&L'!I23 -> 164202.43 | G5: ='P&L'!J23 -> 203035.62
B6: (-)Operating Taxes | C6: =C5*C7 -> 10222.902 | D6: =D5*D7 -> 12601.236 | E6: =E5*E7 -> 15586.478 | F6: =F5*F7 -> 19294.012 | G6: =G5*G7 -> 23856.966
B7: (-)Operation Tax Rate | C7: ='P&L'!F32 -> 0.11750138 | D7: ='P&L'!G32 -> 0.11750138 | E7: ='P&L'!H32 -> 0.11750138 | F7: ='P&L'!I32 -> 0.11750138 | G7: ='P&L'!J32 -> 0.11750138
B9: NOPAT | C9: =C5-C6 -> 76779.495 | D9: =D5-D6 -> 94642.065 | E9: =E5-E6 -> 117062.84 | F9: =F5-F6 -> 144908.42 | G9: =G5-G6 -> 179178.66
B11: (+)Depretiation | C11: =Schedules!F7 -> 19400.622 | D11: =Schedules!G7 -> 23303.244 | E11: =Schedules!H7 -> 27205.866 | F11: =Schedules!I7 -> 31108.488 | G11: =Schedules!J7 -> 35011.11
B13: Gross Cash Flow | C13: =C9+C11 -> 96180.117 | D13: =D9+D11 -> 117945.31 | E13: =E9+E11 -> 144268.71 | F13: =F9+F11 -> 176016.9 | G13: =G9+G11 -> 214189.77
B15: Account Payable | C15: ='Other Items'!F20-'Other Items'!E20 -> -1410.8752 | D15: ='Other Items'!G20-'Other Items'!F20 -> 663.49286 | E15: ='Other Items'!H20-'Other Items'!G20 -> 678.55893 | F15: ='Other Items'!I20-'Other Items'!H20 -> 673.49178 | G15: ='Other Items'!J20-'Other Items'!I20 -> 641.12946
B16: Account Receivable | C16: ='Other Items'!F26-'Other Items'!E26 -> 3287.671 | D16: ='Other Items'!G26-'Other Items'!F26 -> 3888.4943 | E16: ='Other Items'!H26-'Other Items'!G26 -> 4601.3459 | F16: ='Other Items'!I26-'Other Items'!H26 -> 5428.1486 | G16: ='Other Items'!J26-'Other Items'!I26 -> 6382.6113
B17: Accrued Expenses & other Liabilities | C17: ='Other Items'!F23-'Other Items'!E23 -> -1300.8798 | D17: ='Other Items'!G23-'Other Items'!F23 -> 4345.6518 | E17: ='Other Items'!H23-'Other Items'!G23 -> 5142.311 | F17: ='Other Items'!I23-'Other Items'!H23 -> 6066.3181 | G17: ='Other Items'!J23-'Other Items'!I23 -> 7132.9938
B18: Other Current Asset | C18: ='Other Items'!F17-'Other Items'!E17 -> -950.29459 | D18: ='Other Items'!G17-'Other Items'!F17 -> -1517.984 | E18: ='Other Items'!H17-'Other Items'!G17 -> -2258.1674 | F18: ='Other Items'!I17-'Other Items'!H17 -> -3214.374 | G18: ='Other Items'!J17-'Other Items'!I17 -> -4433.1368
B20: (-)Investment in Working Capital | C20: =C15+C17-C16-C18 -> -5049.1314 | D20: =D15+D17-D16-D18 -> 2638.6343 | E20: =E15+E17-E16-E18 -> 3477.6914 | F20: =F15+F17-F16-F18 -> 4526.0354 | G20: =G15+G17-G16-G18 -> 5824.6488
B22: PP&E | C22: =Schedules!F6 -> 40257 | D22: =Schedules!G6 -> 40257 | E22: =Schedules!H6 -> 40257 | F22: =Schedules!I6 -> 40257 | G22: =Schedules!J6 -> 40257
B24: (-)Capex | C24: =-C22 -> -40257 | D24: =-D22 -> -40257 | E24: =-E22 -> -40257 | F24: =-F22 -> -40257 | G24: =-G22 -> -40257
B26: UFCF | C26: =C24+C20+C13 -> 50873.986 | D26: =D24+D20+D13 -> 80326.943 | E26: =E24+E20+E13 -> 107489.4 | F26: =F24+F20+F13 -> 140285.94 | G26: =G24+G20+G13 -> 179757.42
B28: Diff b/w Actual & Operating Tax | C28: ='P&L'!F31-'Cash Flow'!C6 -> 205.35863 | D28: ='P&L'!G31-'Cash Flow'!D6 -> 259.96299 | E28: ='P&L'!H31-'Cash Flow'!E6 -> 314.56736 | F28: ='P&L'!I31-'Cash Flow'!F6 -> 369.17172 | G28: ='P&L'!J31-'Cash Flow'!G6 -> 423.77608
B29: Interest Expense | C29: =Schedules!F18 -> 1747.7125 | D29: =Schedules!G18 -> 2212.425 | E29: =Schedules!H18 -> 2677.1375 | F29: =Schedules!I18 -> 3141.8501 | G29: =Schedules!J18 -> 3606.5626
B30: Debt Repaid | C30: =Schedules!F15 -> 10441 | D30: =Schedules!G15 -> 10441 | E30: =Schedules!H15 -> 10441 | F30: =Schedules!I15 -> 10441 | G30: =Schedules!J15 -> 10441
B32: Net Cash Flow | C32: =C26-C28+C29+C30 -> 62857.34 | D32: =D26-D28+D29+D30 -> 92720.405 | E32: =E26-E28+E29+E30 -> 120292.97 | F32: =F26-F28+F29+F30 -> 153499.62 | G32: =G26-G28+G29+G30 -> 193381.2

Sheet WACC
B2: Working Average Cost of Capital
B4: Risk Free Rate | C4: 0.044
B5: Market Risk Premium | C5: 0.045
B6: Beta | C6: 1.39
B9: Cost of Equity | C9: =C4+C5*C6 -> 0.10655
B10: Cost of Debt | C10: 0.04
B11: Equity | C11: ='Balanace Sheet'!J35 -> 807021.33
B12: Debt | C12: ='Balanace Sheet'!J26 -> 81031
B13: Weight of Equity | C13: =C11/(C11+C12) -> 0.90875425
B14: Weight of Debt | C14: =C12/(C11+C12) -> 0.091245749
B16: WACC | C16: =(C9*C13)+(C10*C14) -> 0.1004776

Sheet DCF
B2: DCF Model
B3: ='Cash Flow'!B3:G3 -> (In millions, except per share amounts)
B4: ='Cash Flow'!B4 -> Particular | C4: ='Cash Flow'!C4 -> 2025 | D4: ='Cash Flow'!D4 -> 2026 | E4: ='Cash Flow'!E4 -> 2027 | F4: ='Cash Flow'!F4 -> 2028 | G4: ='Cash Flow'!G4 -> 2029
B5: UFCF | C5: ='Cash Flow'!C26 -> 50873.986 | D5: ='Cash Flow'!D26 -> 80326.943 | E5: ='Cash Flow'!E26 -> 107489.4 | F5: ='Cash Flow'!F26 -> 140285.94 | G5: ='Cash Flow'!G26 -> 179757.42
B6: Discounted Factor | C6: =1/(1+$C$8)^C7 -> 0.90869637 | D6: =1/(1+$C$8)^D7 -> 0.8257291 | E6: =1/(1+$C$8)^E7 -> 0.75033704 | F6: =1/(1+$C$8)^F7 -> 0.68182855 | G6: =1/(1+$C$8)^G7 -> 0.61957513
B7: No. of Years | C7: 1 | D7: 2 | E7: 3 | F7: 4 | G7: 5
B8: WACC | C8: =WACC!C16 -> 0.1004776
B10: PV of Future Cash Flow | C10: =C5*C6 -> 46229.007 | D10: =D5*D6 -> 66328.294 | E10: =E5*E6 -> 80653.276 | F10: =F5*F6 -> 95650.958 | G10: =G5*G6 -> 111373.22
B12: Sum of PV | C12: =SUM(C10:G10) -> 400234.76
B14: Growth Rate | C14: 0.028
B15: TV of Cash Flow | C15: =G5*(1+C14)/(C8-C14) -> 2549624.1 | E15: Sensitivity Analysis
E16: =C19 -> 1979918.4 | F16: 0.08 | G16: 0.09 | H16: 0.1004776 | I16: 0.11 | J16: 0.12
B17: PV of Terminal Value/Continuins Value | C17: =C15*G6 -> 1579683.7 | E17: 0.01 | F17: 2191945.4 | G17: 1888475.2 | H17: 1643492.2 | I17: 1466151.4 | J17: 1313659.6
E18: 0.02 | F18: 2506533.6 | G18: 2115876.4 | H18: 1811816.2 | I18: 1597720 | J18: 1417513.3
B19: Enterprise Value | C19: =C12+C17 -> 1979918.4 | E19: 0.028 | F19: 2845321 | G19: 2350613.1 | H19: 1979918.3 | I19: 1726079.7 | J19: 1516851.6
B20: Debt | C20: ='Balanace Sheet'!J26 -> 81031 | E20: 0.04 | F20: 3607592.5 | G20: 2843560.3 | H20: 2315458.7 | I20: 1973630.4 | J20: 1703111
B21: Cash | C21: ='Balanace Sheet'!J7 -> 666640.53 | E21: 0.05 | F21: 4708651.4 | G21: 3480283.7 | H21: 2716943.2 | I21: 2255563.2 | J21: 1907109.4
B22: Equity Value | C22: =C19-C20+C21 -> 2565528
B23: Outstanding Shares | C23: 2521
B25: Fair Price | C25: =C22/C23 -> 1017.6628
