Workbook

Sheet Netflix DCF Model Raw Data 
B2: Netflix Raw Data
B4: Income Statement for Netflix | C4: Year 2022 | D4: Year 2023 | E4: Year 2024
B5: Revenues | C5: $ 31,615,550 | D5: $ 33,723,297 | E5: $ 39,000,966
B6: Cost of revenues | C6: 19168285 | D6: 19715368 | E6: 21038464
B7: Sales and marketing | C7: 2530502 | D7: 2657883 | E7: 2917554
B8: Technology and development | C8: 2711041 | D8: 2675758 | E8: 2925295
B9: General and administrative | C9: 1572891 | D9: 1720285 | E9: 1702039
B10: Operating income | C10: 5632831 | D10: 6954003 | E10: 10417614
B11: Other income (expense):
B12: Interest expense | C12: -706212 | D12: -699826 | E12: -718733
B13: Interest and other income (expense) | C13: 337310 | D13: -48772 | E13: 266776
B14: Income before income taxes | C14: 5263929 | D14: 6205405 | E14: 9965657
B15: Provision for income taxes | C15: -772005 | D15: -797415 | E15: -1254026
B16: Net income | C16: $ 4,491,924 | D16: $ 5,407,990 | E16: $ 8,711,631
B19: Balanace Sheet | C19: Year 2022 | D19: Year 2023 | E19: Year 2024
B20: Assets
B21: Current assets:
B22: Cash and cash equivalents | C22: 5147176 | D22: 7116913 | E22: 7804733
B23: Short-term investments | C23: 911276 | D23: 20973 | E23: 1779006
B24: Other current assets | C24: 3208021 | D24: 2780247 | E24: 3516640
B25: Total current assets | C25: 9266473 | D25: 9918133 | E25: 13100379
B26: Content assets, net | C26: 32736713 | D26: 31658056 | E26: 32452462
B27: Property and equipment, net | C27: 1398257 | D27: 1491444 | E27: 1593756
B28: Other non-current assets | C28: 5193325 | D28: 5664359 | E28: 6483777
B29: Total assets | C29: 48594768 | D29: 48731992 | E29: 53630374
B30: Liabilities and Stockholders’ Equity
B31: Current liabilities:
B32: Current content liabilities | C32: 4480150 | D32: 4466470 | E32: 4393681
B33: Accounts payable | C33: 671513 | D33: 747412 | E33: 899909
B34: Accrued expenses and other liabilities | C34: 1514650 | D34: 1803960 | E34: 2156544
B35: Deferred revenue | C35: 1264661 | D35: 1442969 | E35: 1520813
B36: Short-term debt | C36: - | D36: 399844 | E36: 1784453
B37: Total current liabilities | C37: 7930974 | D37: 8860655 | E37: 10755400
B38: Non-current content liabilities | C38: 3081277 | D38: 2578173 | E38: 1780806
B39: Long-term debt | C39: 14353076 | D39: 14143417 | E39: 13798351
B40: Other non-current liabilities | C40: 2452040 | D40: 2561434 | E40: 2552250
B41: Total liabilities | C41: 27817367 | D41: 28143679 | E41: 28886807
B42: Stockholders’ equity:
B43: Common stock | C43: 4637601 | D43: 5145172 | E43: 6252126
B44: Treasury stock at cost | C44: -824190 | D44: -6922200 | E44: -13171638
...

Sheet Revenue Modelling
B1: Revenue Sources
B2: (in thousands) | C2: 2022 | D2: 2023 | E2: 2024 | F2: 2025 F | G2: 2026 F | H2: 2027 F | I2: 2028 F | J2: 2029 F
B4: Streaming revenues | C4: =C11+C18+C25+C32 -> 31469852 | D4: =D11+D18+D25+D32 -> 33640458 | E4: =E11+E18+E25+E32 -> 39000966 | F4: =F11+F18+F25+F32 -> 42853158 | G4: =G11+G18+G25+G32 -> 47947761 | H4: =H11+H18+H25+H32 -> 53585177 | I4: =I11+I18+I25+I32 -> 60283217 | J4: =J11+J18+J25+J32 -> 67614889
B5: DVD revenues | C5: 145698 | D5: 82839 | E5: - | F5: - | G5: - | H5: - | I5: - | J5: -
B6: Growth % | D6: =D7/C7-1 -> 0.066668048 | E6: =E7/D7-1 -> 0.1564992 | F6: =F7/E7-1 -> 0.098771719 | G6: =G7/F7-1 -> 0.11888511 | H6: =H7/G7-1 -> 0.11757413 | I6: =I7/H7-1 -> 0.12499801 | J6: =J7/I7-1 -> 0.12162044
B7: Total Revenues | C7: =C4+C5 -> 31615550 | D7: =D4+D5 -> 33723297 | E7: =E4 -> 39000966 | F7: =F4 -> 42853158 | G7: =G4 -> 47947761 | H7: =H4 -> 53585177 | I7: =I4 -> 60283217 | J7: =J4 -> 67614889
B10: Unites States and Canada ( in thousands) | K10: Average Monthly Revenue UCAN
B11: Revenue | C11: 14084643 | D11: 14873783 | E11: 17359369 | F11: =F13*F12 -> 17706789 | G11: =G13*G12 -> 19224435 | H11: =H13*H12 -> 20689765 | I11: =I13*I12 -> 22364933 | J11: =J13*J12 -> 24122686 | K11: 2022 | L11: 2023 | M11: 2024
B12: Average yearly revenue per membership | C12: =K12*12 -> 190.32 | D12: =L12*12 -> 195.36 | E12: =M12*12 -> 206.4 | F12: =AVERAGE($C$12:$E$12) -> 197.36 | G12: =AVERAGE($C$12:$E$12) -> 197.36 | H12: =AVERAGE($C$12:$E$12) -> 197.36 | I12: =AVERAGE($C$12:$E$12) -> 197.36 | J12: =AVERAGE($C$12:$E$12) -> 197.36 | K12: 15.86 | L12: 16.28 | M12: 17.2
B13: Average Paid membership | C13: =C11/C12 -> 74005.06 | D13: =D11/D12 -> 76135.253 | E13: =E11/E12 -> 84105.47 | F13: =E13*(1+F14) -> 89718.223 | G13: =F13*(1+G14) -> 97407.958 | H13: =G13*(1+H14) -> 104832.61 | I13: =H13*(1+I14) -> 113320.5 | J13: =I13*(1+J14) -> 122226.83
B14: Growth % | C14: - | D14: =D13/C13-1 -> 0.028784423 | E14: =E13/D13-1 -> 0.10468498 | F14: =AVERAGE(D14:E14) -> 0.066734699 | G14: =AVERAGE(E14:F14) -> 0.085709838 | H14: =AVERAGE(F14:G14) -> 0.076222269 | I14: =AVERAGE(G14:H14) -> 0.080966053 | J14: =AVERAGE(H14:I14) -> 0.078594161
B17: Europe, Middle East, and Africa (EMEA) (in thousands) | K17: Average Monthly Revenue EMEA
B18: Revenues | C18: 9745015 | D18: 10556487 | E18: 12387035 | F18: =F20*F19 -> 13965617 | G18: =G20*G19 -> 16013456 | H18: =H20*H19 -> 18224384 | I18: =I20*I19 -> 20818637 | J18: =J20*J19 -> 23737592 | K18: 2022 | L18: 2023 | M18: 2024
B19: Average yearly revenue per membership | C19: =K19*12 -> 131.88 | D19: =L19*12 -> 130.44 | E19: =M19*12 -> 131.52 | F19: =AVERAGE($C$19:$E$19) -> 131.28 | G19: =AVERAGE($C$19:$E$19) -> 131.28 | H19: =AVERAGE($C$19:$E$19) -> 131.28 | I19: =AVERAGE($C$19:$E$19) -> 131.28 | J19: =AVERAGE($C$19:$E$19) -> 131.28 | K19: 10.99 | L19: 10.87 | M19: 10.96
B20: Average Paid membership | C20: =C18/C19 -> 73893.047 | D20: =D18/D19 -> 80929.83 | E20: =E18/E19 -> 94183.66 | F20: =E20*(1+F21) -> 106380.38 | G20: =F20*(1+G21) -> 121979.41 | H20: =G20*(1+H21) -> 138820.72 | I20: =H20*(1+I21) -> 158581.94 | J20: =I20*(1+J21) -> 180816.51
B21: Growth % | C21: - | D21: =D20/C20-1 -> 0.0952293 | E21: =E20/D20-1 -> 0.16376941 | F21: =AVERAGE(D21:E21) -> 0.12949935 | G21: =AVERAGE(E21:F21) -> 0.14663438 | H21: =AVERAGE(F21:G21) -> 0.13806687 | I21: =AVERAGE(G21:H21) -> 0.14235063 | J21: =AVERAGE(H21:I21) -> 0.14020875
B24: Latin America (LATAM) (in thousands) | K24: Average Monthly Revenue Latin A
B25: Revenues | C25: 4069973 | D25: 4446461 | E25: 4839816 | F25: =F27*F26 -> 5500076.6 | G25: =G27*G26 -> 6087871.5 | H25: =H27*H26 -> 6738484.2 | I25: =I27*I26 -> 7458628 | J25: =J27*J26 -> 8255733.9 | K25: 2022 | L25: 2023 | M25: 2024
B26: Average yearly revenue per membership | C26: =K26*12 -> 101.76 | D26: =L26*12 -> 103.92 | E26: =M26*12 -> 98.88 | F26: =AVERAGE($C$26:$E$26) -> 101.52 | G26: =AVERAGE($C$26:$E$26) -> 101.52 | H26: =AVERAGE($C$26:$E$26) -> 101.52 | I26: =AVERAGE($C$26:$E$26) -> 101.52 | J26: =AVERAGE($C$26:$E$26) -> 101.52 | K26: 8.48 | L26: 8.66 | M26: 8.24
B27: Average Paid membership | C27: =C25/C26 -> 39995.804 | D27: =D25/D26 -> 42787.346 | E27: =E25/E26 -> 48946.359 | F27: =E27*(1+F28) -> 54177.272 | G27: =F27*(1+G28) -> 59967.213 | H27: =G27*(1+H28) -> 66375.928 | I27: =H27*(1+I28) -> 73469.543 | J27: =I27*(1+J28) -> 81321.256
B28: Growth % | C28: - | D28: =D27/C27-1 -> 0.069795876 | E28: =E27/D27-1 -> 0.14394474 | F28: =AVERAGE($D$28:$E$28) -> 0.10687031 | G28: =AVERAGE($D$28:$E$28) -> 0.10687031 | H28: =AVERAGE($D$28:$E$28) -> 0.10687031 | I28: =AVERAGE($D$28:$E$28) -> 0.10687031 | J28: =AVERAGE($D$28:$E$28) -> 0.10687031
B31: Asia-Pacific (in thousands) | K31: Average Monthly Revenue APAC
B32: Revenues | C32: 3570221 | D32: 3763727 | E32: 4414746 | F32: =F34*F33 -> 5680676.6 | G32: =G34*G33 -> 6621998.4 | H32: =H34*H33 -> 7932544.1 | I32: =I34*I33 -> 9641019.7 | J32: =J34*J33 -> 11498877 | K32: 2022 | L32: 2023 | M32: 2024
B33: Average yearly revenue per membership | C33: =K33*12 -> 102 | D33: =L33*12 -> 91.68 | E33: =M33*12 -> 87.48 | F33: =AVERAGE(C33:E33) -> 93.72 | G33: =AVERAGE(D33:F33) -> 90.96 | H33: =AVERAGE(E33:G33) -> 90.72 | I33: =AVERAGE(F33:H33) -> 91.8 | J33: =AVERAGE(G33:I33) -> 91.16 | K33: 8.5 | L33: 7.64 | M33: 7.29
B34: Average Paid membership | C34: =C32/C33 -> 35002.167 | D34: =D32/D33 -> 41052.869 | E34: =E32/E33 -> 50465.775 | F34: =E34*(1+F35) -> 60613.28 | G34: =F34*(1+G35) -> 72801.214 | H34: =G34*(1+H35) -> 87439.86 | I34: =H34*(1+I35) -> 105022 | J34: =I34*(1+J35) -> 126139.51
B35: Growth % | C35: - | D35: =D34/C34-1 -> 0.1728665 | E35: =E34/D34-1 -> 0.22928742 | F35: =AVERAGE($D$35:$E$35) -> 0.20107696 | G35: =AVERAGE($D$35:$E$35) -> 0.20107696 | H35: =AVERAGE($D$35:$E$35) -> 0.20107696 | I35: =AVERAGE($D$35:$E$35) -> 0.20107696 | J35: =AVERAGE($D$35:$E$35) -> 0.20107696

Sheet Other Items of P&L
B1: Other Items
B2: (in thousands) | C2: 2022 | D2: 2023 | E2: 2024 | F2: 2025 F | G2: 2026 F | H2: 2027 F | I2: 2028 F | J2: 2029 F
B3: Cost of Goods Sold | C3: ='Netflix DCF Model Raw Data '!C6-Schedules!C7 -> 18831603 | D3: ='Netflix DCF Model Raw Data '!D6-Schedules!D7 -> 19358421 | E3: ='Netflix DCF Model Raw Data '!E6-Schedules!E7 -> 20709550 | F3: =F4*'Revenue Modelling'!F7 -> 24293194 | G3: =G4*'Revenue Modelling'!G7 -> 25283363 | H3: =H4*'Revenue Modelling'!H7 -> 25813863 | I3: =I4*'Revenue Modelling'!I7 -> 28050578 | J3: =J4*'Revenue Modelling'!J7 -> 29172647
B4: as a % revenues | C4: =C3/'Revenue Modelling'!C7 -> 0.59564369 | D4: =D3/'Revenue Modelling'!D7 -> 0.57403702 | E4: =E3/'Revenue Modelling'!E7 -> 0.53100095 | F4: =AVERAGE(C4:E4) -> 0.56689389 | G4: =AVERAGE(D4:F4)-3% -> 0.52731062 | H4: =AVERAGE(E4:G4)-6% -> 0.48173515 | I4: =AVERAGE(F4:H4)-6% -> 0.46531322 | J4: =AVERAGE(G4:I4)-6% -> 0.431453
B6: ='Netflix DCF Model Raw Data '!B7 -> Sales and marketing | C6: ='Netflix DCF Model Raw Data '!C7 -> 2530502 | D6: ='Netflix DCF Model Raw Data '!D7 -> 2657883 | E6: ='Netflix DCF Model Raw Data '!E7 -> 2917554 | F6: =F7*'Revenue Modelling'!F7 -> 3337710.5 | G6: =G7*'Revenue Modelling'!G7 -> 3734514.6 | H6: =H7*'Revenue Modelling'!H7 -> 4173596.9 | I6: =I7*'Revenue Modelling'!I7 -> 4695288.2 | J6: =J7*'Revenue Modelling'!J7 -> 5266331.3
B7: as a % revenues | C7: =C6/'Revenue Modelling'!C7 -> 0.080039791 | D7: =D6/'Revenue Modelling'!D7 -> 0.078814447 | E7: =E6/'Revenue Modelling'!E7 -> 0.074807224 | F7: =AVERAGE($C$7:$E$7) -> 0.077887154 | G7: =AVERAGE($C$7:$E$7) -> 0.077887154 | H7: =AVERAGE($C$7:$E$7) -> 0.077887154 | I7: =AVERAGE($C$7:$E$7) -> 0.077887154 | J7: =AVERAGE($C$7:$E$7) -> 0.077887154
B9: Technology and Development | C9: ='Netflix DCF Model Raw Data '!C8 -> 2711041 | D9: ='Netflix DCF Model Raw Data '!D8 -> 2675758 | E9: ='Netflix DCF Model Raw Data '!E8 -> 2925295 | F9: =F10*'Revenue Modelling'!F7 -> 3429687.4 | G9: =G10*'Revenue Modelling'!G7 -> 3506318.8 | H9: =H10*'Revenue Modelling'!H7 -> 3807531.9 | I9: =I10*'Revenue Modelling'!I7 -> 4204092.7 | J9: =J10*'Revenue Modelling'!J7 -> 4483376.8
B10: as a % revenues | C10: =C9/'Revenue Modelling'!C7 -> 0.08575024 | D10: =D9/'Revenue Modelling'!D7 -> 0.079344496 | E10: =E9/'Revenue Modelling'!E7 -> 0.075005706 | F10: =AVERAGE(C10:E10) -> 0.080033481 | G10: =AVERAGE(D10:F10)-0.5% -> 0.073127894 | H10: =AVERAGE(E10:G10)-0.5% -> 0.071055694 | I10: =AVERAGE(F10:H10)-0.5% -> 0.069739023 | J10: =AVERAGE(G10:I10)-0.5% -> 0.066307537
B12: General and Administrative | C12: ='Netflix DCF Model Raw Data '!C9 -> 1572891 | D12: ='Netflix DCF Model Raw Data '!D9 -> 1720285 | E12: ='Netflix DCF Model Raw Data '!E9 -> 1702039 | F12: =F13*'Revenue Modelling'!F7 -> 2062712 | G12: =G13*'Revenue Modelling'!G7 -> 2282107.8 | H12: =H13*'Revenue Modelling'!H7 -> 2489407.9 | I12: =I13*'Revenue Modelling'!I7 -> 2857166.4 | J12: =J13*'Revenue Modelling'!J7 -> 3188007.2
B13: as a % revenues | C13: =C12/'Revenue Modelling'!C7 -> 0.04975055 | D13: =D12/'Revenue Modelling'!D7 -> 0.051011768 | E13: =E12/'Revenue Modelling'!E7 -> 0.043640945 | F13: =AVERAGE(C13:E13) -> 0.048134421 | G13: =AVERAGE(D13:F13) -> 0.047595711 | H13: =AVERAGE(E13:G13) -> 0.046457026 | I13: =AVERAGE(F13:H13) -> 0.047395719 | J13: =AVERAGE(G13:I13) -> 0.047149485
B15: Other Current assets | C15: ='Netflix DCF Model Raw Data '!C24 -> 3208021 | D15: ='Netflix DCF Model Raw Data '!D24 -> 2780247 | E15: ='Netflix DCF Model Raw Data '!E24 -> 3516640 | F15: =F16*'Revenue Modelling'!F7 -> 3915074 | G15: =G16*'Revenue Modelling'!G7 -> 4380518 | H15: =H16*'Revenue Modelling'!H7 -> 4895553.6 | I15: =I16*'Revenue Modelling'!I7 -> 5507488 | J15: =J16*'Revenue Modelling'!J7 -> 6177311.2
B16: as a % revenues | C16: =C15/'Revenue Modelling'!C7 -> 0.10146972 | D16: =D15/'Revenue Modelling'!D7 -> 0.082442918 | E16: =E15/'Revenue Modelling'!E7 -> 0.090168023 | F16: =AVERAGE($C$16:$E$16) -> 0.09136022 | G16: =AVERAGE($C$16:$E$16) -> 0.09136022 | H16: =AVERAGE($C$16:$E$16) -> 0.09136022 | I16: =AVERAGE($C$16:$E$16) -> 0.09136022 | J16: =AVERAGE($C$16:$E$16) -> 0.09136022
B18: Accounts Payable | C18: ='Netflix DCF Model Raw Data '!C33 -> 671513 | D18: ='Netflix DCF Model Raw Data '!D33 -> 747412 | E18: ='Netflix DCF Model Raw Data '!E33 -> 899909 | F18: =(F19*F3)/365 -> 953279.43 | G18: =(G19*G3)/365 -> 992134.28 | H18: =(H19*H3)/365 -> 1012951.4 | I18: =(I19*I3)/365 -> 1100721.4 | J18: =(J19*J3)/365 -> 1144752.1
B19: Days Payable | C19: ='Other Items of P&L'!C18/'Other Items of P&L'!C3*365 -> 13.015474 | D19: ='Other Items of P&L'!D18/'Other Items of P&L'!D3*365 -> 14.092336 | E19: ='Other Items of P&L'!E18/'Other Items of P&L'!E3*365 -> 15.860643 | F19: =AVERAGE($C$19:$E$19) -> 14.322818 | G19: =AVERAGE($C$19:$E$19) -> 14.322818 | H19: =AVERAGE($C$19:$E$19) -> 14.322818 | I19: =AVERAGE($C$19:$E$19) -> 14.322818 | J19: =AVERAGE($C$19:$E$19) -> 14.322818
B21: Accrued Expenses and other Liabilities | C21: ='Netflix DCF Model Raw Data '!C34 -> 1514650 | D21: ='Netflix DCF Model Raw Data '!D34 -> 1803960 | E21: ='Netflix DCF Model Raw Data '!E34 -> 2156544 | F21: =F22*'Revenue Modelling'!F7 -> 2369549.6 | G21: =G22*'Revenue Modelling'!G7 -> 2651253.7 | H21: =H22*'Revenue Modelling'!H7 -> 2962972.6 | I21: =I22*'Revenue Modelling'!I7 -> 3333338.2 | J21: =J22*'Revenue Modelling'!J7 -> 3738740.3
B22: as a % revenues | C22: =C21/'Revenue Modelling'!C7 -> 0.047908387 | D22: =D21/'Revenue Modelling'!D7 -> 0.05349299 | E22: =E21/'Revenue Modelling'!E7 -> 0.05529463 | F22: =$E$22 -> 0.05529463 | G22: =$E$22 -> 0.05529463 | H22: =$E$22 -> 0.05529463 | I22: =$E$22 -> 0.05529463 | J22: =$E$22 -> 0.05529463
B24: Deferred Revenue | C24: ='Netflix DCF Model Raw Data '!C35 -> 1264661 | D24: ='Netflix DCF Model Raw Data '!D35 -> 1442969 | E24: ='Netflix DCF Model Raw Data '!E35 -> 1520813 | F24: =F25*'Revenue Modelling'!F7 -> 1671026.3 | G24: =G25*'Revenue Modelling'!G7 -> 1869686.5 | H24: =H25*'Revenue Modelling'!H7 -> 2089513.2 | I24: =I25*'Revenue Modelling'!I7 -> 2350698.2 | J24: =J25*'Revenue Modelling'!J7 -> 2636591.2
B25: as a % revenues | C25: =C24/'Revenue Modelling'!C7 -> 0.040001234 | D25: =D24/'Revenue Modelling'!D7 -> 0.042788491 | E25: =E24/'Revenue Modelling'!E7 -> 0.038994239 | F25: =$E$25 -> 0.038994239 | G25: =$E$25 -> 0.038994239 | H25: =$E$25 -> 0.038994239 | I25: =$E$25 -> 0.038994239 | J25: =$E$25 -> 0.038994239

Sheet Schedules
B1: Other Items
B2: (in thousands) | C2: 2022 | D2: 2023 | E2: 2024 | F2: 2025 F | G2: 2026 F | H2: 2027 F | I2: 2028 F | J2: 2029 F
B3: PPE Schedule
B4: (in thousands)
B5: Beginning Balance | D5: =C8 -> 1398257 | E5: =D8 -> 1491444 | F5: =E8 -> 1593756 | G5: =F8 -> 1657599.8 | H5: =G8 -> 1709516.7 | I5: =H8 -> 1751652.7 | J5: =I8 -> 1785769.5
B6: add: Capex | D6: =(D8+D7)-D5 -> 450134 | E6: =(E8+E7)-E5 -> 431226 | F6: =$E$6 -> 431226 | G6: =$E$6 -> 431226 | H6: =$E$6 -> 431226 | I6: =$E$6 -> 431226 | J6: =$E$6 -> 431226
B7: less: Depreciation | C7: 336682 | D7: 356947 | E7: 328914 | F7: =(F5+F6)/F10 -> 367382.18 | G7: =(G5+G6)/G10 -> 379309.12 | H7: =(H5+H6)/H10 -> 389089.96 | I7: =(I5+I6)/I10 -> 397109.27 | J7: =(J5+J6)/J10 -> 403682.97
B8: Closing Balance | C8: ='Netflix DCF Model Raw Data '!C27 -> 1398257 | D8: ='Netflix DCF Model Raw Data '!D27 -> 1491444 | E8: ='Netflix DCF Model Raw Data '!E27 -> 1593756 | F8: =(F5+F6)-F7 -> 1657599.8 | G8: =(G5+G6)-G7 -> 1709516.7 | H8: =(H5+H6)-H7 -> 1751652.7 | I8: =(I5+I6)-I7 -> 1785769.5 | J8: =(J5+J6)-J7 -> 1813312.5
B10: Useful life | D10: =(D5+D6)/D7 -> 5.1783346 | E10: =(E5+E6)/E7 -> 5.8455098 | F10: =AVERAGE(D10:E10) -> 5.5119222 | G10: =F10-0.5% -> 5.5069222 | H10: =G10-0.5% -> 5.5019222 | I10: =H10-0.5% -> 5.4969222 | J10: =I10-0.5% -> 5.4919222
B13: Content Assets
B14: (in thousands)
B15: Beginning Balance | D15: =C18 -> 32736713 | E15: =D18 -> 31658056 | F15: =E18 -> 32452462 | G15: =F18 -> 32992321 | H15: =G18 -> 33359197 | I15: =H18 -> 33608517 | J15: =I18 -> 33777948
B16: add: Addition to Content Assets | D16: =(D18+D17)-D15 -> 13118780 | E16: =(E18+E17)-E15 -> 16095923 | F16: =$E$16 -> 16095923 | G16: =$E$16 -> 16095923 | H16: =$E$16 -> 16095923 | I16: =$E$16 -> 16095923 | J16: =$E$16 -> 16095923
B17: less: Amortisation of Content Assets | C17: 14026132 | D17: 14197437 | E17: 15301517 | F17: =(F15+F16)/F20 -> 15556064 | G17: =(G15+G16)/G20 -> 15729048 | H17: =(H15+H16)/H20 -> 15846603 | I17: =(I15+I16)/I20 -> 15926491 | J17: =(J15+J16)/J20 -> 15980781
B18: Closing Balance | C18: ='Netflix DCF Model Raw Data '!C26 -> 32736713 | D18: ='Netflix DCF Model Raw Data '!D26 -> 31658056 | E18: ='Netflix DCF Model Raw Data '!E26 -> 32452462 | F18: =(F15+F16)-F17 -> 32992321 | G18: =(G15+G16)-G17 -> 33359197 | H18: =(H15+H16)-H17 -> 33608517 | I18: =(I15+I16)-I17 -> 33777948 | J18: =(J15+J16)-J17 -> 33893090
B20: Useful life | D20: =(D15+D16)/D17 -> 3.229843 | E20: =(E15+E16)/E17 -> 3.1208657 | F20: =$E$20 -> 3.1208657 | G20: =$E$20 -> 3.1208657 | H20: =$E$20 -> 3.1208657 | I20: =$E$20 -> 3.1208657 | J20: =$E$20 -> 3.1208657
B23: Debt Schedule
B24: (in thousands)
B25: Beginning Balance of Debt | D25: =C27 -> 14353076 | E25: =D27 -> 14143417 | F25: =E27 -> 13798351 | G25: =F27 -> 15585351 | H25: =G27 -> 16585351 | I25: =H27 -> 17931351 | J25: =I27 -> 21431351
B26: add/less: Debt Taken /(debt repaid) | D26: =D27-D25 -> -209659 | E26: =E27-E25 -> -345066 | F26: -1787000 | G26: -1000000 | H26: -1346000 | I26: -3500000 | J26: =-4081000 -> -4081000
B27: Closing Balance | C27: ='Netflix DCF Model Raw Data '!C39 -> 14353076 | D27: ='Netflix DCF Model Raw Data '!D39 -> 14143417 | E27: ='Netflix DCF Model Raw Data '!E39 -> 13798351 | F27: =F25-F26 -> 15585351 | G27: =G25-G26 -> 16585351 | H27: =H25-H26 -> 17931351 | I27: =I25-I26 -> 21431351 | J27: =J25-J26 -> 25512351
B29: Interest Expense | C29: ='Netflix DCF Model Raw Data '!C12 -> -706212 | D29: ='Netflix DCF Model Raw Data '!D12 -> -699826 | E29: ='Netflix DCF Model Raw Data '!E12 -> -718733 | F29: =F27*F30 -> -783277.38 | G29: =G27*G30 -> -833534.66 | H29: =H27*H30 -> -901180.97 | I29: =I27*I30 -> -1077081.5 | J29: =J27*J30 -> -1282181.4
C30: =C29/C27 -> -0.049202833 | D30: =D29/D27 -> -0.049480688 | E30: =E29/E27 -> -0.052088326 | F30: =AVERAGE($C$30:$E$30) -> -0.050257282 | G30: =AVERAGE($C$30:$E$30) -> -0.050257282 | H30: =AVERAGE($C$30:$E$30) -> -0.050257282 | I30: =AVERAGE($C$30:$E$30) -> -0.050257282 | J30: =AVERAGE($C$30:$E$30) -> -0.050257282
B33: Notes:
B34: Depreciation and Amortisation have taken from 10K Report 2024.
B35: Debt Taken calculated from the table given.

Sheet P&L
B2: Income Statement for Netflix Inc
B3: Particular | C3: 2022 | D3: 2023 | E3: 2024 | F3: 2025 F | G3: 2026 F | H3: 2027 F | I3: 2028 F | J3: 2029 F
B4: Revenue | C4: ='Revenue Modelling'!C7 -> 31615550 | D4: ='Revenue Modelling'!D7 -> 33723297 | E4: ='Revenue Modelling'!E7 -> 39000966 | F4: ='Revenue Modelling'!F7 -> 42853158 | G4: ='Revenue Modelling'!G7 -> 47947761 | H4: ='Revenue Modelling'!H7 -> 53585177 | I4: ='Revenue Modelling'!I7 -> 60283217 | J4: ='Revenue Modelling'!J7 -> 67614889
B5: Growth % of Revenue | C5: - | D5: =+D4/C4-1 -> 0.066668048 | E5: =+E4/D4-1 -> 0.1564992 | F5: =+F4/E4-1 -> 0.098771719 | G5: =+G4/F4-1 -> 0.11888511 | H5: =+H4/G4-1 -> 0.11757413 | I5: =+I4/H4-1 -> 0.12499801 | J5: =+J4/I4-1 -> 0.12162044
B7: COGS | C7: ='Other Items of P&L'!C3 -> 18831603 | D7: ='Other Items of P&L'!D3 -> 19358421 | E7: ='Other Items of P&L'!E3 -> 20709550 | F7: ='Other Items of P&L'!F3 -> 24293194 | G7: ='Other Items of P&L'!G3 -> 25283363 | H7: ='Other Items of P&L'!H3 -> 25813863 | I7: ='Other Items of P&L'!I3 -> 28050578 | J7: ='Other Items of P&L'!J3 -> 29172647
B9: Gross Profit | C9: =C4-C7 -> 12783947 | D9: =D4-D7 -> 14364876 | E9: =E4-E7 -> 18291416 | F9: =F4-F7 -> 18559965 | G9: =G4-G7 -> 22664397 | H9: =H4-H7 -> 27771314 | I9: =I4-I7 -> 32232639 | J9: =J4-J7 -> 38442242
B10: Gross Profit % | C10: =C9/C4 -> 0.40435631 | D10: =D9/D4 -> 0.42596298 | E10: =E9/E4 -> 0.46899905 | F10: =F9/F4 -> 0.43310611 | G10: =G9/G4 -> 0.47268938 | H10: =H9/H4 -> 0.51826485 | I10: =I9/I4 -> 0.53468678 | J10: =J9/J4 -> 0.568547
B12: Operating Expense
B13: ='Other Items of P&L'!B6 -> Sales and marketing | C13: ='Other Items of P&L'!C6 -> 2530502 | D13: ='Other Items of P&L'!D6 -> 2657883 | E13: ='Other Items of P&L'!E6 -> 2917554 | F13: ='Other Items of P&L'!F6 -> 3337710.5 | G13: ='Other Items of P&L'!G6 -> 3734514.6 | H13: ='Other Items of P&L'!H6 -> 4173596.9 | I13: ='Other Items of P&L'!I6 -> 4695288.2 | J13: ='Other Items of P&L'!J6 -> 5266331.3
B14: ='Other Items of P&L'!B9 -> Technology and Development | C14: ='Other Items of P&L'!C9 -> 2711041 | D14: ='Other Items of P&L'!D9 -> 2675758 | E14: ='Other Items of P&L'!E9 -> 2925295 | F14: ='Other Items of P&L'!F9 -> 3429687.4 | G14: ='Other Items of P&L'!G9 -> 3506318.8 | H14: ='Other Items of P&L'!H9 -> 3807531.9 | I14: ='Other Items of P&L'!I9 -> 4204092.7 | J14: ='Other Items of P&L'!J9 -> 4483376.8
B15: ='Other Items of P&L'!B12 -> General and Administrative | C15: ='Other Items of P&L'!C12 -> 1572891 | D15: ='Other Items of P&L'!D12 -> 1720285 | E15: ='Other Items of P&L'!E12 -> 1702039 | F15: ='Other Items of P&L'!F12 -> 2062712 | G15: ='Other Items of P&L'!G12 -> 2282107.8 | H15: ='Other Items of P&L'!H12 -> 2489407.9 | I15: ='Other Items of P&L'!I12 -> 2857166.4 | J15: ='Other Items of P&L'!J12 -> 3188007.2
B17: EBITDA | C17: =C9-C13-C14-C15 -> 5969513 | D17: =D9-D13-D14-D15 -> 7310950 | E17: =E9-E13-E14-E15 -> 10746528 | F17: =F9-F13-F14-F15 -> 9729854.9 | G17: =G9-G13-G14-G15 -> 13141456 | H17: =H9-H13-H14-H15 -> 17300777 | I17: =I9-I13-I14-I15 -> 20476092 | J17: =J9-J13-J14-J15 -> 25504527
B18: EBITDA % | C18: =C17/C4 -> 0.18881573 | D18: =D17/D4 -> 0.21679227 | E18: =E17/E4 -> 0.27554517 | F18: =F17/F4 -> 0.22705106 | G18: =G17/G4 -> 0.27407862 | H18: =H17/H4 -> 0.32286497 | I18: =I17/I4 -> 0.33966488 | J18: =J17/J4 -> 0.37720283
B20: Depreciation | C20: =Schedules!C7 -> 336682 | D20: =Schedules!D7 -> 356947 | E20: =Schedules!E7 -> 328914 | F20: =Schedules!F7 -> 367382.18 | G20: =Schedules!G7 -> 379309.12 | H20: =Schedules!H7 -> 389089.96 | I20: =Schedules!I7 -> 397109.27 | J20: =Schedules!J7 -> 403682.97
B22: EBIT | C22: =C17-C20 -> 5632831 | D22: =D17-D20 -> 6954003 | E22: =E17-E20 -> 10417614 | F22: =F17-F20 -> 9362472.7 | G22: =G17-G20 -> 12762147 | H22: =H17-H20 -> 16911687 | I22: =I17-I20 -> 20078983 | J22: =J17-J20 -> 25100844
B23: EBIT % | C23: =C22/C4 -> 0.17816647 | D23: =D22/D4 -> 0.20620768 | E23: =E22/E4 -> 0.26711169 | F23: =F22/F4 -> 0.21847801 | G23: =G22/G4 -> 0.26616774 | H23: =H22/H4 -> 0.31560382 | I23: =I22/I4 -> 0.33307749 | J23: =J22/J4 -> 0.3712325
B25: ='Netflix DCF Model Raw Data '!B12 -> Interest expense | C25: =Schedules!C29 -> -706212 | D25: =Schedules!D29 -> -699826 | E25: =Schedules!E29 -> -718733 | F25: =Schedules!F29 -> -783277.38 | G25: =Schedules!G29 -> -833534.66 | H25: =Schedules!H29 -> -901180.97 | I25: =Schedules!I29 -> -1077081.5 | J25: =Schedules!J29 -> -1282181.4
B26: ='Netflix DCF Model Raw Data '!B13 -> Interest and other income (expense) | C26: ='Netflix DCF Model Raw Data '!C13 -> 337310 | D26: ='Netflix DCF Model Raw Data '!D13 -> -48772 | E26: ='Netflix DCF Model Raw Data '!E13 -> 266776 | F26: - | G26: - | H26: - | I26: - | J26: -
B28: EBT | C28: =C22+C25-C26 -> 4589309 | D28: =D22+D25+D26 -> 6205405 | E28: =E22+E25-E26 -> 9432105 | F28: =F22+F25 -> 8579195.3 | G28: =G22+G25 -> 11928612 | H28: =H22+H25 -> 16010506 | I28: =I22+I25 -> 19001901 | J28: =J22+J25 -> 23818663
B29: EBT % | C29: =C28/C4 -> 0.14515987 | D29: =D28/D4 -> 0.18400944 | E29: =E28/E4 -> 0.24184286 | F29: =F28/F4 -> 0.20019984 | G29: =G28/G4 -> 0.24878351 | H29: =H28/H4 -> 0.2987861 | I29: =I28/I4 -> 0.31521047 | J29: =J28/J4 -> 0.35226949
B31: Tax | C31: ='Netflix DCF Model Raw Data '!C15 -> -772005 | D31: ='Netflix DCF Model Raw Data '!D15 -> -797415 | E31: ='Netflix DCF Model Raw Data '!E15 -> -1254026 | F31: =F28*F32 -> -1140629.2 | G31: =G28*G32 -> -1585944 | H31: =H28*H32 -> -2128643.7 | I31: =I28*I32 -> -2526358.5 | J31: =J28*J32 -> -3166761
B32: Tax % | C32: =C31/C28 -> -0.16821813 | D32: =D31/D28 -> -0.1285033 | E32: =E31/E28 -> -0.13295293 | F32: =$E$32 -> -0.13295293 | G32: =$E$32 -> -0.13295293 | H32: =$E$32 -> -0.13295293 | I32: =$E$32 -> -0.13295293 | J32: =$E$32 -> -0.13295293
B34: Net Profit | C34: =C28+C31 -> 3817304 | D34: =D28+D31 -> 5407990 | E34: =E28+E31 -> 8178079 | F34: =F28+F31 -> 7438566.1 | G34: =G28+G31 -> 10342668 | H34: =H28+H31 -> 13881862 | I34: =I28+I31 -> 16475543 | J34: =J28+J31 -> 20651902
B35: Net Profit % | C35: =C34/C4 -> 0.12074134 | D35: =D34/D4 -> 0.16036362 | E35: =E34/E4 -> 0.20968914 | F35: =F34/F4 -> 0.17358268 | G35: =G34/G4 -> 0.21570702 | H35: =H34/H4 -> 0.25906161 | I35: =I34/I4 -> 0.27330231 | J35: =J34/J4 -> 0.30543423

Sheet Balance Sheet
B2: Balanace Sheet for Netflix Inc
B3: Particular (in thousands) | C3: 2022 | D3: 2023 | E3: 2024 | F3: 2025 F | G3: 2026 F | H3: 2027 F | I3: 2028 F | J3: 2029 F
B4: ='Netflix DCF Model Raw Data '!B20 -> Assets
B5: ='Netflix DCF Model Raw Data '!B21 -> Current assets:
B6: ='Netflix DCF Model Raw Data '!B22 -> Cash and cash equivalents | C6: ='Netflix DCF Model Raw Data '!C22 -> 5147176 | D6: ='Netflix DCF Model Raw Data '!D22 -> 7116913 | E6: ='Netflix DCF Model Raw Data '!E22 -> 7804733 | F6: =E6+'Cash Flow'!F34 -> 16444751 | G6: =F6+'Cash Flow'!G34 -> 27422402 | H6: =G6+'Cash Flow'!H34 -> 42396136 | I6: =H6+'Cash Flow'!I34 -> 62275516 | J6: =I6+'Cash Flow'!J34 -> 86931236
B7: ='Netflix DCF Model Raw Data '!B23 -> Short-term investments | C7: ='Netflix DCF Model Raw Data '!C23 -> 911276 | D7: ='Netflix DCF Model Raw Data '!D23 -> 20973 | E7: ='Netflix DCF Model Raw Data '!E23 -> 1779006 | F7: 1779006 | G7: 1779006 | H7: 1779006 | I7: 1779006 | J7: 1779006
B8: ='Netflix DCF Model Raw Data '!B24 -> Other current assets | C8: ='Netflix DCF Model Raw Data '!C24 -> 3208021 | D8: ='Netflix DCF Model Raw Data '!D24 -> 2780247 | E8: ='Netflix DCF Model Raw Data '!E24 -> 3516640 | F8: ='Other Items of P&L'!F15 -> 3915074 | G8: ='Other Items of P&L'!G15 -> 4380518 | H8: ='Other Items of P&L'!H15 -> 4895553.6 | I8: ='Other Items of P&L'!I15 -> 5507488 | J8: ='Other Items of P&L'!J15 -> 6177311.2
B10: ='Netflix DCF Model Raw Data '!B25 -> Total current assets | C10: =SUM(C6:C8) -> 9266473 | D10: =SUM(D6:D8) -> 9918133 | E10: =SUM(E6:E8) -> 13100379 | F10: =SUM(F6:F8) -> 22138831 | G10: =SUM(G6:G8) -> 33581926 | H10: =SUM(H6:H8) -> 49070695 | I10: =SUM(I6:I8) -> 69562010 | J10: =SUM(J6:J8) -> 94887553
B12: ='Netflix DCF Model Raw Data '!B26 -> Content assets, net | C12: ='Netflix DCF Model Raw Data '!C26 -> 32736713 | D12: ='Netflix DCF Model Raw Data '!D26 -> 31658056 | E12: ='Netflix DCF Model Raw Data '!E26 -> 32452462 | F12: =Schedules!F18 -> 32992321 | G12: =Schedules!G18 -> 33359197 | H12: =Schedules!H18 -> 33608517 | I12: =Schedules!I18 -> 33777948 | J12: =Schedules!J18 -> 33893090
B13: ='Netflix DCF Model Raw Data '!B27 -> Property and equipment, net | C13: ='Netflix DCF Model Raw Data '!C27 -> 1398257 | D13: ='Netflix DCF Model Raw Data '!D27 -> 1491444 | E13: ='Netflix DCF Model Raw Data '!E27 -> 1593756 | F13: =Schedules!F8 -> 1657599.8 | G13: =Schedules!G8 -> 1709516.7 | H13: =Schedules!H8 -> 1751652.7 | I13: =Schedules!I8 -> 1785769.5 | J13: =Schedules!J8 -> 1813312.5
B14: ='Netflix DCF Model Raw Data '!B28 -> Other non-current assets | C14: ='Netflix DCF Model Raw Data '!C28 -> 5193325 | D14: ='Netflix DCF Model Raw Data '!D28 -> 5664359 | E14: ='Netflix DCF Model Raw Data '!E28 -> 6483777 | F14: 6483777 | G14: 6483777 | H14: 6483777 | I14: 6483777 | J14: 6483777
B15: ='Netflix DCF Model Raw Data '!B29 -> Total assets | C15: =SUM(C12:C14,C10) -> 48594768 | D15: =SUM(D12:D14,D10) -> 48731992 | E15: =SUM(E12:E14,E10) -> 53630374 | F15: =SUM(F12:F14,F10) -> 63272529 | G15: =SUM(G12:G14,G10) -> 75134417 | H15: =SUM(H12:H14,H10) -> 90914642 | I15: =SUM(I12:I14,I10) -> 1.1160951e+08 | J15: =SUM(J12:J14,J10) -> 1.3707773e+08
B17: ='Netflix DCF Model Raw Data '!B30 -> Liabilities and Stockholders’ Equity
B18: ='Netflix DCF Model Raw Data '!B31 -> Current liabilities:
B19: ='Netflix DCF Model Raw Data '!B32 -> Current content liabilities | C19: ='Netflix DCF Model Raw Data '!C32 -> 4480150 | D19: ='Netflix DCF Model Raw Data '!D32 -> 4466470 | E19: ='Netflix DCF Model Raw Data '!E32 -> 4393681 | F19: 4393681 | G19: 4393681 | H19: 4393681 | I19: 4393681 | J19: 4393681
B20: ='Netflix DCF Model Raw Data '!B33 -> Accounts payable | C20: ='Netflix DCF Model Raw Data '!C33 -> 671513 | D20: ='Netflix DCF Model Raw Data '!D33 -> 747412 | E20: ='Netflix DCF Model Raw Data '!E33 -> 899909 | F20: ='Other Items of P&L'!F18 -> 953279.43 | G20: ='Other Items of P&L'!G18 -> 992134.28 | H20: ='Other Items of P&L'!H18 -> 1012951.4 | I20: ='Other Items of P&L'!I18 -> 1100721.4 | J20: ='Other Items of P&L'!J18 -> 1144752.1
B21: ='Netflix DCF Model Raw Data '!B34 -> Accrued expenses and other liabilities | C21: ='Netflix DCF Model Raw Data '!C34 -> 1514650 | D21: ='Netflix DCF Model Raw Data '!D34 -> 1803960 | E21: ='Netflix DCF Model Raw Data '!E34 -> 2156544 | F21: ='Other Items of P&L'!F21 -> 2369549.6 | G21: ='Other Items of P&L'!G21 -> 2651253.7 | H21: ='Other Items of P&L'!H21 -> 2962972.6 | I21: ='Other Items of P&L'!I21 -> 3333338.2 | J21: ='Other Items of P&L'!J21 -> 3738740.3
B22: ='Netflix DCF Model Raw Data '!B35 -> Deferred revenue | C22: ='Netflix DCF Model Raw Data '!C35 -> 1264661 | D22: ='Netflix DCF Model Raw Data '!D35 -> 1442969 | E22: ='Netflix DCF Model Raw Data '!E35 -> 1520813 | F22: ='Other Items of P&L'!F24 -> 1671026.3 | G22: ='Other Items of P&L'!G24 -> 1869686.5 | H22: ='Other Items of P&L'!H24 -> 2089513.2 | I22: ='Other Items of P&L'!I24 -> 2350698.2 | J22: ='Other Items of P&L'!J24 -> 2636591.2
B23: ='Netflix DCF Model Raw Data '!B36 -> Short-term debt | C23: ='Netflix DCF Model Raw Data '!C36 -> - | D23: ='Netflix DCF Model Raw Data '!D36 -> 399844 | E23: ='Netflix DCF Model Raw Data '!E36 -> 1784453 | F23: 1784453 | G23: 1784453 | H23: 1784453 | I23: 1784453 | J23: 1784453
B25: ='Netflix DCF Model Raw Data '!B37 -> Total current liabilities | C25: =SUM(C19:C23) -> 7930974 | D25: =SUM(D19:D23) -> 8860655 | E25: =SUM(E19:E23) -> 10755400 | F25: =SUM(F19:F23) -> 11171989 | G25: =SUM(G19:G23) -> 11691208 | H25: =SUM(H19:H23) -> 12243571 | I25: =SUM(I19:I23) -> 12962892 | J25: =SUM(J19:J23) -> 13698218
B27: ='Netflix DCF Model Raw Data '!B38 -> Non-current content liabilities | C27: ='Netflix DCF Model Raw Data '!C38 -> 3081277 | D27: ='Netflix DCF Model Raw Data '!D38 -> 2578173 | E27: ='Netflix DCF Model Raw Data '!E38 -> 1780806 | F27: 1780806 | G27: 1780806 | H27: 1780806 | I27: 1780806 | J27: 1780806
B28: ='Netflix DCF Model Raw Data '!B39 -> Long-term debt | C28: ='Netflix DCF Model Raw Data '!C39 -> 14353076 | D28: ='Netflix DCF Model Raw Data '!D39 -> 14143417 | E28: ='Netflix DCF Model Raw Data '!E39 -> 13798351 | F28: =Schedules!F27 -> 15585351 | G28: =Schedules!G27 -> 16585351 | H28: =Schedules!H27 -> 17931351 | I28: =Schedules!I27 -> 21431351 | J28: =Schedules!J27 -> 25512351
B29: ='Netflix DCF Model Raw Data '!B40 -> Other non-current liabilities | C29: ='Netflix DCF Model Raw Data '!C40 -> 2452040 | D29: ='Netflix DCF Model Raw Data '!D40 -> 2561434 | E29: ='Netflix DCF Model Raw Data '!E40 -> 2552250 | F29: 2552250 | G29: 2552250 | H29: 2552250 | I29: 2552250 | J29: 2552250
B31: ='Netflix DCF Model Raw Data '!B41 -> Total liabilities | C31: =SUM(C27:C29) -> 19886393 | D31: =SUM(D27:D29) -> 19283024 | E31: =SUM(E27:E29) -> 18131407 | F31: =SUM(F27:F29) -> 19918407 | G31: =SUM(G27:G29) -> 20918407 | H31: =SUM(H27:H29) -> 22264407 | I31: =SUM(I27:I29) -> 25764407 | J31: =SUM(J27:J29) -> 29845407
B33: ='Netflix DCF Model Raw Data '!B42 -> Stockholders’ equity:
B34: ='Netflix DCF Model Raw Data '!B43 -> Common stock | C34: ='Netflix DCF Model Raw Data '!C43 -> 4637601 | D34: ='Netflix DCF Model Raw Data '!D43 -> 5145172 | E34: ='Netflix DCF Model Raw Data '!E43 -> 6252126 | F34: 6252126 | G34: 6252126 | H34: 6252126 | I34: 6252126 | J34: 6252126
B35: ='Netflix DCF Model Raw Data '!B44 -> Treasury stock at cost | C35: ='Netflix DCF Model Raw Data '!C44 -> -824190 | D35: ='Netflix DCF Model Raw Data '!D44 -> -6922200 | E35: ='Netflix DCF Model Raw Data '!E44 -> -13171638 | F35: -13171638 | G35: -13171638 | H35: -13171638 | I35: -13171638 | J35: -13171638
B36: ='Netflix DCF Model Raw Data '!B45 -> Accumulated other comprehensive loss | C36: ='Netflix DCF Model Raw Data '!C45 -> -217306 | D36: ='Netflix DCF Model Raw Data '!D45 -> -223945 | E36: ='Netflix DCF Model Raw Data '!E45 -> 362162 | F36: 362162 | G36: 362162 | H36: 362162 | I36: 362162 | J36: 362162
B37: ='Netflix DCF Model Raw Data '!B46 -> Retained earnings | C37: ='Netflix DCF Model Raw Data '!C46 -> 17181296 | D37: ='Netflix DCF Model Raw Data '!D46 -> 22589286 | E37: ='Netflix DCF Model Raw Data '!E46 -> 31300917 | F37: =E37+'P&L'!F34 -> 38739483 | G37: =F37+'P&L'!G34 -> 49082151 | H37: =G37+'P&L'!H34 -> 62964014 | I37: =H37+'P&L'!I34 -> 79439556 | J37: =I37+'P&L'!J34 -> 1.0009146e+08
B38: ='Netflix DCF Model Raw Data '!B47 -> Total stockholders’ equity | C38: =SUM(C34:C37) -> 20777401 | D38: =SUM(D34:D37) -> 20588313 | E38: =SUM(E34:E37) -> 24743567 | F38: =SUM(F34:F37) -> 32182133 | G38: =SUM(G34:G37) -> 42524801 | H38: =SUM(H34:H37) -> 56406664 | I38: =SUM(I34:I37) -> 72882206 | J38: =SUM(J34:J37) -> 93534108
B40: ='Netflix DCF Model Raw Data '!B48 -> Total liabilities and stockholders’ equity | C40: =SUM(C25,C31,C38) -> 48594768 | D40: =SUM(D25,D31,D38) -> 48731992 | E40: =SUM(E25,E31,E38) -> 53630374 | F40: =SUM(F25,F31,F38) -> 63272529 | G40: =SUM(G25,G31,G38) -> 75134417 | H40: =SUM(H25,H31,H38) -> 90914642 | I40: =SUM(I25,I31,I38) -> 1.1160951e+08 | J40: =SUM(J25,J31,J38) -> 1.3707773e+08
B42: Check | C42: =C15=C40 -> TRUE | D42: =D15=D40 -> TRUE | E42: =E15=E40 -> TRUE | F42: =F15=F40 -> TRUE | G42: =G15=G40 -> TRUE | H42: =H15=H40 -> TRUE | I42: =I15=I40 -> TRUE | J42: =J15=J40 -> TRUE

Sheet Cash Flow
B2: Balanace Sheet for Netflix Inc
B3: Particular (in thousands) | C3: 2022 | D3: 2023 | E3: 2024 | F3: 2025 F | G3: 2026 F | H3: 2027 F | I3: 2028 F | J3: 2029 F
B4: EBIT | F4: ='P&L'!F22 -> 9362472.7 | G4: ='P&L'!G22 -> 12762147 | H4: ='P&L'!H22 -> 16911687 | I4: ='P&L'!I22 -> 20078983 | J4: ='P&L'!J22 -> 25100844
B5: (-)Operating Taxes | F5: =F4*F6 -> -1244768.2 | G5: =G4*G6 -> -1696764.8 | H5: =H4*H6 -> -2248458.3 | I5: =I4*I6 -> -2669559.6 | J5: =J4*J6 -> -3337230.8
B6: (-)Operation Tax Rate | F6: ='P&L'!F32 -> -0.13295293 | G6: ='P&L'!G32 -> -0.13295293 | H6: ='P&L'!H32 -> -0.13295293 | I6: ='P&L'!I32 -> -0.13295293 | J6: ='P&L'!J32 -> -0.13295293
B8: NOPAT | F8: =F4+F5 -> 8117704.5 | G8: =G4+G5 -> 11065382 | H8: =H4+H5 -> 14663228 | I8: =I4+I5 -> 17409423 | J8: =J4+J5 -> 21763613
B10: (+)Depretiation | F10: =Schedules!F7 -> 367382.18 | G10: =Schedules!G7 -> 379309.12 | H10: =Schedules!H7 -> 389089.96 | I10: =Schedules!I7 -> 397109.27 | J10: =Schedules!J7 -> 403682.97
B11: (+)Amortisation | F11: =Schedules!F17 -> 15556064 | G11: =Schedules!G17 -> 15729048 | H11: =Schedules!H17 -> 15846603 | I11: =Schedules!I17 -> 15926491 | J11: =Schedules!J17 -> 15980781
B13: Gross Cash Flow | F13: =F8+F10+F11 -> 24041150 | G13: =G8+G10+G11 -> 27173739 | H13: =H8+H10+H11 -> 30898922 | I13: =I8+I10+I11 -> 33733024 | J13: =J8+J10+J11 -> 38148078
B15: Account Payable | F15: ='Other Items of P&L'!F18-'Other Items of P&L'!E18 -> 53370.427 | G15: ='Other Items of P&L'!G18-'Other Items of P&L'!F18 -> 38854.854 | H15: ='Other Items of P&L'!H18-'Other Items of P&L'!G18 -> 20817.135 | I15: ='Other Items of P&L'!I18-'Other Items of P&L'!H18 -> 87770.019 | J15: ='Other Items of P&L'!J18-'Other Items of P&L'!I18 -> 44030.639
B16: Differred Revenue | F16: ='Other Items of P&L'!F24-'Other Items of P&L'!E24 -> 150213.31 | G16: ='Other Items of P&L'!G24-'Other Items of P&L'!F24 -> 198660.14 | H16: ='Other Items of P&L'!H24-'Other Items of P&L'!G24 -> 219826.76 | I16: ='Other Items of P&L'!I24-'Other Items of P&L'!H24 -> 261185 | J16: ='Other Items of P&L'!J24-'Other Items of P&L'!I24 -> 285892.96
B17: Currenet Content Liabilities
B18: Accrued Expenses & other Liabilities | F18: ='Other Items of P&L'!F21-'Other Items of P&L'!E21 -> 213005.56 | G18: ='Other Items of P&L'!G21-'Other Items of P&L'!F21 -> 281704.15 | H18: ='Other Items of P&L'!H21-'Other Items of P&L'!G21 -> 311718.85 | I18: ='Other Items of P&L'!I21-'Other Items of P&L'!H21 -> 370365.68 | J18: ='Other Items of P&L'!J21-'Other Items of P&L'!I21 -> 405402.07
B19: Other Current Asset | F19: ='Other Items of P&L'!F15-'Other Items of P&L'!E15 -> 398433.99 | G19: ='Other Items of P&L'!G15-'Other Items of P&L'!F15 -> 465443.98 | H19: ='Other Items of P&L'!H15-'Other Items of P&L'!G15 -> 515035.59 | I19: ='Other Items of P&L'!I15-'Other Items of P&L'!H15 -> 611934.46 | J19: ='Other Items of P&L'!J15-'Other Items of P&L'!I15 -> 669823.13
B21: (-)Investment in Working Capital | F21: =(F15+F16+F17+F18)-F19 -> 18155.307 | G21: =(G15+G16+G17+G18)-G19 -> 53775.158 | H21: =(H15+H16+H17+H18)-H19 -> 37327.151 | I21: =(I15+I16+I17+I18)-I19 -> 107386.23 | J21: =(J15+J16+J17+J18)-J19 -> 65502.536
B23: Content Assets | F23: =Schedules!F16 -> 16095923 | G23: =Schedules!G16 -> 16095923 | H23: =Schedules!H16 -> 16095923 | I23: =Schedules!I16 -> 16095923 | J23: =Schedules!J16 -> 16095923
B24: PP&E | F24: =Schedules!F6 -> 431226 | G24: =Schedules!G6 -> 431226 | H24: =Schedules!H6 -> 431226 | I24: =Schedules!I6 -> 431226 | J24: =Schedules!J6 -> 431226
B26: (-)Capex | F26: =-(F23+F24) -> -16527149 | G26: =-(G23+G24) -> -16527149 | H26: =-(H23+H24) -> -16527149 | I26: =-(I23+I24) -> -16527149 | J26: =-(J23+J24) -> -16527149
B28: UFCF | F28: =F13+F21+F26 -> 7532156.7 | G28: =G13+G21+G26 -> 10700365 | H28: =H13+H21+H26 -> 14409100 | I28: =I13+I21+I26 -> 17313261 | J28: =J13+J21+J26 -> 21686431
B30: Diff b/w Actual & Operating Tax | F30: ='P&L'!F31-'Cash Flow'!F5 -> 104139.02 | G30: ='P&L'!G31-'Cash Flow'!G5 -> 110820.88 | H30: ='P&L'!H31-'Cash Flow'!H5 -> 119814.65 | I30: ='P&L'!I31-'Cash Flow'!I5 -> 143201.14 | J30: ='P&L'!J31-'Cash Flow'!J5 -> 170469.78
B31: Interest Expense | F31: =Schedules!F29 -> -783277.38 | G31: =Schedules!G29 -> -833534.66 | H31: =Schedules!H29 -> -901180.97 | I31: =Schedules!I29 -> -1077081.5 | J31: =Schedules!J29 -> -1282181.4
B32: Debt Repaid | F32: =Schedules!F26 -> -1787000 | G32: =Schedules!G26 -> -1000000 | H32: =Schedules!H26 -> -1346000 | I32: =Schedules!I26 -> -3500000 | J32: =Schedules!J26 -> -4081000
B34: Net Cash Flow | F34: =F28+F31+F30-F32 -> 8640018.3 | G34: =G28+G31+G30-G32 -> 10977651 | H34: =H28+H31+H30-H32 -> 14973733 | I34: =I28+I31+I30-I32 -> 19879381 | J34: =J28+J31+J30-J32 -> 24655720

Sheet WACC
B2: Working Average Cost of Capital
B4: Risk Free Rate | C4: 0.0415
B5: Market Risk Premium | C5: 0.0444
B6: Beta | C6: 1.38
B8: (in thousands) | C8: Amount
B10: Cost of Equity | C10: =C4+C5*C6 -> 0.102772
B11: Cost of Debt | C11: 0.054
B12: Equity | C12: ='Balance Sheet'!J38 -> 93534108
B13: Debt | C13: ='Balance Sheet'!J28 -> 25512351
B14: Weight of Equity | C14: =C12/(C12+C13) -> 0.78569416
B15: Weight of Debt | C15: =C13/(C12+C13) -> 0.21430584
B17: WACC | C17: =(C10*C14)+(C11*C15) -> 0.092319876

Sheet DCF
B2: DCF Model
B3: (in thousands) | C3: 2025 F | D3: 2026 F | E3: 2027 F | F3: 2028 F | G3: 2029 F
B4: UFCF | C4: ='Cash Flow'!F28 -> 7532156.7 | D4: ='Cash Flow'!G28 -> 10700365 | E4: ='Cash Flow'!H28 -> 14409100 | F4: ='Cash Flow'!I28 -> 17313261 | G4: ='Cash Flow'!J28 -> 21686431
B5: Discounted Factor | C5: =1/(1+WACC!$C$17)^DCF!C6 -> 0.91548275 | D5: =1/(1+WACC!$C$17)^DCF!D6 -> 0.83810866 | E5: =1/(1+WACC!$C$17)^DCF!E6 -> 0.76727402 | F5: =1/(1+WACC!$C$17)^DCF!F6 -> 0.70242612 | G5: =1/(1+WACC!$C$17)^DCF!G6 -> 0.643059
B6: No. of Years | C6: 1 | D6: 2 | E6: 3 | F6: 4 | G6: 5
B8: PV of Future Cash Flow | C8: =C4*C5 -> 6895559.5 | D8: =D4*D5 -> 8968068.5 | E8: =E4*E5 -> 11055728 | F8: =F4*F5 -> 12161287 | G8: =G4*G5 -> 13945655
B10: Sum of PV | C10: =SUM(C8:G8) -> 53026297
B12: Growth Rate/GDP Rate | C12: 2.8
B13: TV of Cash Flow | C13: =G4*(1+C12)/(DCF!E22-DCF!C12) -> -29431585
B15: PV of Terminal Value/Continuins Value | C15: =C13*G5 -> -18926246
B17: Enterprise Value | C17: =C15+C10 -> 34100052
B18: Debt | C18: ='Balance Sheet'!J28 -> 25512351
B19: Cash | C19: ='Balance Sheet'!J6 -> 86931236
B20: Equity Value | C20: =C17-C18+C19 -> 95518937
